Workbook

Sheet Consolidado
A1: Prioridade no Contato? | B1: Data Envio Paciente | C1: Motivo Envio | D1: Origem | E1: MO | F1: Nome do paciente | G1: CPF | H1: Data de Nascimento | I1: Idade | J1: Genero | K1: Estado | L1: Município | M1: Bairro | N1: Nível de Rede | O1: Telefone atualizado | P1: Profissional | Q1: Status BNF Linha | R1: Data de Inclusão | S1: Data da Alta, Inatividade ou Recusa | T1: Status Do Contato | U1: Situação Atual Do Paciente | V1: Tentativa de Contato 1 | W1: Tentativa de Contato 2 | X1: Tentativa de Contato 3 | Y1: Observações Importantes | Z1: Medicação Emagrecimento (SOMENTE DE EMAGRECIMENTO) | AA1: Peso Inicial (SEPARAR POR VIRGULA, SOMENTE NÚMEROS) | AB1: Altura Inicial (SEPARAR POR VIRGULA, SOMENTE NÚMEROS) | AC1: IMC Inicial | AD1: Resultado IMC | AE1: Local de Acomapanhamento | AF1: Status Pré Consulta Enfermagem | AG1: Data 1ª Consulta de Enfermagem | AH1: Status da 1ª Consulta Enfermagem | AI1: Se reagendado, sinalizar datas | AJ1: Complexidade | AK1: Resultado da Escala | AL1: Critério da Linha | AM1: Realizou a Cirurgia Bariátrica? | AN1: Data da Cirurgia | AO1: Tempo De Programa | AP1: Flag | AQ1: Encaminhado p/ Consolidado? | AR1: Laudo emitido (CMDP)? | AS1: Linha | AT1: Mês/Ano | AU1: Semana | AV1: Mês/Ano Inclusão | AW1: Semana Inclusão | AX1: SLA Captação | AY1: SLA Exclusão | AZ1: SLA Tent. Contatos | BA1: SLA Consulta | BB1: Ativo/Inativo
A2: Não | B2: 46083 | C2: Transbordo Navegação | D2: Captado pela Amil | E2: 88147444 | F2: ANTONIO ZACARIAS LIMA JUNIOR | H2: 28075 | I2: 49 | J2: M | K2: SP | N2: 60 | O2: 11987029701 | P2: Equipe Emagrecimento | Q2: 3. Alta por exclusão do plano | R2: 46155 | S2: 46181 | T2: Contato Com Sucesso | U2: Fora da Linha | V2: 46118 | W2: 46150 | Y2: contato com sucesso em 08/05 | Z2: Não Informado | AC2: =SUM(AA2/(AB2^2)) -> #DIV/0! | AD2: =IF(AC2<18.5,"ABAIXO DO PESO", (IF(AC2<=24.9,"PESO NORMAL", (IF(AC2<=29.9,"SOBREPESO", (IF(AC2<=34.9,"OBESIDADE I", (IF(AC2<=39.9,"OBESIDADE II", (IF(AC2<=999,"OBESIDADE III","VAZIO"))))))))))) -> #DIV/0! | AE2: Sem Dados | AO2: =IF(R2="","",IF(R2>TODAY(),"0 meses",DATEDIF(R2,TODAY(),"m") & " meses")) -> 0 meses | AP2: Não | AQ2: Sim | AS2: Emagrecimento | AT2: =MONTH(B2)&"/"&YEAR(B2) -> 3/2026 | AU2: =WEEKNUM(B2)-WEEKNUM(EOMONTH(B2,-1)+1)+1 -> 1 | AV2: =MONTH(R2)&"/"&YEAR(R2) -> 5/2026 | AW2: =WEEKNUM(R2)-WEEKNUM(EOMONTH(R2,-1)+1)+1 -> 3 | AX2: =IF(BB2="S",IF(Q2="1. Aceitou o programa",R2-B2,0),0) -> 0 | AY2: =IF(BB2="S",IF(AND(S2<>"",R2<>""),S2-R2,0),0) -> 26 | AZ2: =IF(BB2="S",IF(Q2="1. Aceitou o programa",IF(OR(X2="Não se Aplica",X2=""),IF(OR(W2="Não se Aplica",W2=""),0,W2-V2),AVERAGE(X2-W2,W2-V2)),0),0) -> 0 | BA2: =IF(BB2="S",IF(AND(Q2="1. Aceitou o programa",AH2="Realizada"),IFERROR(IF(AG2="",0,AG2-R2),0),0),0) -> 0 | BB2: =_xlfn.XLOOKUP(U2,'Lista Suspensa'!$AA$20:$AA$23,'Lista Suspensa'!$AB$20:$AB$23,"N/A") -> S
A3: Não | B3: 46083 | C3: Transbordo Navegação | D3: Captado pela Amil | E3: 92913655 | F3: ERIKA LOURENCO BAPTISTA SOUZA | H3: 28990 | I3: 47 | J3: F | K3: SP | N3: 60 | O3: 11957868696 | P3: Daniela | Q3: 3. Alta por exclusão do plano | R3: 46155 | S3: 46181 | T3: Contato Com Sucesso | U3: Fora da Linha | V3: 46126 | W3: 46150 | Y3: 14/04/2026 17:40:00 contato com sucesso em | Z3: Não Informado | AC3: =SUM(AA3/(AB3^2)) -> #DIV/0! | AD3: =IF(AC3<18.5,"ABAIXO DO PESO", (IF(AC3<=24.9,"PESO NORMAL", (IF(AC3<=29.9,"SOBREPESO", (IF(AC3<=34.9,"OBESIDADE I", (IF(AC3<=39.9,"OBESIDADE II", (IF(AC3<=999,"OBESIDADE III","VAZIO"))))))))))) -> #DIV/0! | AE3: Sem Dados | AO3: =IF(R3="","",IF(R3>TODAY(),"0 meses",DATEDIF(R3,TODAY(),"m") & " meses")) -> 0 meses | AP3: Não | AQ3: Sim | AS3: Emagrecimento | AT3: =MONTH(B3)&"/"&YEAR(B3) -> 3/2026 | AU3: =WEEKNUM(B3)-WEEKNUM(EOMONTH(B3,-1)+1)+1 -> 1 | AV3: =MONTH(R3)&"/"&YEAR(R3) -> 5/2026 | AW3: =WEEKNUM(R3)-WEEKNUM(EOMONTH(R3,-1)+1)+1 -> 3 | AX3: =IF(BB3="S",IF(Q3="1. Aceitou o programa",R3-B3,0),0) -> 0 | AY3: =IF(BB3="S",IF(AND(S3<>"",R3<>""),S3-R3,0),0) -> 26 | AZ3: =IF(BB3="S",IF(Q3="1. Aceitou o programa",IF(OR(X3="Não se Aplica",X3=""),IF(OR(W3="Não se Aplica",W3=""),0,W3-V3),AVERAGE(X3-W3,W3-V3)),0),0) -> 0 | BA3: =IF(BB3="S",IF(AND(Q3="1. Aceitou o programa",AH3="Realizada"),IFERROR(IF(AG3="",0,AG3-R3),0),0),0) -> 0 | BB3: =_xlfn.XLOOKUP(U3,'Lista Suspensa'!$AA$20:$AA$23,'Lista Suspensa'!$AB$20:$AB$23,"N/A") -> S
A4: Não | B4: 46083 | C4: Transbordo Navegação | D4: Captado pela Amil | E4: 94031113 | F4: CINTHIA SANTOS PINHEIRO | H4: 29196 | I4: 46 | J4: F | K4: SP | N4: 110 | O4: 11-998481982 | P4: Equipe Emagrecimento | Q4: 3. Alta por exclusão do plano | R4: 46155 | S4: 46181 | T4: Contato Com Sucesso | U4: Fora da Linha | V4: 46125 | W4: 46150 | Y4: 13/04/2026 17:06:00 contato com sucesso em | Z4: Não Informado | AC4: =SUM(AA4/(AB4^2)) -> #DIV/0! | AD4: =IF(AC4<18.5,"ABAIXO DO PESO", (IF(AC4<=24.9,"PESO NORMAL", (IF(AC4<=29.9,"SOBREPESO", (IF(AC4<=34.9,"OBESIDADE I", (IF(AC4<=39.9,"OBESIDADE II", (IF(AC4<=999,"OBESIDADE III","VAZIO"))))))))))) -> #DIV/0! | AE4: Sem Dados | AO4: =IF(R4="","",IF(R4>TODAY(),"0 meses",DATEDIF(R4,TODAY(),"m") & " meses")) -> 0 meses | AP4: Não | AQ4: Sim | AS4: Emagrecimento | AT4: =MONTH(B4)&"/"&YEAR(B4) -> 3/2026 | AU4: =WEEKNUM(B4)-WEEKNUM(EOMONTH(B4,-1)+1)+1 -> 1 | AV4: =MONTH(R4)&"/"&YEAR(R4) -> 5/2026 | AW4: =WEEKNUM(R4)-WEEKNUM(EOMONTH(R4,-1)+1)+1 -> 3 | AX4: =IF(BB4="S",IF(Q4="1. Aceitou o programa",R4-B4,0),0) -> 0 | AY4: =IF(BB4="S",IF(AND(S4<>"",R4<>""),S4-R4,0),0) -> 26 | AZ4: =IF(BB4="S",IF(Q4="1. Aceitou o programa",IF(OR(X4="Não se Aplica",X4=""),IF(OR(W4="Não se Aplica",W4=""),0,W4-V4),AVERAGE(X4-W4,W4-V4)),0),0) -> 0 | BA4: =IF(BB4="S",IF(AND(Q4="1. Aceitou o programa",AH4="Realizada"),IFERROR(IF(AG4="",0,AG4-R4),0),0),0) -> 0 | BB4: =_xlfn.XLOOKUP(U4,'Lista Suspensa'!$AA$20:$AA$23,'Lista Suspensa'!$AB$20:$AB$23,"N/A") -> S
A5: Não | B5: 46083 | C5: Transbordo Navegação | D5: Captado pela Amil | E5: 94418702 | F5: MAURILIO CABRAL DE MELLO NETO | H5: 29576 | I5: 45 | J5: M | K5: SP | N5: 450 | O5: 11-940013778 | P5: Daniela | Q5: 3. Alta por exclusão do plano | R5: 46155 | S5: 46181 | T5: Contato Com Sucesso | U5: Fora da Linha | V5: 46128 | W5: 46150 | Y5: 16/04/2026 17:48:00 contato com sucesso em | Z5: Não Informado | AC5: =SUM(AA5/(AB5^2)) -> #DIV/0! | AD5: =IF(AC5<18.5,"ABAIXO DO PESO", (IF(AC5<=24.9,"PESO NORMAL", (IF(AC5<=29.9,"SOBREPESO", (IF(AC5<=34.9,"OBESIDADE I", (IF(AC5<=39.9,"OBESIDADE II", (IF(AC5<=999,"OBESIDADE III","VAZIO"))))))))))) -> #DIV/0! | AE5: Sem Dados | AO5: =IF(R5="","",IF(R5>TODAY(),"0 meses",DATEDIF(R5,TODAY(),"m") & " meses")) -> 0 meses | AP5: Não | AQ5: Sim | AS5: Emagrecimento | AT5: =MONTH(B5)&"/"&YEAR(B5) -> 3/2026 | AU5: =WEEKNUM(B5)-WEEKNUM(EOMONTH(B5,-1)+1)+1 -> 1 | AV5: =MONTH(R5)&"/"&YEAR(R5) -> 5/2026 | AW5: =WEEKNUM(R5)-WEEKNUM(EOMONTH(R5,-1)+1)+1 -> 3 | AX5: =IF(BB5="S",IF(Q5="1. Aceitou o programa",R5-B5,0),0) -> 0 | AY5: =IF(BB5="S",IF(AND(S5<>"",R5<>""),S5-R5,0),0) -> 26 | AZ5: =IF(BB5="S",IF(Q5="1. Aceitou o programa",IF(OR(X5="Não se Aplica",X5=""),IF(OR(W5="Não se Aplica",W5=""),0,W5-V5),AVERAGE(X5-W5,W5-V5)),0),0) -> 0 | BA5: =IF(BB5="S",IF(AND(Q5="1. Aceitou o programa",AH5="Realizada"),IFERROR(IF(AG5="",0,AG5-R5),0),0),0) -> 0 | BB5: =_xlfn.XLOOKUP(U5,'Lista Suspensa'!$AA$20:$AA$23,'Lista Suspensa'!$AB$20:$AB$23,"N/A") -> S
A6: Não | B6: 46083 | C6: Transbordo Navegação | D6: Captado pela Amil | E6: 94386311 | F6: HEBERT DE CARVALHO | H6: 32236 | I6: 38 | J6: M | K6: SP | N6: 380 | O6: 11-985444555 | P6: Equipe Emagrecimento | Q6: 3. Alta por exclusão do plano | R6: 46155 | S6: 46181 | T6: Contato Com Sucesso | U6: Fora da Linha | V6: 46126 | W6: 46150 | Y6: 14/04/2026 17:08:00 contato com sucesso em | Z6: Não Informado | AC6: =SUM(AA6/(AB6^2)) -> #DIV/0! | AD6: =IF(AC6<18.5,"ABAIXO DO PESO", (IF(AC6<=24.9,"PESO NORMAL", (IF(AC6<=29.9,"SOBREPESO", (IF(AC6<=34.9,"OBESIDADE I", (IF(AC6<=39.9,"OBESIDADE II", (IF(AC6<=999,"OBESIDADE III","VAZIO"))))))))))) -> #DIV/0! | AE6: Sem Dados | AO6: =IF(R6="","",IF(R6>TODAY(),"0 meses",DATEDIF(R6,TODAY(),"m") & " meses")) -> 0 meses | AP6: Não | AQ6: Sim | AS6: Emagrecimento | AT6: =MONTH(B6)&"/"&YEAR(B6) -> 3/2026 | AU6: =WEEKNUM(B6)-WEEKNUM(EOMONTH(B6,-1)+1)+1 -> 1 | AV6: =MONTH(R6)&"/"&YEAR(R6) -> 5/2026 | AW6: =WEEKNUM(R6)-WEEKNUM(EOMONTH(R6,-1)+1)+1 -> 3 | AX6: =IF(BB6="S",IF(Q6="1. Aceitou o programa",R6-B6,0),0) -> 0 | AY6: =IF(BB6="S",IF(AND(S6<>"",R6<>""),S6-R6,0),0) -> 26 | AZ6: =IF(BB6="S",IF(Q6="1. Aceitou o programa",IF(OR(X6="Não se Aplica",X6=""),IF(OR(W6="Não se Aplica",W6=""),0,W6-V6),AVERAGE(X6-W6,W6-V6)),0),0) -> 0 | BA6: =IF(BB6="S",IF(AND(Q6="1. Aceitou o programa",AH6="Realizada"),IFERROR(IF(AG6="",0,AG6-R6),0),0),0) -> 0 | BB6: =_xlfn.XLOOKUP(U6,'Lista Suspensa'!$AA$20:$AA$23,'Lista Suspensa'!$AB$20:$AB$23,"N/A") -> S
A7: Não | B7: 46083 | C7: Transbordo Navegação | D7: Captado pela Amil | E7: 76307672 | F7: MANUEL AGOSTINHO OLIVEIRA GROVA | H7: 23376 | I7: 62 | J7: M | N7: 50 | O7: 21-964582309 | P7: Equipe Emagrecimento | Q7: 3. Alta por exclusão do plano | R7: 46155 | S7: 46181 | T7: Contato Com Sucesso | U7: Fora da Linha | V7: 46113 | W7: 46150 | Y7: 20/03/2026 18:22:00 contato com sucesso em | Z7: Não Informado | AC7: =SUM(AA7/(AB7^2)) -> #DIV/0! | AD7: =IF(AC7<18.5,"ABAIXO DO PESO", (IF(AC7<=24.9,"PESO NORMAL", (IF(AC7<=29.9,"SOBREPESO", (IF(AC7<=34.9,"OBESIDADE I", (IF(AC7<=39.9,"OBESIDADE II", (IF(AC7<=999,"OBESIDADE III","VAZIO"))))))))))) -> #DIV/0! | AE7: Sem Dados | AL7: Pós-Bariátrico | AM7: Sim - Não Acompanhou Pré Operatório conosco | AO7: =IF(R7="","",IF(R7>TODAY(),"0 meses",DATEDIF(R7,TODAY(),"m") & " meses")) -> 0 meses | AP7: Não | AQ7: Sim | AS7: Emagrecimento | AT7: =MONTH(B7)&"/"&YEAR(B7) -> 3/2026 | AU7: =WEEKNUM(B7)-WEEKNUM(EOMONTH(B7,-1)+1)+1 -> 1 | AV7: =MONTH(R7)&"/"&YEAR(R7) -> 5/2026 | AW7: =WEEKNUM(R7)-WEEKNUM(EOMONTH(R7,-1)+1)+1 -> 3 | AX7: =IF(BB7="S",IF(Q7="1. Aceitou o programa",R7-B7,0),0) -> 0 | AY7: =IF(BB7="S",IF(AND(S7<>"",R7<>""),S7-R7,0),0) -> 26 | AZ7: =IF(BB7="S",IF(Q7="1. Aceitou o programa",IF(OR(X7="Não se Aplica",X7=""),IF(OR(W7="Não se Aplica",W7=""),0,W7-V7),AVERAGE(X7-W7,W7-V7)),0),0) -> 0 | BA7: =IF(BB7="S",IF(AND(Q7="1. Aceitou o programa",AH7="Realizada"),IFERROR(IF(AG7="",0,AG7-R7),0),0),0) -> 0 | BB7: =_xlfn.XLOOKUP(U7,'Lista Suspensa'!$AA$20:$AA$23,'Lista Suspensa'!$AB$20:$AB$23,"N/A") -> S
A8: Não | B8: 46083 | C8: Transbordo Navegação | D8: Captado pela Amil | E8: 88147442 | F8: PRISCILLA REBELO SOARES CONCEICAO | H8: 31318 | I8: 40 | J8: F | N8: 60 | O8: 11-972720940 | P8: Alessandra | Q8: 3. Alta por exclusão do plano | R8: 46155 | S8: 46181 | T8: Contato Com Sucesso | U8: Fora da Linha | V8: 46118 | W8: 46143 | X8: 46142 | Y8: contato com sucesso 04/05 | Z8: Não Informado | AC8: =SUM(AA8/(AB8^2)) -> #DIV/0! | AD8: =IF(AC8<18.5,"ABAIXO DO PESO", (IF(AC8<=24.9,"PESO NORMAL", (IF(AC8<=29.9,"SOBREPESO", (IF(AC8<=34.9,"OBESIDADE I", (IF(AC8<=39.9,"OBESIDADE II", (IF(AC8<=999,"OBESIDADE III","VAZIO"))))))))))) -> #DIV/0! | AE8: Sem Dados | AO8: =IF(R8="","",IF(R8>TODAY(),"0 meses",DATEDIF(R8,TODAY(),"m") & " meses")) -> 0 meses | AP8: Não | AQ8: Sim | AS8: Emagrecimento | AT8: =MONTH(B8)&"/"&YEAR(B8) -> 3/2026 | AU8: =WEEKNUM(B8)-WEEKNUM(EOMONTH(B8,-1)+1)+1 -> 1 | AV8: =MONTH(R8)&"/"&YEAR(R8) -> 5/2026 | AW8: =WEEKNUM(R8)-WEEKNUM(EOMONTH(R8,-1)+1)+1 -> 3 | AX8: =IF(BB8="S",IF(Q8="1. Aceitou o programa",R8-B8,0),0) -> 0 | AY8: =IF(BB8="S",IF(AND(S8<>"",R8<>""),S8-R8,0),0) -> 26 | AZ8: =IF(BB8="S",IF(Q8="1. Aceitou o programa",IF(OR(X8="Não se Aplica",X8=""),IF(OR(W8="Não se Aplica",W8=""),0,W8-V8),AVERAGE(X8-W8,W8-V8)),0),0) -> 0 | BA8: =IF(BB8="S",IF(AND(Q8="1. Aceitou o programa",AH8="Realizada"),IFERROR(IF(AG8="",0,AG8-R8),0),0),0) -> 0 | BB8: =_xlfn.XLOOKUP(U8,'Lista Suspensa'!$AA$20:$AA$23,'Lista Suspensa'!$AB$20:$AB$23,"N/A") -> S
A9: Não | B9: 46083 | C9: Transbordo Navegação | D9: Captado pela Amil | E9: 86340731 | F9: CRISTIANE MARTINS DA SILVA | H9: 31505 | I9: 40 | J9: F | N9: 80 | O9: 11-960719415 | P9: Equipe Emagrecimento | Q9: 3. Alta por exclusão do plano | R9: 46155 | S9: 46181 | T9: Contato Com Sucesso | U9: Fora da Linha | V9: 46114 | W9: 46142 | X9: 46150 | Y9: 29/04/2026 17:58:00 contato com sucesso em | Z9: Não Informado | AC9: =SUM(AA9/(AB9^2)) -> #DIV/0! | AD9: =IF(AC9<18.5,"ABAIXO DO PESO", (IF(AC9<=24.9,"PESO NORMAL", (IF(AC9<=29.9,"SOBREPESO", (IF(AC9<=34.9,"OBESIDADE I", (IF(AC9<=39.9,"OBESIDADE II", (IF(AC9<=999,"OBESIDADE III","VAZIO"))))))))))) -> #DIV/0! | AE9: Sem Dados | AO9: =IF(R9="","",IF(R9>TODAY(),"0 meses",DATEDIF(R9,TODAY(),"m") & " meses")) -> 0 meses | AP9: Não | AQ9: Sim | AS9: Emagrecimento | AT9: =MONTH(B9)&"/"&YEAR(B9) -> 3/2026 | AU9: =WEEKNUM(B9)-WEEKNUM(EOMONTH(B9,-1)+1)+1 -> 1 | AV9: =MONTH(R9)&"/"&YEAR(R9) -> 5/2026 | AW9: =WEEKNUM(R9)-WEEKNUM(EOMONTH(R9,-1)+1)+1 -> 3 | AX9: =IF(BB9="S",IF(Q9="1. Aceitou o programa",R9-B9,0),0) -> 0 | AY9: =IF(BB9="S",IF(AND(S9<>"",R9<>""),S9-R9,0),0) -> 26 | AZ9: =IF(BB9="S",IF(Q9="1. Aceitou o programa",IF(OR(X9="Não se Aplica",X9=""),IF(OR(W9="Não se Aplica",W9=""),0,W9-V9),AVERAGE(X9-W9,W9-V9)),0),0) -> 0 | BA9: =IF(BB9="S",IF(AND(Q9="1. Aceitou o programa",AH9="Realizada"),IFERROR(IF(AG9="",0,AG9-R9),0),0),0) -> 0 | BB9: =_xlfn.XLOOKUP(U9,'Lista Suspensa'!$AA$20:$AA$23,'Lista Suspensa'!$AB$20:$AB$23,"N/A") -> S
A10: Não | B10: 46083 | C10: Transbordo Navegação | D10: Captado pela Amil | E10: 93499995 | F10: LILIA PINTO DE SOUZA MOTA | H10: 32407 | I10: 37 | J10: F | N10: 60 | O10: 21-969271240 | P10: Daniela | Q10: 3. Alta por exclusão do plano | R10: 46155 | S10: 46181 | T10: Contato Com Sucesso | U10: Fora da Linha | V10: 46128 | Y10: 16/04/2026 18:02:00 contato com sucesso em | Z10: Não Informado | AC10: =SUM(AA10/(AB10^2)) -> #DIV/0! | AD10: =IF(AC10<18.5,"ABAIXO DO PESO", (IF(AC10<=24.9,"PESO NORMAL", (IF(AC10<=29.9,"SOBREPESO", (IF(AC10<=34.9,"OBESIDADE I", (IF(AC10<=39.9,"OBESIDADE II", (IF(AC10<=999,"OBESIDADE III","VAZIO"))))))))))) -> #DIV/0! | AE10: Sem Dados | AO10: =IF(R10="","",IF(R10>TODAY(),"0 meses",DATEDIF(R10,TODAY(),"m") & " meses")) -> 0 meses | AP10: Não | AQ10: Sim | AS10: Emagrecimento | AT10: =MONTH(B10)&"/"&YEAR(B10) -> 3/2026 | AU10: =WEEKNUM(B10)-WEEKNUM(EOMONTH(B10,-1)+1)+1 -> 1 | AV10: =MONTH(R10)&"/"&YEAR(R10) -> 5/2026 | AW10: =WEEKNUM(R10)-WEEKNUM(EOMONTH(R10,-1)+1)+1 -> 3 | AX10: =IF(BB10="S",IF(Q10="1. Aceitou o programa",R10-B10,0),0) -> 0 | AY10: =IF(BB10="S",IF(AND(S10<>"",R10<>""),S10-R10,0),0) -> 26 | AZ10: =IF(BB10="S",IF(Q10="1. Aceitou o programa",IF(OR(X10="Não se Aplica",X10=""),IF(OR(W10="Não se Aplica",W10=""),0,W10-V10),AVERAGE(X10-W10,W10-V10)),0),0) -> 0 | BA10: =IF(BB10="S",IF(AND(Q10="1. Aceitou o programa",AH10="Realizada"),IFERROR(IF(AG10="",0,AG10-R10),0),0),0) -> 0 | BB10: =_xlfn.XLOOKUP(U10,'Lista Suspensa'!$AA$20:$AA$23,'Lista Suspensa'!$AB$20:$AB$23,"N/A") -> S
A11: Não | B11: 46083 | C11: Transbordo Navegação | D11: Captado pela Amil | E11: 89007976 | F11: AMANDA CARDOZO DA PENHA SENA | H11: 32472 | I11: 37 | J11: F | N11: 120 | O11: 21-999101770 | P11: Equipe Emagrecimento | Q11: 3. Alta por exclusão do plano | R11: 46155 | S11: 46181 | T11: Contato Com Sucesso | U11: Fora da Linha | V11: 46112 | W11: 46155 | Y11: contato com suceesso em 13/05 | Z11: Não Informado | AC11: =SUM(AA11/(AB11^2)) -> #DIV/0! | AD11: =IF(AC11<18.5,"ABAIXO DO PESO", (IF(AC11<=24.9,"PESO NORMAL", (IF(AC11<=29.9,"SOBREPESO", (IF(AC11<=34.9,"OBESIDADE I", (IF(AC11<=39.9,"OBESIDADE II", (IF(AC11<=999,"OBESIDADE III","VAZIO"))))))))))) -> #DIV/0! | AE11: Sem Dados | AO11: =IF(R11="","",IF(R11>TODAY(),"0 meses",DATEDIF(R11,TODAY(),"m") & " meses")) -> 0 meses | AP11: Não | AQ11: Sim | AS11: Emagrecimento | AT11: =MONTH(B11)&"/"&YEAR(B11) -> 3/2026 | AU11: =WEEKNUM(B11)-WEEKNUM(EOMONTH(B11,-1)+1)+1 -> 1 | AV11: =MONTH(R11)&"/"&YEAR(R11) -> 5/2026 | AW11: =WEEKNUM(R11)-WEEKNUM(EOMONTH(R11,-1)+1)+1 -> 3 | AX11: =IF(BB11="S",IF(Q11="1. Aceitou o programa",R11-B11,0),0) -> 0 | AY11: =IF(BB11="S",IF(AND(S11<>"",R11<>""),S11-R11,0),0) -> 26 | AZ11: =IF(BB11="S",IF(Q11="1. Aceitou o programa",IF(OR(X11="Não se Aplica",X11=""),IF(OR(W11="Não se Aplica",W11=""),0,W11-V11),AVERAGE(X11-W11,W11-V11)),0),0) -> 0 | BA11: =IF(BB11="S",IF(AND(Q11="1. Aceitou o programa",AH11="Realizada"),IFERROR(IF(AG11="",0,AG11-R11),0),0),0) -> 0 | BB11: =_xlfn.XLOOKUP(U11,'Lista Suspensa'!$AA$20:$AA$23,'Lista Suspensa'!$AB$20:$AB$23,"N/A") -> S
A12: Não | B12: 46083 | C12: Transbordo Navegação | D12: Captado pela Amil | E12: 93882577 | F12: VANIA SILVA DE PAIVA FARIAS | H12: 31461 | I12: 40 | J12: F | K12: RJ | N12: 120 | O12: 21970004629 | P12: Equipe Emagrecimento | Q12: 3. Alta por exclusão do plano | R12: 46155 | S12: 46181 | T12: Contato Com Sucesso | U12: Fora da Linha | V12: 46149 | Y12: contato com sucesso em 08/05 | Z12: Não Informado | AC12: =SUM(AA12/(AB12^2)) -> #DIV/0! | AD12: =IF(AC12<18.5,"ABAIXO DO PESO", (IF(AC12<=24.9,"PESO NORMAL", (IF(AC12<=29.9,"SOBREPESO", (IF(AC12<=34.9,"OBESIDADE I", (IF(AC12<=39.9,"OBESIDADE II", (IF(AC12<=999,"OBESIDADE III","VAZIO"))))))))))) -> #DIV/0! | AE12: Sem Dados | AO12: =IF(R12="","",IF(R12>TODAY(),"0 meses",DATEDIF(R12,TODAY(),"m") & " meses")) -> 0 meses | AP12: Não | AQ12: Sim | AS12: Emagrecimento | AT12: =MONTH(B12)&"/"&YEAR(B12) -> 3/2026 | AU12: =WEEKNUM(B12)-WEEKNUM(EOMONTH(B12,-1)+1)+1 -> 1 | AV12: =MONTH(R12)&"/"&YEAR(R12) -> 5/2026 | AW12: =WEEKNUM(R12)-WEEKNUM(EOMONTH(R12,-1)+1)+1 -> 3 | AX12: =IF(BB12="S",IF(Q12="1. Aceitou o programa",R12-B12,0),0) -> 0 | AY12: =IF(BB12="S",IF(AND(S12<>"",R12<>""),S12-R12,0),0) -> 26 | AZ12: =IF(BB12="S",IF(Q12="1. Aceitou o programa",IF(OR(X12="Não se Aplica",X12=""),IF(OR(W12="Não se Aplica",W12=""),0,W12-V12),AVERAGE(X12-W12,W12-V12)),0),0) -> 0 | BA12: =IF(BB12="S",IF(AND(Q12="1. Aceitou o programa",AH12="Realizada"),IFERROR(IF(AG12="",0,AG12-R12),0),0),0) -> 0 | BB12: =_xlfn.XLOOKUP(U12,'Lista Suspensa'!$AA$20:$AA$23,'Lista Suspensa'!$AB$20:$AB$23,"N/A") -> S
A13: Não | B13: 46083 | C13: Transbordo Navegação | D13: Captado pela Amil | E13: 94701068 | F13: PAULA NOGUEIRA DO NASCIMENTO GABRIEL | H13: 31724 | I13: 39 | J13: F | K13: RJ | N13: 120 | O13: 21-986426870 | P13: Equipe Emagrecimento | Q13: 3. Alta por exclusão do plano | R13: 46155 | S13: 46181 | T13: Contato Com Sucesso | U13: Fora da Linha | V13: 46149 | Y13: 17/04/2026 18:04:00 contato com sucesso em | Z13: Não Informado | AC13: =SUM(AA13/(AB13^2)) -> #DIV/0! | AD13: =IF(AC13<18.5,"ABAIXO DO PESO", (IF(AC13<=24.9,"PESO NORMAL", (IF(AC13<=29.9,"SOBREPESO", (IF(AC13<=34.9,"OBESIDADE I", (IF(AC13<=39.9,"OBESIDADE II", (IF(AC13<=999,"OBESIDADE III","VAZIO"))))))))))) -> #DIV/0! | AE13: Sem Dados | AO13: =IF(R13="","",IF(R13>TODAY(),"0 meses",DATEDIF(R13,TODAY(),"m") & " meses")) -> 0 meses | AP13: Não | AQ13: Sim | AS13: Emagrecimento | AT13: =MONTH(B13)&"/"&YEAR(B13) -> 3/2026 | AU13: =WEEKNUM(B13)-WEEKNUM(EOMONTH(B13,-1)+1)+1 -> 1 | AV13: =MONTH(R13)&"/"&YEAR(R13) -> 5/2026 | AW13: =WEEKNUM(R13)-WEEKNUM(EOMONTH(R13,-1)+1)+1 -> 3 | AX13: =IF(BB13="S",IF(Q13="1. Aceitou o programa",R13-B13,0),0) -> 0 | AY13: =IF(BB13="S",IF(AND(S13<>"",R13<>""),S13-R13,0),0) -> 26 | AZ13: =IF(BB13="S",IF(Q13="1. Aceitou o programa",IF(OR(X13="Não se Aplica",X13=""),IF(OR(W13="Não se Aplica",W13=""),0,W13-V13),AVERAGE(X13-W13,W13-V13)),0),0) -> 0 | BA13: =IF(BB13="S",IF(AND(Q13="1. Aceitou o programa",AH13="Realizada"),IFERROR(IF(AG13="",0,AG13-R13),0),0),0) -> 0 | BB13: =_xlfn.XLOOKUP(U13,'Lista Suspensa'!$AA$20:$AA$23,'Lista Suspensa'!$AB$20:$AB$23,"N/A") -> S
A14: Não | B14: 46083 | C14: Transbordo Navegação | D14: Captado pela Amil | E14: 94504450 | F14: VIVIAN VILLELA CORTOPASSI ALVES | H14: 27221 | I14: 51 | J14: F | K14: SP | N14: 750 | O14: 11-987565673 | P14: Equipe Emagrecimento | Q14: 3. Alta por exclusão do plano | R14: 46155 | S14: 46181 | T14: Contato Com Sucesso | U14: Fora da Linha | V14: 46149 | Y14: 20/04/2026 17:28:00 contato com sucesso em | Z14: Não Informado | AC14: =SUM(AA14/(AB14^2)) -> #DIV/0! | AD14: =IF(AC14<18.5,"ABAIXO DO PESO", (IF(AC14<=24.9,"PESO NORMAL", (IF(AC14<=29.9,"SOBREPESO", (IF(AC14<=34.9,"OBESIDADE I", (IF(AC14<=39.9,"OBESIDADE II", (IF(AC14<=999,"OBESIDADE III","VAZIO"))))))))))) -> #DIV/0! | AE14: Sem Dados | AO14: =IF(R14="","",IF(R14>TODAY(),"0 meses",DATEDIF(R14,TODAY(),"m") & " meses")) -> 0 meses | AP14: Não | AQ14: Sim | AS14: Emagrecimento | AT14: =MONTH(B14)&"/"&YEAR(B14) -> 3/2026 | AU14: =WEEKNUM(B14)-WEEKNUM(EOMONTH(B14,-1)+1)+1 -> 1 | AV14: =MONTH(R14)&"/"&YEAR(R14) -> 5/2026 | AW14: =WEEKNUM(R14)-WEEKNUM(EOMONTH(R14,-1)+1)+1 -> 3 | AX14: =IF(BB14="S",IF(Q14="1. Aceitou o programa",R14-B14,0),0) -> 0 | AY14: =IF(BB14="S",IF(AND(S14<>"",R14<>""),S14-R14,0),0) -> 26 | AZ14: =IF(BB14="S",IF(Q14="1. Aceitou o programa",IF(OR(X14="Não se Aplica",X14=""),IF(OR(W14="Não se Aplica",W14=""),0,W14-V14),AVERAGE(X14-W14,W14-V14)),0),0) -> 0 | BA14: =IF(BB14="S",IF(AND(Q14="1. Aceitou o programa",AH14="Realizada"),IFERROR(IF(AG14="",0,AG14-R14),0),0),0) -> 0 | BB14: =_xlfn.XLOOKUP(U14,'Lista Suspensa'!$AA$20:$AA$23,'Lista Suspensa'!$AB$20:$AB$23,"N/A") -> S
A15: Não | B15: 46083 | C15: Transbordo Navegação | D15: Captado pela Amil | E15: 92957507 | F15: ROSANE CANDIDO DE JESUS | H15: 27520 | I15: 51 | J15: F | K15: SP | N15: 110 | O15: 11-952003415 | P15: Equipe Emagrecimento | Q15: 1. Aceitou o programa | R15: 46155 | T15: Contato Com Sucesso | U15: Ativo | V15: 46149 | Y15: 17/04/2026 17:06:00 contato com sucesso em | Z15: Não Informado | AC15: =SUM(AA15/(AB15^2)) -> #DIV/0! | AD15: =IF(AC15<18.5,"ABAIXO DO PESO", (IF(AC15<=24.9,"PESO NORMAL", (IF(AC15<=29.9,"SOBREPESO", (IF(AC15<=34.9,"OBESIDADE I", (IF(AC15<=39.9,"OBESIDADE II", (IF(AC15<=999,"OBESIDADE III","VAZIO"))))))))))) -> #DIV/0! | AE15: Sem Dados | AO15: =IF(R15="","",IF(R15>TODAY(),"0 meses",DATEDIF(R15,TODAY(),"m") & " meses")) -> 0 meses | AP15: Não | AQ15: Sim | AS15: Emagrecimento | AT15: =MONTH(B15)&"/"&YEAR(B15) -> 3/2026 | AU15: =WEEKNUM(B15)-WEEKNUM(EOMONTH(B15,-1)+1)+1 -> 1 | AV15: =MONTH(R15)&"/"&YEAR(R15) -> 5/2026 | AW15: =WEEKNUM(R15)-WEEKNUM(EOMONTH(R15,-1)+1)+1 -> 3 | AX15: =IF(BB15="S",IF(Q15="1. Aceitou o programa",R15-B15,0),0) -> 72 | AY15: =IF(BB15="S",IF(AND(S15<>"",R15<>""),S15-R15,0),0) -> 0 | AZ15: =IF(BB15="S",IF(Q15="1. Aceitou o programa",IF(OR(X15="Não se Aplica",X15=""),IF(OR(W15="Não se Aplica",W15=""),0,W15-V15),AVERAGE(X15-W15,W15-V15)),0),0) -> 0 | BA15: =IF(BB15="S",IF(AND(Q15="1. Aceitou o programa",AH15="Realizada"),IFERROR(IF(AG15="",0,AG15-R15),0),0),0) -> 0 | BB15: =_xlfn.XLOOKUP(U15,'Lista Suspensa'!$AA$20:$AA$23,'Lista Suspensa'!$AB$20:$AB$23,"N/A") -> S
A16: Não | B16: 46083 | C16: Transbordo Navegação | D16: Captado pela Amil | E16: 94108842 | F16: KATIA CARAPIA | H16: 30716 | I16: 42 | J16: F | K16: SP | N16: 110 | O16: 11-965159730 | P16: Equipe Emagrecimento | Q16: 3. Alta por exclusão do plano | R16: 46155 | S16: 46181 | T16: Contato Com Sucesso | U16: Fora da Linha | V16: 46149 | Y16: 15/04/2026 18:06:00 contato com sucesso em | Z16: Não Informado | AC16: =SUM(AA16/(AB16^2)) -> #DIV/0! | AD16: =IF(AC16<18.5,"ABAIXO DO PESO", (IF(AC16<=24.9,"PESO NORMAL", (IF(AC16<=29.9,"SOBREPESO", (IF(AC16<=34.9,"OBESIDADE I", (IF(AC16<=39.9,"OBESIDADE II", (IF(AC16<=999,"OBESIDADE III","VAZIO"))))))))))) -> #DIV/0! | AE16: Sem Dados | AO16: =IF(R16="","",IF(R16>TODAY(),"0 meses",DATEDIF(R16,TODAY(),"m") & " meses")) -> 0 meses | AP16: Não | AQ16: Sim | AS16: Emagrecimento | AT16: =MONTH(B16)&"/"&YEAR(B16) -> 3/2026 | AU16: =WEEKNUM(B16)-WEEKNUM(EOMONTH(B16,-1)+1)+1 -> 1 | AV16: =MONTH(R16)&"/"&YEAR(R16) -> 5/2026 | AW16: =WEEKNUM(R16)-WEEKNUM(EOMONTH(R16,-1)+1)+1 -> 3 | AX16: =IF(BB16="S",IF(Q16="1. Aceitou o programa",R16-B16,0),0) -> 0 | AY16: =IF(BB16="S",IF(AND(S16<>"",R16<>""),S16-R16,0),0) -> 26 | AZ16: =IF(BB16="S",IF(Q16="1. Aceitou o programa",IF(OR(X16="Não se Aplica",X16=""),IF(OR(W16="Não se Aplica",W16=""),0,W16-V16),AVERAGE(X16-W16,W16-V16)),0),0) -> 0 | BA16: =IF(BB16="S",IF(AND(Q16="1. Aceitou o programa",AH16="Realizada"),IFERROR(IF(AG16="",0,AG16-R16),0),0),0) -> 0 | BB16: =_xlfn.XLOOKUP(U16,'Lista Suspensa'!$AA$20:$AA$23,'Lista Suspensa'!$AB$20:$AB$23,"N/A") -> S
A17: Não | B17: 46083 | C17: Transbordo Navegação | D17: Captado pela Amil | E17: 92687232 | F17: VINICIUS MATHIAS VAZ | H17: 32334 | I17: 37 | J17: M | N17: 80 | O17: 21-998869501 | P17: Equipe Emagrecimento | Q17: 3. Alta por exclusão do plano | R17: 46155 | S17: 46181 | T17: Contato Com Sucesso | U17: Fora da Linha | V17: 46149 | Y17: 20/04/2026 17:26:00 contato com sucesso em | Z17: Não Informado | AC17: =SUM(AA17/(AB17^2)) -> #DIV/0! | AD17: =IF(AC17<18.5,"ABAIXO DO PESO", (IF(AC17<=24.9,"PESO NORMAL", (IF(AC17<=29.9,"SOBREPESO", (IF(AC17<=34.9,"OBESIDADE I", (IF(AC17<=39.9,"OBESIDADE II", (IF(AC17<=999,"OBESIDADE III","VAZIO"))))))))))) -> #DIV/0! | AE17: Sem Dados | AO17: =IF(R17="","",IF(R17>TODAY(),"0 meses",DATEDIF(R17,TODAY(),"m") & " meses")) -> 0 meses | AP17: Não | AQ17: Sim | AS17: Emagrecimento | AT17: =MONTH(B17)&"/"&YEAR(B17) -> 3/2026 | AU17: =WEEKNUM(B17)-WEEKNUM(EOMONTH(B17,-1)+1)+1 -> 1 | AV17: =MONTH(R17)&"/"&YEAR(R17) -> 5/2026 | AW17: =WEEKNUM(R17)-WEEKNUM(EOMONTH(R17,-1)+1)+1 -> 3 | AX17: =IF(BB17="S",IF(Q17="1. Aceitou o programa",R17-B17,0),0) -> 0 | AY17: =IF(BB17="S",IF(AND(S17<>"",R17<>""),S17-R17,0),0) -> 26 | AZ17: =IF(BB17="S",IF(Q17="1. Aceitou o programa",IF(OR(X17="Não se Aplica",X17=""),IF(OR(W17="Não se Aplica",W17=""),0,W17-V17),AVERAGE(X17-W17,W17-V17)),0),0) -> 0 | BA17: =IF(BB17="S",IF(AND(Q17="1. Aceitou o programa",AH17="Realizada"),IFERROR(IF(AG17="",0,AG17-R17),0),0),0) -> 0 | BB17: =_xlfn.XLOOKUP(U17,'Lista Suspensa'!$AA$20:$AA$23,'Lista Suspensa'!$AB$20:$AB$23,"N/A") -> S
A18: Não | B18: 46083 | C18: Transbordo Navegação | D18: Captado pela Amil | E18: 92947782 | F18: PALOMMA FELIX BARRETO | H18: 33737 | I18: 34 | J18: F | N18: 380 | O18: 21-995953502 | P18: Equipe Emagrecimento | Q18: 1. Aceitou o programa | R18: 46155 | T18: Contato Com Sucesso | U18: Ativo | V18: 46149 | Y18: contato com sucesso em 08/05 | Z18: Não Informado | AC18: =SUM(AA18/(AB18^2)) -> #DIV/0! | AD18: =IF(AC18<18.5,"ABAIXO DO PESO", (IF(AC18<=24.9,"PESO NORMAL", (IF(AC18<=29.9,"SOBREPESO", (IF(AC18<=34.9,"OBESIDADE I", (IF(AC18<=39.9,"OBESIDADE II", (IF(AC18<=999,"OBESIDADE III","VAZIO"))))))))))) -> #DIV/0! | AE18: Sem Dados | AO18: =IF(R18="","",IF(R18>TODAY(),"0 meses",DATEDIF(R18,TODAY(),"m") & " meses")) -> 0 meses | AP18: Não | AQ18: Sim | AS18: Emagrecimento | AT18: =MONTH(B18)&"/"&YEAR(B18) -> 3/2026 | AU18: =WEEKNUM(B18)-WEEKNUM(EOMONTH(B18,-1)+1)+1 -> 1 | AV18: =MONTH(R18)&"/"&YEAR(R18) -> 5/2026 | AW18: =WEEKNUM(R18)-WEEKNUM(EOMONTH(R18,-1)+1)+1 -> 3 | AX18: =IF(BB18="S",IF(Q18="1. Aceitou o programa",R18-B18,0),0) -> 72 | AY18: =IF(BB18="S",IF(AND(S18<>"",R18<>""),S18-R18,0),0) -> 0 | AZ18: =IF(BB18="S",IF(Q18="1. Aceitou o programa",IF(OR(X18="Não se Aplica",X18=""),IF(OR(W18="Não se Aplica",W18=""),0,W18-V18),AVERAGE(X18-W18,W18-V18)),0),0) -> 0 | BA18: =IF(BB18="S",IF(AND(Q18="1. Aceitou o programa",AH18="Realizada"),IFERROR(IF(AG18="",0,AG18-R18),0),0),0) -> 0 | BB18: =_xlfn.XLOOKUP(U18,'Lista Suspensa'!$AA$20:$AA$23,'Lista Suspensa'!$AB$20:$AB$23,"N/A") -> S
A19: Fluxo Antigo | B19: 45292 | C19: Captação + Navegação | D19: Empresa - Light | E19: 87552831 | F19: LEONARDO MONTEIRO DO LAGO | H19: 30244 | I19: 43 | J19: M | O19: (21) 9671-52680 | P19: Equipe Emagrecimento | Q19: 1. Aceitou o programa | R19: 45734 | T19: Contato Com Sucesso | U19: Ativo | V19: 45734 | W19: Não se aplica | X19: Não se aplica | Y19: 28/01/2026 11:42:00 contato com sucesso em | Z19: Não Utiliza | AA19: 115 | AB19: 1.72 | AC19: =SUM(AA19/(AB19^2)) -> 38.872363 | AD19: =IF(AC19<18.5,"ABAIXO DO PESO", (IF(AC19<=24.9,"PESO NORMAL", (IF(AC19<=29.9,"SOBREPESO", (IF(AC19<=34.9,"OBESIDADE I", (IF(AC19<=39.9,"OBESIDADE II", (IF(AC19<=999,"OBESIDADE III","VAZIO"))))))))))) -> OBESIDADE II | AE19: AES - Campo Grande | AF19: Aguardando Agendamento | AL19: Linha de Intervenção II | AO19: =IF(R19="","",IF(R19>TODAY(),"0 meses",DATEDIF(R19,TODAY(),"m") & " meses")) -> 14 meses | AP19: Sim | AQ19: Sim | AS19: Emagrecimento | AT19: =MONTH(B19)&"/"&YEAR(B19) -> 1/2024 | AU19: =WEEKNUM(B19)-WEEKNUM(EOMONTH(B19,-1)+1)+1 -> 1 | AV19: =MONTH(R19)&"/"&YEAR(R19) -> 3/2025 | AW19: =WEEKNUM(R19)-WEEKNUM(EOMONTH(R19,-1)+1)+1 -> 4 | AX19: =IF(BB19="S",IF(Q19="1. Aceitou o programa",R19-B19,0),0) -> 442 | AY19: =IF(BB19="S",IF(AND(S19<>"",R19<>""),S19-R19,0),0) -> 0 | AZ19: =IF(BB19="S",IF(Q19="1. Aceitou o programa",IF(OR(X19="Não se Aplica",X19=""),IF(OR(W19="Não se Aplica",W19=""),0,W19-V19),AVERAGE(X19-W19,W19-V19)),0),0) -> 0 | BA19: =IF(BB19="S",IF(AND(Q19="1. Aceitou o programa",AH19="Realizada"),IFERROR(IF(AG19="",0,AG19-R19),0),0),0) -> 0 | BB19: =_xlfn.XLOOKUP(U19,'Lista Suspensa'!$AA$20:$AA$23,'Lista Suspensa'!$AB$20:$AB$23,"N/A") -> S
A20: Fluxo Antigo | B20: 45292 | C20: Captação + Navegação | D20: Empresa - Light | E20: 87554321 | F20: WILLIAM BRAGA TELLES | H20: 34361 | I20: 32 | J20: M | O20: (21) 964622733 | P20: Equipe Emagrecimento | Q20: 1. Aceitou o programa | R20: 45734 | T20: Contato Com Sucesso | U20: Ativo | V20: 45734 | W20: Não se aplica | X20: Não se aplica | Z20: Mounjaro | AA20: 127 | AB20: 1.85 | AC20: =SUM(AA20/(AB20^2)) -> 37.107378 | AD20: =IF(AC20<18.5,"ABAIXO DO PESO", (IF(AC20<=24.9,"PESO NORMAL", (IF(AC20<=29.9,"SOBREPESO", (IF(AC20<=34.9,"OBESIDADE I", (IF(AC20<=39.9,"OBESIDADE II", (IF(AC20<=999,"OBESIDADE III","VAZIO"))))))))))) -> OBESIDADE II | AE20: CMDP - Centro Médico Dom Pedro | AF20: Aguardando Agendamento | AL20: Linha de Intervenção I | AO20: =IF(R20="","",IF(R20>TODAY(),"0 meses",DATEDIF(R20,TODAY(),"m") & " meses")) -> 14 meses | AP20: Sim | AQ20: Sim | AS20: Emagrecimento | AT20: =MONTH(B20)&"/"&YEAR(B20) -> 1/2024 | AU20: =WEEKNUM(B20)-WEEKNUM(EOMONTH(B20,-1)+1)+1 -> 1 | AV20: =MONTH(R20)&"/"&YEAR(R20) -> 3/2025 | AW20: =WEEKNUM(R20)-WEEKNUM(EOMONTH(R20,-1)+1)+1 -> 4 | AX20: =IF(BB20="S",IF(Q20="1. Aceitou o programa",R20-B20,0),0) -> 442 | AY20: =IF(BB20="S",IF(AND(S20<>"",R20<>""),S20-R20,0),0) -> 0 | AZ20: =IF(BB20="S",IF(Q20="1. Aceitou o programa",IF(OR(X20="Não se Aplica",X20=""),IF(OR(W20="Não se Aplica",W20=""),0,W20-V20),AVERAGE(X20-W20,W20-V20)),0),0) -> 0 | BA20: =IF(BB20="S",IF(AND(Q20="1. Aceitou o programa",AH20="Realizada"),IFERROR(IF(AG20="",0,AG20-R20),0),0),0) -> 0 | BB20: =_xlfn.XLOOKUP(U20,'Lista Suspensa'!$AA$20:$AA$23,'Lista Suspensa'!$AB$20:$AB$23,"N/A") -> S
A21: Fluxo Antigo | B21: 45292 | C21: Captação + Navegação | D21: Empresa - Light | E21: 87554718 | F21: WAGNER DO BONFIM CORDEIRO | H21: 23935 | I21: 60 | J21: M | K21: RJ | O21: (21) 9700-52967 | P21: Equipe Emagrecimento | Q21: 1. Aceitou o programa | R21: 45735 | T21: Contato Com Sucesso | U21: Ativo | V21: 45735 | W21: Não se aplica | X21: Não se aplica | Z21: Não Utiliza | AA21: 125 | AB21: 1.75 | AC21: =SUM(AA21/(AB21^2)) -> 40.816327 | AD21: =IF(AC21<18.5,"ABAIXO DO PESO", (IF(AC21<=24.9,"PESO NORMAL", (IF(AC21<=29.9,"SOBREPESO", (IF(AC21<=34.9,"OBESIDADE I", (IF(AC21<=39.9,"OBESIDADE II", (IF(AC21<=999,"OBESIDADE III","VAZIO"))))))))))) -> OBESIDADE III | AE21: AES - Niteroi | AF21: Aguardando Agendamento | AL21: Linha de Intervenção II | AO21: =IF(R21="","",IF(R21>TODAY(),"0 meses",DATEDIF(R21,TODAY(),"m") & " meses")) -> 14 meses | AP21: Sim | AQ21: Sim | AS21: Emagrecimento | AT21: =MONTH(B21)&"/"&YEAR(B21) -> 1/2024 | AU21: =WEEKNUM(B21)-WEEKNUM(EOMONTH(B21,-1)+1)+1 -> 1 | AV21: =MONTH(R21)&"/"&YEAR(R21) -> 3/2025 | AW21: =WEEKNUM(R21)-WEEKNUM(EOMONTH(R21,-1)+1)+1 -> 4 | AX21: =IF(BB21="S",IF(Q21="1. Aceitou o programa",R21-B21,0),0) -> 443 | AY21: =IF(BB21="S",IF(AND(S21<>"",R21<>""),S21-R21,0),0) -> 0 | AZ21: =IF(BB21="S",IF(Q21="1. Aceitou o programa",IF(OR(X21="Não se Aplica",X21=""),IF(OR(W21="Não se Aplica",W21=""),0,W21-V21),AVERAGE(X21-W21,W21-V21)),0),0) -> 0 | BA21: =IF(BB21="S",IF(AND(Q21="1. Aceitou o programa",AH21="Realizada"),IFERROR(IF(AG21="",0,AG21-R21),0),0),0) -> 0 | BB21: =_xlfn.XLOOKUP(U21,'Lista Suspensa'!$AA$20:$AA$23,'Lista Suspensa'!$AB$20:$AB$23,"N/A") -> S
A22: Fluxo Antigo | B22: 45292 | C22: Captação + Navegação | D22: Empresa - Light | E22: 806074787 | F22: JOSE LUIZ DA SILVA | H22: 19582 | I22: 72 | J22: M | K22: SP | O22: (24) 988362520 | P22: Equipe Emagrecimento | Q22: 1. Aceitou o programa | R22: 45735 | T22: Contato Com Sucesso | U22: Ativo | V22: 45735 | W22: 46147 | X22: Não se aplica | Y22: Telemonitoramento com múltiplas tentativas de contato - mais de 3 em meses diferentes | Z22: Não Utiliza | AA22: 147 | AB22: 1.65 | AC22: =SUM(AA22/(AB22^2)) -> 53.99449 | AD22: =IF(AC22<18.5,"ABAIXO DO PESO", (IF(AC22<=24.9,"PESO NORMAL", (IF(AC22<=29.9,"SOBREPESO", (IF(AC22<=34.9,"OBESIDADE I", (IF(AC22<=39.9,"OBESIDADE II", (IF(AC22<=999,"OBESIDADE III","VAZIO"))))))))))) -> OBESIDADE III | AE22: CMDP - Centro Médico Dom Pedro | AF22: Aguardando Agendamento | AL22: Critério de Grade Especial | AO22: =IF(R22="","",IF(R22>TODAY(),"0 meses",DATEDIF(R22,TODAY(),"m") & " meses")) -> 14 meses | AP22: Sim | AQ22: Sim | AS22: Emagrecimento | AT22: =MONTH(B22)&"/"&YEAR(B22) -> 1/2024 | AU22: =WEEKNUM(B22)-WEEKNUM(EOMONTH(B22,-1)+1)+1 -> 1 | AV22: =MONTH(R22)&"/"&YEAR(R22) -> 3/2025 | AW22: =WEEKNUM(R22)-WEEKNUM(EOMONTH(R22,-1)+1)+1 -> 4 | AX22: =IF(BB22="S",IF(Q22="1. Aceitou o programa",R22-B22,0),0) -> 443 | AY22: =IF(BB22="S",IF(AND(S22<>"",R22<>""),S22-R22,0),0) -> 0 | AZ22: =IF(BB22="S",IF(Q22="1. Aceitou o programa",IF(OR(X22="Não se Aplica",X22=""),IF(OR(W22="Não se Aplica",W22=""),0,W22-V22),AVERAGE(X22-W22,W22-V22)),0),0) -> 412 | BA22: =IF(BB22="S",IF(AND(Q22="1. Aceitou o programa",AH22="Realizada"),IFERROR(IF(AG22="",0,AG22-R22),0),0),0) -> 0 | BB22: =_xlfn.XLOOKUP(U22,'Lista Suspensa'!$AA$20:$AA$23,'Lista Suspensa'!$AB$20:$AB$23,"N/A") -> S
A23: Fluxo Antigo | B23: 45292 | C23: Captação + Navegação | D23: Empresa - Light | E23: 87555996 | F23: SIDNEI MARCELO DOS SANTOS | H23: 25049 | I23: 57 | J23: M | K23: RJ | O23: 21999513007 | P23: Equipe Emagrecimento | Q23: 1. Aceitou o programa | R23: 45736 | T23: Contato Com Sucesso | U23: Ativo | V23: 45736 | W23: Não se aplica | X23: Não se aplica | Z23: Não Utiliza | AA23: 138 | AB23: 1.83 | AC23: =SUM(AA23/(AB23^2)) -> 41.207561 | AD23: =IF(AC23<18.5,"ABAIXO DO PESO", (IF(AC23<=24.9,"PESO NORMAL", (IF(AC23<=29.9,"SOBREPESO", (IF(AC23<=34.9,"OBESIDADE I", (IF(AC23<=39.9,"OBESIDADE II", (IF(AC23<=999,"OBESIDADE III","VAZIO"))))))))))) -> OBESIDADE III | AE23: CMDP - Centro Médico Dom Pedro | AF23: Aguardando Agendamento | AL23: Linha de Intervenção II | AO23: =IF(R23="","",IF(R23>TODAY(),"0 meses",DATEDIF(R23,TODAY(),"m") & " meses")) -> 14 meses | AP23: Sim | AQ23: Sim | AS23: Emagrecimento | AT23: =MONTH(B23)&"/"&YEAR(B23) -> 1/2024 | AU23: =WEEKNUM(B23)-WEEKNUM(EOMONTH(B23,-1)+1)+1 -> 1 | AV23: =MONTH(R23)&"/"&YEAR(R23) -> 3/2025 | AW23: =WEEKNUM(R23)-WEEKNUM(EOMONTH(R23,-1)+1)+1 -> 4 | AX23: =IF(BB23="S",IF(Q23="1. Aceitou o programa",R23-B23,0),0) -> 444 | AY23: =IF(BB23="S",IF(AND(S23<>"",R23<>""),S23-R23,0),0) -> 0 | AZ23: =IF(BB23="S",IF(Q23="1. Aceitou o programa",IF(OR(X23="Não se Aplica",X23=""),IF(OR(W23="Não se Aplica",W23=""),0,W23-V23),AVERAGE(X23-W23,W23-V23)),0),0) -> 0 | BA23: =IF(BB23="S",IF(AND(Q23="1. Aceitou o programa",AH23="Realizada"),IFERROR(IF(AG23="",0,AG23-R23),0),0),0) -> 0 | BB23: =_xlfn.XLOOKUP(U23,'Lista Suspensa'!$AA$20:$AA$23,'Lista Suspensa'!$AB$20:$AB$23,"N/A") -> S
A24: Fluxo Antigo | B24: 45292 | C24: Captação + Navegação | D24: Empresa - Light | E24: 87553741 | F24: ROBSON MUNIZ DE AMORIM | H24: 27649 | I24: 50 | J24: M | K24: RJ | O24: (21) 9891-67278 | P24: Equipe Emagrecimento | Q24: 1. Aceitou o programa | R24: 45736 | T24: Contato Com Sucesso | U24: Ativo | V24: 45736 | W24: Não se aplica | X24: Não se aplica | Y24: 03/02/2026 13:30:00 contato com sucesso em | Z24: Não Utiliza | AA24: 127 | AB24: 1.77 | AC24: =SUM(AA24/(AB24^2)) -> 40.537521 | AD24: =IF(AC24<18.5,"ABAIXO DO PESO", (IF(AC24<=24.9,"PESO NORMAL", (IF(AC24<=29.9,"SOBREPESO", (IF(AC24<=34.9,"OBESIDADE I", (IF(AC24<=39.9,"OBESIDADE II", (IF(AC24<=999,"OBESIDADE III","VAZIO"))))))))))) -> OBESIDADE III | AE24: CMDP - Centro Médico Dom Pedro | AF24: Aguardando Agendamento | AL24: Linha de Intervenção II | AO24: =IF(R24="","",IF(R24>TODAY(),"0 meses",DATEDIF(R24,TODAY(),"m") & " meses")) -> 14 meses | AP24: Sim | AQ24: Sim | AS24: Emagrecimento | AT24: =MONTH(B24)&"/"&YEAR(B24) -> 1/2024 | AU24: =WEEKNUM(B24)-WEEKNUM(EOMONTH(B24,-1)+1)+1 -> 1 | AV24: =MONTH(R24)&"/"&YEAR(R24) -> 3/2025 | AW24: =WEEKNUM(R24)-WEEKNUM(EOMONTH(R24,-1)+1)+1 -> 4 | AX24: =IF(BB24="S",IF(Q24="1. Aceitou o programa",R24-B24,0),0) -> 444 | AY24: =IF(BB24="S",IF(AND(S24<>"",R24<>""),S24-R24,0),0) -> 0 | AZ24: =IF(BB24="S",IF(Q24="1. Aceitou o programa",IF(OR(X24="Não se Aplica",X24=""),IF(OR(W24="Não se Aplica",W24=""),0,W24-V24),AVERAGE(X24-W24,W24-V24)),0),0) -> 0 | BA24: =IF(BB24="S",IF(AND(Q24="1. Aceitou o programa",AH24="Realizada"),IFERROR(IF(AG24="",0,AG24-R24),0),0),0) -> 0 | BB24: =_xlfn.XLOOKUP(U24,'Lista Suspensa'!$AA$20:$AA$23,'Lista Suspensa'!$AB$20:$AB$23,"N/A") -> S
A25: Fluxo Antigo | B25: 45292 | C25: Captação + Navegação | D25: Empresa - Light | E25: 87556502 | F25: CARLOS EDUARDO DE SOUSA | H25: 28749 | I25: 47 | J25: M | K25: RJ | O25: 21987478413 | P25: Equipe Emagrecimento | Q25: 1. Aceitou o programa | R25: 45737 | T25: Contato Com Sucesso | U25: Ativo | V25: 45737 | W25: Não se aplica | X25: Não se aplica | Z25: Não Utiliza | AA25: 118 | AB25: 1.69 | AC25: =SUM(AA25/(AB25^2)) -> 41.31508 | AD25: =IF(AC25<18.5,"ABAIXO DO PESO", (IF(AC25<=24.9,"PESO NORMAL", (IF(AC25<=29.9,"SOBREPESO", (IF(AC25<=34.9,"OBESIDADE I", (IF(AC25<=39.9,"OBESIDADE II", (IF(AC25<=999,"OBESIDADE III","VAZIO"))))))))))) -> OBESIDADE III | AE25: CMDP - Centro Médico Dom Pedro | AF25: Aguardando Agendamento | AL25: Linha de Intervenção I | AO25: =IF(R25="","",IF(R25>TODAY(),"0 meses",DATEDIF(R25,TODAY(),"m") & " meses")) -> 14 meses | AP25: Sim | AQ25: Sim | AS25: Emagrecimento | AT25: =MONTH(B25)&"/"&YEAR(B25) -> 1/2024 | AU25: =WEEKNUM(B25)-WEEKNUM(EOMONTH(B25,-1)+1)+1 -> 1 | AV25: =MONTH(R25)&"/"&YEAR(R25) -> 3/2025 | AW25: =WEEKNUM(R25)-WEEKNUM(EOMONTH(R25,-1)+1)+1 -> 4 | AX25: =IF(BB25="S",IF(Q25="1. Aceitou o programa",R25-B25,0),0) -> 445 | AY25: =IF(BB25="S",IF(AND(S25<>"",R25<>""),S25-R25,0),0) -> 0 | AZ25: =IF(BB25="S",IF(Q25="1. Aceitou o programa",IF(OR(X25="Não se Aplica",X25=""),IF(OR(W25="Não se Aplica",W25=""),0,W25-V25),AVERAGE(X25-W25,W25-V25)),0),0) -> 0 | BA25: =IF(BB25="S",IF(AND(Q25="1. Aceitou o programa",AH25="Realizada"),IFERROR(IF(AG25="",0,AG25-R25),0),0),0) -> 0 | BB25: =_xlfn.XLOOKUP(U25,'Lista Suspensa'!$AA$20:$AA$23,'Lista Suspensa'!$AB$20:$AB$23,"N/A") -> S
A26: Fluxo Antigo | B26: 45292 | C26: Captação + Navegação | D26: Empresa - Light | E26: 87554774 | F26: ALESSANDRO MARQUES DA COSTA THEODORO | H26: 31439 | I26: 40 | J26: M | O26: 21964260716 | P26: Equipe Emagrecimento | Q26: 1. Aceitou o programa | R26: 45740 | T26: Contato Com Sucesso | U26: Ativo | V26: 45740 | W26: Não se aplica | X26: Não se aplica | Y26: Telemonitoramento com múltiplas tentativas de contato - mais de 3 em meses diferentes | Z26: Não Utiliza | AA26: 125 | AB26: 1.74 | AC26: =SUM(AA26/(AB26^2)) -> 41.286828 | AD26: =IF(AC26<18.5,"ABAIXO DO PESO", (IF(AC26<=24.9,"PESO NORMAL", (IF(AC26<=29.9,"SOBREPESO", (IF(AC26<=34.9,"OBESIDADE I", (IF(AC26<=39.9,"OBESIDADE II", (IF(AC26<=999,"OBESIDADE III","VAZIO"))))))))))) -> OBESIDADE III | AE26: CMDP - Centro Médico Dom Pedro | AF26: Aguardando Agendamento | AL26: Linha de Intervenção II | AO26: =IF(R26="","",IF(R26>TODAY(),"0 meses",DATEDIF(R26,TODAY(),"m") & " meses")) -> 14 meses | AP26: Sim | AQ26: Sim | AS26: Emagrecimento | AT26: =MONTH(B26)&"/"&YEAR(B26) -> 1/2024 | AU26: =WEEKNUM(B26)-WEEKNUM(EOMONTH(B26,-1)+1)+1 -> 1 | AV26: =MONTH(R26)&"/"&YEAR(R26) -> 3/2025 | AW26: =WEEKNUM(R26)-WEEKNUM(EOMONTH(R26,-1)+1)+1 -> 5 | AX26: =IF(BB26="S",IF(Q26="1. Aceitou o programa",R26-B26,0),0) -> 448 | AY26: =IF(BB26="S",IF(AND(S26<>"",R26<>""),S26-R26,0),0) -> 0 | AZ26: =IF(BB26="S",IF(Q26="1. Aceitou o programa",IF(OR(X26="Não se Aplica",X26=""),IF(OR(W26="Não se Aplica",W26=""),0,W26-V26),AVERAGE(X26-W26,W26-V26)),0),0) -> 0 | BA26: =IF(BB26="S",IF(AND(Q26="1. Aceitou o programa",AH26="Realizada"),IFERROR(IF(AG26="",0,AG26-R26),0),0),0) -> 0 | BB26: =_xlfn.XLOOKUP(U26,'Lista Suspensa'!$AA$20:$AA$23,'Lista Suspensa'!$AB$20:$AB$23,"N/A") -> S
A27: Fluxo Antigo | B27: 45292 | C27: Captação + Navegação | D27: Empresa - Light | E27: 87555136 | F27: THIAGO SA JUNIOR | H27: 31553 | I27: 39 | J27: M | O27: 21993239225 | P27: Equipe Emagrecimento | Q27: 1. Aceitou o programa | R27: 45740 | T27: Contato Com Sucesso | U27: Ativo | V27: 45740 | W27: Não se aplica | X27: Não se aplica | Z27: Não Utiliza | AA27: 130 | AB27: 1.7 | AC27: =SUM(AA27/(AB27^2)) -> 44.982699 | AD27: =IF(AC27<18.5,"ABAIXO DO PESO", (IF(AC27<=24.9,"PESO NORMAL", (IF(AC27<=29.9,"SOBREPESO", (IF(AC27<=34.9,"OBESIDADE I", (IF(AC27<=39.9,"OBESIDADE II", (IF(AC27<=999,"OBESIDADE III","VAZIO"))))))))))) -> OBESIDADE III | AE27: CMDP - Centro Médico Dom Pedro | AF27: Aguardando Agendamento | AL27: Linha de Intervenção II | AO27: =IF(R27="","",IF(R27>TODAY(),"0 meses",DATEDIF(R27,TODAY(),"m") & " meses")) -> 14 meses | AP27: Sim | AQ27: Sim | AS27: Emagrecimento | AT27: =MONTH(B27)&"/"&YEAR(B27) -> 1/2024 | AU27: =WEEKNUM(B27)-WEEKNUM(EOMONTH(B27,-1)+1)+1 -> 1 | AV27: =MONTH(R27)&"/"&YEAR(R27) -> 3/2025 | AW27: =WEEKNUM(R27)-WEEKNUM(EOMONTH(R27,-1)+1)+1 -> 5 | AX27: =IF(BB27="S",IF(Q27="1. Aceitou o programa",R27-B27,0),0) -> 448 | AY27: =IF(BB27="S",IF(AND(S27<>"",R27<>""),S27-R27,0),0) -> 0 | AZ27: =IF(BB27="S",IF(Q27="1. Aceitou o programa",IF(OR(X27="Não se Aplica",X27=""),IF(OR(W27="Não se Aplica",W27=""),0,W27-V27),AVERAGE(X27-W27,W27-V27)),0),0) -> 0 | BA27: =IF(BB27="S",IF(AND(Q27="1. Aceitou o programa",AH27="Realizada"),IFERROR(IF(AG27="",0,AG27-R27),0),0),0) -> 0 | BB27: =_xlfn.XLOOKUP(U27,'Lista Suspensa'!$AA$20:$AA$23,'Lista Suspensa'!$AB$20:$AB$23,"N/A") -> S
A28: Fluxo Antigo | B28: 45292 | C28: Captação + Navegação | D28: Empresa - Light | E28: 87555028 | F28: VALCENIR ANGELO CONSTANTINO | H28: 32102 | I28: 38 | J28: M | O28: (21) 964034709 | P28: Equipe Emagrecimento | Q28: 1. Aceitou o programa | R28: 45742 | T28: Contato Com Sucesso | U28: Ativo | V28: 45742 | W28: Não se aplica | X28: Não se aplica | Y28: 03/02/2026 16:36:00 contato com sucesso em | Z28: Não Utiliza | AA28: 137 | AB28: 1.88 | AC28: =SUM(AA28/(AB28^2)) -> 38.761883 | AD28: =IF(AC28<18.5,"ABAIXO DO PESO", (IF(AC28<=24.9,"PESO NORMAL", (IF(AC28<=29.9,"SOBREPESO", (IF(AC28<=34.9,"OBESIDADE I", (IF(AC28<=39.9,"OBESIDADE II", (IF(AC28<=999,"OBESIDADE III","VAZIO"))))))))))) -> OBESIDADE II | AE28: CMDP - Centro Médico Dom Pedro | AF28: Aguardando Agendamento | AL28: Linha de Intervenção I | AO28: =IF(R28="","",IF(R28>TODAY(),"0 meses",DATEDIF(R28,TODAY(),"m") & " meses")) -> 14 meses | AP28: Sim | AQ28: Sim | AS28: Emagrecimento | AT28: =MONTH(B28)&"/"&YEAR(B28) -> 1/2024 | AU28: =WEEKNUM(B28)-WEEKNUM(EOMONTH(B28,-1)+1)+1 -> 1 | AV28: =MONTH(R28)&"/"&YEAR(R28) -> 3/2025 | AW28: =WEEKNUM(R28)-WEEKNUM(EOMONTH(R28,-1)+1)+1 -> 5 | AX28: =IF(BB28="S",IF(Q28="1. Aceitou o programa",R28-B28,0),0) -> 450 | AY28: =IF(BB28="S",IF(AND(S28<>"",R28<>""),S28-R28,0),0) -> 0 | AZ28: =IF(BB28="S",IF(Q28="1. Aceitou o programa",IF(OR(X28="Não se Aplica",X28=""),IF(OR(W28="Não se Aplica",W28=""),0,W28-V28),AVERAGE(X28-W28,W28-V28)),0),0) -> 0 | BA28: =IF(BB28="S",IF(AND(Q28="1. Aceitou o programa",AH28="Realizada"),IFERROR(IF(AG28="",0,AG28-R28),0),0),0) -> 0 | BB28: =_xlfn.XLOOKUP(U28,'Lista Suspensa'!$AA$20:$AA$23,'Lista Suspensa'!$AB$20:$AB$23,"N/A") -> S
A29: Fluxo Antigo | B29: 45292 | C29: Captação + Navegação | D29: Empresa - Light | E29: 87554581 | F29: JHONNY SULLIVAN COSTA MAIA | H29: 30976 | I29: 41 | J29: M | O29: (24) 99984-8181 | P29: Equipe Emagrecimento | Q29: 1. Aceitou o programa | R29: 45747 | T29: Contato Com Sucesso | U29: Ativo | V29: 45747 | W29: Não se aplica | X29: Não se aplica | Z29: Não Utiliza | AA29: 113 | AB29: 1.81 | AC29: =SUM(AA29/(AB29^2)) -> 34.492232 | AD29: =IF(AC29<18.5,"ABAIXO DO PESO", (IF(AC29<=24.9,"PESO NORMAL", (IF(AC29<=29.9,"SOBREPESO", (IF(AC29<=34.9,"OBESIDADE I", (IF(AC29<=39.9,"OBESIDADE II", (IF(AC29<=999,"OBESIDADE III","VAZIO"))))))))))) -> OBESIDADE I | AE29: CMDP - Centro Médico Dom Pedro | AF29: Aguardando Agendamento | AL29: Linha de Intervenção I | AO29: =IF(R29="","",IF(R29>TODAY(),"0 meses",DATEDIF(R29,TODAY(),"m") & " meses")) -> 14 meses | AP29: Sim | AQ29: Sim | AS29: Emagrecimento | AT29: =MONTH(B29)&"/"&YEAR(B29) -> 1/2024 | AU29: =WEEKNUM(B29)-WEEKNUM(EOMONTH(B29,-1)+1)+1 -> 1 | AV29: =MONTH(R29)&"/"&YEAR(R29) -> 3/2025 | AW29: =WEEKNUM(R29)-WEEKNUM(EOMONTH(R29,-1)+1)+1 -> 6 | AX29: =IF(BB29="S",IF(Q29="1. Aceitou o programa",R29-B29,0),0) -> 455 | AY29: =IF(BB29="S",IF(AND(S29<>"",R29<>""),S29-R29,0),0) -> 0 | AZ29: =IF(BB29="S",IF(Q29="1. Aceitou o programa",IF(OR(X29="Não se Aplica",X29=""),IF(OR(W29="Não se Aplica",W29=""),0,W29-V29),AVERAGE(X29-W29,W29-V29)),0),0) -> 0 | BA29: =IF(BB29="S",IF(AND(Q29="1. Aceitou o programa",AH29="Realizada"),IFERROR(IF(AG29="",0,AG29-R29),0),0),0) -> 0 | BB29: =_xlfn.XLOOKUP(U29,'Lista Suspensa'!$AA$20:$AA$23,'Lista Suspensa'!$AB$20:$AB$23,"N/A") -> S
A30: Fluxo Antigo | B30: 45292 | C30: Captação + Navegação | D30: Empresa - Light | E30: 87556485 | F30: JOHNATAN JACKSON DE JESUS RIBEIRO DOS SANTOS | H30: 33094 | I30: 35 | J30: M | O30: (21) 9841-68131 | P30: Equipe Emagrecimento | Q30: 1. Aceitou o programa | R30: 45747 | T30: Contato Com Sucesso | U30: Ativo | V30: 45747 | W30: Não se aplica | X30: Não se aplica | Z30: Mounjaro | AA30: 118 | AB30: 1.85 | AC30: =SUM(AA30/(AB30^2)) -> 34.477721 | AD30: =IF(AC30<18.5,"ABAIXO DO PESO", (IF(AC30<=24.9,"PESO NORMAL", (IF(AC30<=29.9,"SOBREPESO", (IF(AC30<=34.9,"OBESIDADE I", (IF(AC30<=39.9,"OBESIDADE II", (IF(AC30<=999,"OBESIDADE III","VAZIO"))))))))))) -> OBESIDADE I | AE30: CMDP - Centro Médico Dom Pedro | AF30: Aguardando Agendamento | AL30: Linha de Intervenção I | AO30: =IF(R30="","",IF(R30>TODAY(),"0 meses",DATEDIF(R30,TODAY(),"m") & " meses")) -> 14 meses | AP30: Sim | AQ30: Sim | AS30: Emagrecimento | AT30: =MONTH(B30)&"/"&YEAR(B30) -> 1/2024 | AU30: =WEEKNUM(B30)-WEEKNUM(EOMONTH(B30,-1)+1)+1 -> 1 | AV30: =MONTH(R30)&"/"&YEAR(R30) -> 3/2025 | AW30: =WEEKNUM(R30)-WEEKNUM(EOMONTH(R30,-1)+1)+1 -> 6 | AX30: =IF(BB30="S",IF(Q30="1. Aceitou o programa",R30-B30,0),0) -> 455 | AY30: =IF(BB30="S",IF(AND(S30<>"",R30<>""),S30-R30,0),0) -> 0 | AZ30: =IF(BB30="S",IF(Q30="1. Aceitou o programa",IF(OR(X30="Não se Aplica",X30=""),IF(OR(W30="Não se Aplica",W30=""),0,W30-V30),AVERAGE(X30-W30,W30-V30)),0),0) -> 0 | BA30: =IF(BB30="S",IF(AND(Q30="1. Aceitou o programa",AH30="Realizada"),IFERROR(IF(AG30="",0,AG30-R30),0),0),0) -> 0 | BB30: =_xlfn.XLOOKUP(U30,'Lista Suspensa'!$AA$20:$AA$23,'Lista Suspensa'!$AB$20:$AB$23,"N/A") -> S
A31: Não | B31: 46083 | C31: Transbordo Navegação | D31: Captado pela Amil | E31: 87733471 | F31: VANESSA GATTI CLEMENTE | H31: 31378 | I31: 40 | J31: F | N31: 60 | O31: 11-947416688 | P31: Daniela | Q31: 1. Aceitou o programa | R31: 45762 | T31: Contato Com Sucesso | U31: Ativo | V31: 46118 | W31: 46142 | X31: 46150 | Y31: 29/04/2026 17:48:00 contato com sucesso em | Z31: Não Utiliza | AA31: 103 | AB31: 1.67 | AC31: =SUM(AA31/(AB31^2)) -> 36.932124 | AD31: =IF(AC31<18.5,"ABAIXO DO PESO", (IF(AC31<=24.9,"PESO NORMAL", (IF(AC31<=29.9,"SOBREPESO", (IF(AC31<=34.9,"OBESIDADE I", (IF(AC31<=39.9,"OBESIDADE II", (IF(AC31<=999,"OBESIDADE III","VAZIO"))))))))))) -> OBESIDADE II | AE31: Sem Dados | AF31: Agendada | AG31: 09/06/2026 13:40 | AL31: Linha de Intervenção II | AO31: =IF(R31="","",IF(R31>TODAY(),"0 meses",DATEDIF(R31,TODAY(),"m") & " meses")) -> 13 meses | AP31: Sim | AQ31: Sim | AS31: Emagrecimento | AT31: =MONTH(B31)&"/"&YEAR(B31) -> 3/2026 | AU31: =WEEKNUM(B31)-WEEKNUM(EOMONTH(B31,-1)+1)+1 -> 1 | AV31: =MONTH(R31)&"/"&YEAR(R31) -> 4/2025 | AW31: =WEEKNUM(R31)-WEEKNUM(EOMONTH(R31,-1)+1)+1 -> 3 | AX31: =IF(BB31="S",IF(Q31="1. Aceitou o programa",R31-B31,0),0) -> -321 | AY31: =IF(BB31="S",IF(AND(S31<>"",R31<>""),S31-R31,0),0) -> 0 | AZ31: =IF(BB31="S",IF(Q31="1. Aceitou o programa",IF(OR(X31="Não se Aplica",X31=""),IF(OR(W31="Não se Aplica",W31=""),0,W31-V31),AVERAGE(X31-W31,W31-V31)),0),0) -> 16 | BA31: =IF(BB31="S",IF(AND(Q31="1. Aceitou o programa",AH31="Realizada"),IFERROR(IF(AG31="",0,AG31-R31),0),0),0) -> 0 | BB31: =_xlfn.XLOOKUP(U31,'Lista Suspensa'!$AA$20:$AA$23,'Lista Suspensa'!$AB$20:$AB$23,"N/A") -> S
A32: Fluxo Antigo | B32: 45292 | C32: Captação + Navegação | D32: CMDP Endocrino - Eduardo Cechinel Passos | E32: 77794439 | F32: ANDERSON GOMES DE ALMEIDA | H32: 27307 | I32: 51 | J32: M | O32: (11) 94830-8363 | P32: Equipe Emagrecimento | Q32: 1. Aceitou o programa | R32: 45786 | T32: Contato Com Sucesso | U32: Ativo | V32: 45786 | W32: Não se aplica | X32: Não se aplica | Z32: Rybelsus | AA32: 105 | AB32: 1.74 | AC32: =SUM(AA32/(AB32^2)) -> 34.680935 | AD32: =IF(AC32<18.5,"ABAIXO DO PESO", (IF(AC32<=24.9,"PESO NORMAL", (IF(AC32<=29.9,"SOBREPESO", (IF(AC32<=34.9,"OBESIDADE I", (IF(AC32<=39.9,"OBESIDADE II", (IF(AC32<=999,"OBESIDADE III","VAZIO"))))))))))) -> OBESIDADE I | AE32: CMDP - Centro Médico Dom Pedro | AF32: Aguardando Agendamento | AL32: Linha de Intervenção II | AO32: =IF(R32="","",IF(R32>TODAY(),"0 meses",DATEDIF(R32,TODAY(),"m") & " meses")) -> 13 meses | AP32: Sim | AQ32: Sim | AS32: Emagrecimento | AT32: =MONTH(B32)&"/"&YEAR(B32) -> 1/2024 | AU32: =WEEKNUM(B32)-WEEKNUM(EOMONTH(B32,-1)+1)+1 -> 1 | AV32: =MONTH(R32)&"/"&YEAR(R32) -> 5/2025 | AW32: =WEEKNUM(R32)-WEEKNUM(EOMONTH(R32,-1)+1)+1 -> 2 | AX32: =IF(BB32="S",IF(Q32="1. Aceitou o programa",R32-B32,0),0) -> 494 | AY32: =IF(BB32="S",IF(AND(S32<>"",R32<>""),S32-R32,0),0) -> 0 | AZ32: =IF(BB32="S",IF(Q32="1. Aceitou o programa",IF(OR(X32="Não se Aplica",X32=""),IF(OR(W32="Não se Aplica",W32=""),0,W32-V32),AVERAGE(X32-W32,W32-V32)),0),0) -> 0 | BA32: =IF(BB32="S",IF(AND(Q32="1. Aceitou o programa",AH32="Realizada"),IFERROR(IF(AG32="",0,AG32-R32),0),0),0) -> 0 | BB32: =_xlfn.XLOOKUP(U32,'Lista Suspensa'!$AA$20:$AA$23,'Lista Suspensa'!$AB$20:$AB$23,"N/A") -> S
A33: Fluxo Antigo | B33: 45292 | C33: Captação + Navegação | D33: Equipe - Clínica Sallet | E33: 85853351 | F33: ADINOAN FELIZ DA SILVA FERREIRA | H33: 29241 | I33: 46 | J33: F | O33: 11946806114 | P33: Equipe Emagrecimento | Q33: 1. Aceitou o programa | R33: 45812 | T33: Contato Com Sucesso | U33: Ativo | V33: 45812 | W33: Não se aplica | X33: Não se aplica | Z33: Rybelsus | AA33: 95.5 | AB33: 1.65 | AC33: =SUM(AA33/(AB33^2)) -> 35.078053 | AD33: =IF(AC33<18.5,"ABAIXO DO PESO", (IF(AC33<=24.9,"PESO NORMAL", (IF(AC33<=29.9,"SOBREPESO", (IF(AC33<=34.9,"OBESIDADE I", (IF(AC33<=39.9,"OBESIDADE II", (IF(AC33<=999,"OBESIDADE III","VAZIO"))))))))))) -> OBESIDADE II | AE33: CMDP - Centro Médico Dom Pedro | AF33: Aguardando Agendamento | AL33: Linha de Intervenção II | AO33: =IF(R33="","",IF(R33>TODAY(),"0 meses",DATEDIF(R33,TODAY(),"m") & " meses")) -> 12 meses | AP33: Sim | AQ33: Sim | AS33: Emagrecimento | AT33: =MONTH(B33)&"/"&YEAR(B33) -> 1/2024 | AU33: =WEEKNUM(B33)-WEEKNUM(EOMONTH(B33,-1)+1)+1 -> 1 | AV33: =MONTH(R33)&"/"&YEAR(R33) -> 6/2025 | AW33: =WEEKNUM(R33)-WEEKNUM(EOMONTH(R33,-1)+1)+1 -> 1 | AX33: =IF(BB33="S",IF(Q33="1. Aceitou o programa",R33-B33,0),0) -> 520 | AY33: =IF(BB33="S",IF(AND(S33<>"",R33<>""),S33-R33,0),0) -> 0 | AZ33: =IF(BB33="S",IF(Q33="1. Aceitou o programa",IF(OR(X33="Não se Aplica",X33=""),IF(OR(W33="Não se Aplica",W33=""),0,W33-V33),AVERAGE(X33-W33,W33-V33)),0),0) -> 0 | BA33: =IF(BB33="S",IF(AND(Q33="1. Aceitou o programa",AH33="Realizada"),IFERROR(IF(AG33="",0,AG33-R33),0),0),0) -> 0 | BB33: =_xlfn.XLOOKUP(U33,'Lista Suspensa'!$AA$20:$AA$23,'Lista Suspensa'!$AB$20:$AB$23,"N/A") -> S
A34: Fluxo Antigo | B34: 45292 | C34: Captação + Navegação | D34: Captado pela Amil | E34: 85230301 | F34: LUANA RAMOS DA SILVA | H34: 34684 | I34: 31 | J34: F | O34: (11) 947086731 | P34: Equipe Emagrecimento | Q34: 1. Aceitou o programa | R34: 45813 | T34: Contato Com Sucesso | U34: Ativo | V34: 45813 | W34: Não se aplica | X34: Não se aplica | Z34: Não Utiliza | AA34: 133 | AB34: 1.67 | AC34: =SUM(AA34/(AB34^2)) -> 47.689053 | AD34: =IF(AC34<18.5,"ABAIXO DO PESO", (IF(AC34<=24.9,"PESO NORMAL", (IF(AC34<=29.9,"SOBREPESO", (IF(AC34<=34.9,"OBESIDADE I", (IF(AC34<=39.9,"OBESIDADE II", (IF(AC34<=999,"OBESIDADE III","VAZIO"))))))))))) -> OBESIDADE III | AE34: CMDP - Centro Médico Dom Pedro | AF34: Aguardando Agendamento | AL34: Linha de Intervenção II | AO34: =IF(R34="","",IF(R34>TODAY(),"0 meses",DATEDIF(R34,TODAY(),"m") & " meses")) -> 12 meses | AP34: Sim | AQ34: Sim | AS34: Emagrecimento | AT34: =MONTH(B34)&"/"&YEAR(B34) -> 1/2024 | AU34: =WEEKNUM(B34)-WEEKNUM(EOMONTH(B34,-1)+1)+1 -> 1 | AV34: =MONTH(R34)&"/"&YEAR(R34) -> 6/2025 | AW34: =WEEKNUM(R34)-WEEKNUM(EOMONTH(R34,-1)+1)+1 -> 1 | AX34: =IF(BB34="S",IF(Q34="1. Aceitou o programa",R34-B34,0),0) -> 521 | AY34: =IF(BB34="S",IF(AND(S34<>"",R34<>""),S34-R34,0),0) -> 0 | AZ34: =IF(BB34="S",IF(Q34="1. Aceitou o programa",IF(OR(X34="Não se Aplica",X34=""),IF(OR(W34="Não se Aplica",W34=""),0,W34-V34),AVERAGE(X34-W34,W34-V34)),0),0) -> 0 | BA34: =IF(BB34="S",IF(AND(Q34="1. Aceitou o programa",AH34="Realizada"),IFERROR(IF(AG34="",0,AG34-R34),0),0),0) -> 0 | BB34: =_xlfn.XLOOKUP(U34,'Lista Suspensa'!$AA$20:$AA$23,'Lista Suspensa'!$AB$20:$AB$23,"N/A") -> S
A35: Fluxo Antigo | B35: 45292 | C35: Captação + Navegação | D35: Equipe - Dr. Michel Menezes | E35: 89341266 | F35: CARINA DE OLIVEIRA SILVA | H35: 34648 | I35: 31 | J35: F | O35: 21977208008 | P35: Equipe Emagrecimento | Q35: 1. Aceitou o programa | R35: 45818 | T35: Contato Com Sucesso | U35: Ativo | V35: 45818 | W35: Não se aplica | X35: Não se aplica | Z35: Mounjaro | AA35: 96 | AB35: 1.68 | AC35: =SUM(AA35/(AB35^2)) -> 34.013605 | AD35: =IF(AC35<18.5,"ABAIXO DO PESO", (IF(AC35<=24.9,"PESO NORMAL", (IF(AC35<=29.9,"SOBREPESO", (IF(AC35<=34.9,"OBESIDADE I", (IF(AC35<=39.9,"OBESIDADE II", (IF(AC35<=999,"OBESIDADE III","VAZIO"))))))))))) -> OBESIDADE I | AE35: CMDP - Centro Médico Dom Pedro | AF35: Aguardando Agendamento | AL35: Linha de Intervenção II | AO35: =IF(R35="","",IF(R35>TODAY(),"0 meses",DATEDIF(R35,TODAY(),"m") & " meses")) -> 12 meses | AP35: Sim | AQ35: Sim | AS35: Emagrecimento | AT35: =MONTH(B35)&"/"&YEAR(B35) -> 1/2024 | AU35: =WEEKNUM(B35)-WEEKNUM(EOMONTH(B35,-1)+1)+1 -> 1 | AV35: =MONTH(R35)&"/"&YEAR(R35) -> 6/2025 | AW35: =WEEKNUM(R35)-WEEKNUM(EOMONTH(R35,-1)+1)+1 -> 2 | AX35: =IF(BB35="S",IF(Q35="1. Aceitou o programa",R35-B35,0),0) -> 526 | AY35: =IF(BB35="S",IF(AND(S35<>"",R35<>""),S35-R35,0),0) -> 0 | AZ35: =IF(BB35="S",IF(Q35="1. Aceitou o programa",IF(OR(X35="Não se Aplica",X35=""),IF(OR(W35="Não se Aplica",W35=""),0,W35-V35),AVERAGE(X35-W35,W35-V35)),0),0) -> 0 | BA35: =IF(BB35="S",IF(AND(Q35="1. Aceitou o programa",AH35="Realizada"),IFERROR(IF(AG35="",0,AG35-R35),0),0),0) -> 0 | BB35: =_xlfn.XLOOKUP(U35,'Lista Suspensa'!$AA$20:$AA$23,'Lista Suspensa'!$AB$20:$AB$23,"N/A") -> S
A36: Fluxo Antigo | B36: 45292 | C36: Captação + Navegação | D36: Equipe - Dr. Michel Menezes | E36: 93359327 | F36: ELAINE ALMEIDA PARA ASSU DOS SANTOS | H36: 29388 | I36: 45 | J36: F | K36: RJ | O36: 21964815875 | P36: Equipe Emagrecimento | Q36: 1. Aceitou o programa | R36: 45820 | T36: Contato Com Sucesso | U36: Ativo | V36: 45820 | W36: Não se aplica | X36: Não se aplica | Z36: Ozempic | AA36: 133 | AB36: 1.6 | AC36: =SUM(AA36/(AB36^2)) -> 51.953125 | AD36: =IF(AC36<18.5,"ABAIXO DO PESO", (IF(AC36<=24.9,"PESO NORMAL", (IF(AC36<=29.9,"SOBREPESO", (IF(AC36<=34.9,"OBESIDADE I", (IF(AC36<=39.9,"OBESIDADE II", (IF(AC36<=999,"OBESIDADE III","VAZIO"))))))))))) -> OBESIDADE III | AE36: CMDP - Centro Médico Dom Pedro | AF36: Aguardando Agendamento | AL36: Critério de Grade Especial | AO36: =IF(R36="","",IF(R36>TODAY(),"0 meses",DATEDIF(R36,TODAY(),"m") & " meses")) -> 11 meses | AP36: Sim | AQ36: Sim | AS36: Emagrecimento | AT36: =MONTH(B36)&"/"&YEAR(B36) -> 1/2024 | AU36: =WEEKNUM(B36)-WEEKNUM(EOMONTH(B36,-1)+1)+1 -> 1 | AV36: =MONTH(R36)&"/"&YEAR(R36) -> 6/2025 | AW36: =WEEKNUM(R36)-WEEKNUM(EOMONTH(R36,-1)+1)+1 -> 2 | AX36: =IF(BB36="S",IF(Q36="1. Aceitou o programa",R36-B36,0),0) -> 528 | AY36: =IF(BB36="S",IF(AND(S36<>"",R36<>""),S36-R36,0),0) -> 0 | AZ36: =IF(BB36="S",IF(Q36="1. Aceitou o programa",IF(OR(X36="Não se Aplica",X36=""),IF(OR(W36="Não se Aplica",W36=""),0,W36-V36),AVERAGE(X36-W36,W36-V36)),0),0) -> 0 | BA36: =IF(BB36="S",IF(AND(Q36="1. Aceitou o programa",AH36="Realizada"),IFERROR(IF(AG36="",0,AG36-R36),0),0),0) -> 0 | BB36: =_xlfn.XLOOKUP(U36,'Lista Suspensa'!$AA$20:$AA$23,'Lista Suspensa'!$AB$20:$AB$23,"N/A") -> S
A37: Fluxo Antigo | B37: 45292 | C37: Captação + Navegação | D37: Equipe - Instituto Castro | E37: 87668623 | F37: ANTONIA KALIANY HOLANDA CALIL | H37: 30406 | I37: 43 | J37: F | O37: 11970365539 | P37: Equipe Emagrecimento | Q37: 1. Aceitou o programa | R37: 45825 | T37: Contato Com Sucesso | U37: Ativo | V37: 45825 | W37: Não se aplica | X37: Não se aplica | Z37: Não Utiliza | AA37: 93 | AB37: 1.56 | AC37: =SUM(AA37/(AB37^2)) -> 38.21499 | AD37: =IF(AC37<18.5,"ABAIXO DO PESO", (IF(AC37<=24.9,"PESO NORMAL", (IF(AC37<=29.9,"SOBREPESO", (IF(AC37<=34.9,"OBESIDADE I", (IF(AC37<=39.9,"OBESIDADE II", (IF(AC37<=999,"OBESIDADE III","VAZIO"))))))))))) -> OBESIDADE II | AE37: CMDP - Centro Médico Dom Pedro | AF37: Aguardando Agendamento | AL37: Pós-Bariátrico | AM37: Sim - Acompanhou Pré Operatório conosco | AN37: Sem Dados | AO37: =IF(R37="","",IF(R37>TODAY(),"0 meses",DATEDIF(R37,TODAY(),"m") & " meses")) -> 11 meses | AP37: Sim | AQ37: Sim | AS37: Emagrecimento | AT37: =MONTH(B37)&"/"&YEAR(B37) -> 1/2024 | AU37: =WEEKNUM(B37)-WEEKNUM(EOMONTH(B37,-1)+1)+1 -> 1 | AV37: =MONTH(R37)&"/"&YEAR(R37) -> 6/2025 | AW37: =WEEKNUM(R37)-WEEKNUM(EOMONTH(R37,-1)+1)+1 -> 3 | AX37: =IF(BB37="S",IF(Q37="1. Aceitou o programa",R37-B37,0),0) -> 533 | AY37: =IF(BB37="S",IF(AND(S37<>"",R37<>""),S37-R37,0),0) -> 0 | AZ37: =IF(BB37="S",IF(Q37="1. Aceitou o programa",IF(OR(X37="Não se Aplica",X37=""),IF(OR(W37="Não se Aplica",W37=""),0,W37-V37),AVERAGE(X37-W37,W37-V37)),0),0) -> 0 | BA37: =IF(BB37="S",IF(AND(Q37="1. Aceitou o programa",AH37="Realizada"),IFERROR(IF(AG37="",0,AG37-R37),0),0),0) -> 0 | BB37: =_xlfn.XLOOKUP(U37,'Lista Suspensa'!$AA$20:$AA$23,'Lista Suspensa'!$AB$20:$AB$23,"N/A") -> S
