Workbook

Sheet Consolidado
A1: Prioridade no Contato? | B1: Data Envio Paciente | C1: Motivo Envio | D1: Origem | E1: MO | F1: Nome do paciente | G1: CPF | H1: Data de Nascimento | I1: Idade | J1: Genero | K1: Estado | L1: Município | M1: Bairro | N1: Nível de Rede | O1: Telefone atualizado | P1: Profissional | Q1: Status BNF Linha | R1: Data de Inclusão | S1: Data da Alta, Inatividade ou Recusa | T1: Status Do Contato | U1: Situação Atual Do Paciente | V1: Tentativa de Contato 1 | W1: Tentativa de Contato 2 | X1: Tentativa de Contato 3 | Y1: Observações Importantes | Z1: Status Pré Consulta Enfermagem | AA1: Data 1ª Consulta de Enfermagem | AB1: Status da 1ª Consulta Enfermagem | AC1: Se reagendado, sinalizar datas | AD1: Complexidade | AE1: Resultado da Escala | AF1: Local de Acomapanhamento inicial | AG1: Local de Acomapanhamento atual | AH1: Diagnostico Confirmado? | AI1: Direcionado ao Hub? | AJ1: Flag | AK1: Encaminhado p/ Consolidado? | AL1: Linha | AM1: Mês/Ano | AN1: Semana | AO1: Mês/Ano Inclusão | AP1: Semana Inclusão | AQ1: SLA Captação | AR1: SLA Exclusão | AS1: SLA Tent. Contatos | AT1: SLA Consulta | AU1: Ativo/Inativo
A2: Sim | B2: 46030 | C2: Captação + Navegação | D2: Forms | E2: 450110320 | F2: GILVAN CARNEIRO | H2: 26819 | I2: 52 | J2: M | K2: SP | L2: SAO PAULO | M2: Av Carlos Lacerda, 3232 - Pirajussara CEP 05789001 Sao Paulo SP | N2: 100 | O2: 11958997396 | P2: Caio | Q2: 1. Aceitou o programa | R2: 46077 | T2: Contato Com Sucesso | U2: Ativo | V2: 46077 | W2: Não se aplica | X2: Não se aplica | Y2: AVC RECENTE | Z2: Agendada | AA2: 46077 | AB2: Realizada | AJ2: Sim | AK2: Sim | AL2: Pós-AVC | AM2: =MONTH(B2)&"/"&YEAR(B2) -> 1/2026 | AN2: =WEEKNUM(B2)-WEEKNUM(EOMONTH(B2,-1)+1)+1 -> 2 | AO2: =MONTH(R2)&"/"&YEAR(R2) -> 2/2026 | AP2: =WEEKNUM(R2)-WEEKNUM(EOMONTH(R2,-1)+1)+1 -> 4 | AQ2: =IF(AU2="S",IF(Q2="1. Aceitou o programa",R2-B2,0),0) -> 47 | AR2: =IF(AU2="S",IF(AND(S2<>"",R2<>""),S2-R2,0),0) -> 0 | AS2: =IF(AU2="S",IF(Q2="1. Aceitou o programa",IF(OR(X2="Não se Aplica",X2=""),IF(OR(W2="Não se Aplica",W2=""),0,W2-V2),AVERAGE(X2-W2,W2-V2)),0),0) -> 0 | AT2: =IF(AU2="S",IF(AND(Q2="1. Aceitou o programa",AB2="Realizada"),IFERROR(IF(AA2="",0,AA2-R2),0),0),0) -> 0 | AU2: =_xlfn.XLOOKUP(U2,'Lista Suspensa'!$AA$20:$AA$23,'Lista Suspensa'!$AB$20:$AB$23,"N/A") -> S
A3: Sim | B3: 46030 | C3: Captação + Navegação | D3: Forms | E3: 94578522 | F3: ANTONIO SOBRINHO DA SILVA | H3: 18008 | I3: 77 | J3: M | K3: SP | L3: SAO PAULO | M3: R Jorge Kobayashi, 72 - Colinas De Itapevi CEP 06655810 Itapevi SP | N3: 60 | O3: 11998978476 | P3: Caio | Q3: 3. Recusa por falta de interesse | S3: 46077 | T3: Contato Com Sucesso | U3: Fora da Linha | V3: 46077 | W3: 46125 | Y3: 27/12/2026 - Falo com Alessandra - Filha // Desligou de forma abrupa 12/03 | AJ3: Desflagado | AL3: Pós-AVC | AM3: =MONTH(B3)&"/"&YEAR(B3) -> 1/2026 | AN3: =WEEKNUM(B3)-WEEKNUM(EOMONTH(B3,-1)+1)+1 -> 2 | AO3: =MONTH(R3)&"/"&YEAR(R3) -> 1/1900 | AP3: =WEEKNUM(R3)-WEEKNUM(EOMONTH(R3,-1)+1)+1 -> #NUM! | AQ3: =IF(AU3="S",IF(Q3="1. Aceitou o programa",R3-B3,0),0) -> 0 | AR3: =IF(AU3="S",IF(AND(S3<>"",R3<>""),S3-R3,0),0) -> 0 | AS3: =IF(AU3="S",IF(Q3="1. Aceitou o programa",IF(OR(X3="Não se Aplica",X3=""),IF(OR(W3="Não se Aplica",W3=""),0,W3-V3),AVERAGE(X3-W3,W3-V3)),0),0) -> 0 | AT3: =IF(AU3="S",IF(AND(Q3="1. Aceitou o programa",AB3="Realizada"),IFERROR(IF(AA3="",0,AA3-R3),0),0),0) -> 0 | AU3: =_xlfn.XLOOKUP(U3,'Lista Suspensa'!$AA$20:$AA$23,'Lista Suspensa'!$AB$20:$AB$23,"N/A") -> S
A4: Sim | B4: 46030 | C4: Captação + Navegação | D4: Forms | E4: 128560118 | F4: CAZUMI JOSE HIRATA | H4: 13993 | I4: 88 | J4: M | K4: SP | L4: SAO PAULO | M4: Av Jabaquara 1195, 1195 - Mirandopolis CEP 04045970 Sao Paulo SP | N4: 400 | O4: 11995061936 | P4: Caio | Q4: 3. Recusa por falta de interesse | S4: 46077 | T4: Contato Com Sucesso | U4: Fora da Linha | V4: 46077 | W4: 46125 | X4: 46141 | Y4: FALO COM A SRA LUCI - ESPOSA -AVC RECENTE - NÃO ATENDE MAIS | Z4: Agendada | AA4: 46157 | AJ4: Desflagado | AL4: Pós-AVC | AM4: =MONTH(B4)&"/"&YEAR(B4) -> 1/2026 | AN4: =WEEKNUM(B4)-WEEKNUM(EOMONTH(B4,-1)+1)+1 -> 2 | AO4: =MONTH(R4)&"/"&YEAR(R4) -> 1/1900 | AP4: =WEEKNUM(R4)-WEEKNUM(EOMONTH(R4,-1)+1)+1 -> #NUM! | AQ4: =IF(AU4="S",IF(Q4="1. Aceitou o programa",R4-B4,0),0) -> 0 | AR4: =IF(AU4="S",IF(AND(S4<>"",R4<>""),S4-R4,0),0) -> 0 | AS4: =IF(AU4="S",IF(Q4="1. Aceitou o programa",IF(OR(X4="Não se Aplica",X4=""),IF(OR(W4="Não se Aplica",W4=""),0,W4-V4),AVERAGE(X4-W4,W4-V4)),0),0) -> 0 | AT4: =IF(AU4="S",IF(AND(Q4="1. Aceitou o programa",AB4="Realizada"),IFERROR(IF(AA4="",0,AA4-R4),0),0),0) -> 0 | AU4: =_xlfn.XLOOKUP(U4,'Lista Suspensa'!$AA$20:$AA$23,'Lista Suspensa'!$AB$20:$AB$23,"N/A") -> S
A5: Sim | B5: 46030 | C5: Captação + Navegação | D5: Forms | E5: 86832934 | F5: PAULO XAVIER DOS SANTOS | H5: 26573 | I5: 126 | J5: M | K5: SP | L5: SAO PAULO | M5: ND | N5: 60 | O5: 11962088683 | P5: Caio | Q5: 1. Aceitou o programa | R5: 46127 | T5: Contato Com Sucesso | U5: Ativo | V5: 46077 | W5: 46125 | X5: Não se aplica | Y5: NÃO DÁ SEGUIMENTO | Z5: Agendada | AA5: 46127 | AB5: Realizada | AD5: Baixa | AE5: 2 | AF5: Interno - Amil Geral | AI5: Sim | AJ5: Sim | AK5: Sim | AL5: Pós-AVC | AM5: =MONTH(B5)&"/"&YEAR(B5) -> 1/2026 | AN5: =WEEKNUM(B5)-WEEKNUM(EOMONTH(B5,-1)+1)+1 -> 2 | AO5: =MONTH(R5)&"/"&YEAR(R5) -> 4/2026 | AP5: =WEEKNUM(R5)-WEEKNUM(EOMONTH(R5,-1)+1)+1 -> 3 | AQ5: =IF(AU5="S",IF(Q5="1. Aceitou o programa",R5-B5,0),0) -> 97 | AR5: =IF(AU5="S",IF(AND(S5<>"",R5<>""),S5-R5,0),0) -> 0 | AS5: =IF(AU5="S",IF(Q5="1. Aceitou o programa",IF(OR(X5="Não se Aplica",X5=""),IF(OR(W5="Não se Aplica",W5=""),0,W5-V5),AVERAGE(X5-W5,W5-V5)),0),0) -> 48 | AT5: =IF(AU5="S",IF(AND(Q5="1. Aceitou o programa",AB5="Realizada"),IFERROR(IF(AA5="",0,AA5-R5),0),0),0) -> 0 | AU5: =_xlfn.XLOOKUP(U5,'Lista Suspensa'!$AA$20:$AA$23,'Lista Suspensa'!$AB$20:$AB$23,"N/A") -> S
A6: Sim | B6: 46030 | C6: Captação + Navegação | D6: Triggers | E6: 222857366 | F6: NEUSA DUTRA GOMES | H6: 17250 | I6: 79 | J6: F | K6: SP | L6: SAO PAULO | M6: PLANALTO PAULISTA | N6: 600 | O6: 11-996001590; 11-996513083 | P6: Caio | Q6: 1. Aceitou o programa | R6: 46078 | T6: Contato Com Sucesso | U6: Ativo | V6: 46078 | W6: Não se aplica | X6: Não se aplica | Y6: FALO COM A CINTIA | Z6: Aguardando Agendamento | AJ6: Sim | AK6: Sim | AL6: Pós-AVC | AM6: =MONTH(B6)&"/"&YEAR(B6) -> 1/2026 | AN6: =WEEKNUM(B6)-WEEKNUM(EOMONTH(B6,-1)+1)+1 -> 2 | AO6: =MONTH(R6)&"/"&YEAR(R6) -> 2/2026 | AP6: =WEEKNUM(R6)-WEEKNUM(EOMONTH(R6,-1)+1)+1 -> 4 | AQ6: =IF(AU6="S",IF(Q6="1. Aceitou o programa",R6-B6,0),0) -> 48 | AR6: =IF(AU6="S",IF(AND(S6<>"",R6<>""),S6-R6,0),0) -> 0 | AS6: =IF(AU6="S",IF(Q6="1. Aceitou o programa",IF(OR(X6="Não se Aplica",X6=""),IF(OR(W6="Não se Aplica",W6=""),0,W6-V6),AVERAGE(X6-W6,W6-V6)),0),0) -> 0 | AT6: =IF(AU6="S",IF(AND(Q6="1. Aceitou o programa",AB6="Realizada"),IFERROR(IF(AA6="",0,AA6-R6),0),0),0) -> 0 | AU6: =_xlfn.XLOOKUP(U6,'Lista Suspensa'!$AA$20:$AA$23,'Lista Suspensa'!$AB$20:$AB$23,"N/A") -> S
A7: Sim | B7: 46030 | C7: Captação + Navegação | D7: Triggers | E7: 451708490 | F7: MAURO GOUVEA | H7: 16840 | I7: 80 | J7: M | K7: SP | L7: SAO PAULO | M7: VILA GUMERCINDO | N7: 500 | O7: 11-32099067; 11-998012413 | P7: Caio | Q7: 1. Aceitou o programa | R7: 46058 | T7: Contato Com Sucesso | U7: Ativo | V7: 46058 | W7: Não se aplica | X7: Não se aplica | Y7: POSSÍVEL AVC HÁ 20 DIAS - LIGAR EM 20 DIAS | Z7: Aguardando Agendamento | AJ7: Sim | AK7: Sim | AL7: Pós-AVC | AM7: =MONTH(B7)&"/"&YEAR(B7) -> 1/2026 | AN7: =WEEKNUM(B7)-WEEKNUM(EOMONTH(B7,-1)+1)+1 -> 2 | AO7: =MONTH(R7)&"/"&YEAR(R7) -> 2/2026 | AP7: =WEEKNUM(R7)-WEEKNUM(EOMONTH(R7,-1)+1)+1 -> 1 | AQ7: =IF(AU7="S",IF(Q7="1. Aceitou o programa",R7-B7,0),0) -> 28 | AR7: =IF(AU7="S",IF(AND(S7<>"",R7<>""),S7-R7,0),0) -> 0 | AS7: =IF(AU7="S",IF(Q7="1. Aceitou o programa",IF(OR(X7="Não se Aplica",X7=""),IF(OR(W7="Não se Aplica",W7=""),0,W7-V7),AVERAGE(X7-W7,W7-V7)),0),0) -> 0 | AT7: =IF(AU7="S",IF(AND(Q7="1. Aceitou o programa",AB7="Realizada"),IFERROR(IF(AA7="",0,AA7-R7),0),0),0) -> 0 | AU7: =_xlfn.XLOOKUP(U7,'Lista Suspensa'!$AA$20:$AA$23,'Lista Suspensa'!$AB$20:$AB$23,"N/A") -> S
A8: Sim | B8: 46030 | C8: Captação + Navegação | D8: Triggers | E8: 72529316 | F8: ISA ARAUJO FIGARELLA | H8: 31040 | I8: 41 | J8: F | K8: SP | L8: SAO PAULO | M8: JARDIM INGA | N8: 50 | O8: 11-55133065; 11-54154782; 11-954154782 | P8: Caio | Q8: 1. Aceitou o programa | R8: 46066 | T8: Contato Com Sucesso | U8: Ativo | V8: 46066 | W8: Não se aplica | X8: Não se aplica | Y8: AVC HÁ 9 ANOS E AIT HÁ 3 MESES | Z8: Aguardando Agendamento | AJ8: Sim | AK8: Sim | AL8: Pós-AVC | AM8: =MONTH(B8)&"/"&YEAR(B8) -> 1/2026 | AN8: =WEEKNUM(B8)-WEEKNUM(EOMONTH(B8,-1)+1)+1 -> 2 | AO8: =MONTH(R8)&"/"&YEAR(R8) -> 2/2026 | AP8: =WEEKNUM(R8)-WEEKNUM(EOMONTH(R8,-1)+1)+1 -> 2 | AQ8: =IF(AU8="S",IF(Q8="1. Aceitou o programa",R8-B8,0),0) -> 36 | AR8: =IF(AU8="S",IF(AND(S8<>"",R8<>""),S8-R8,0),0) -> 0 | AS8: =IF(AU8="S",IF(Q8="1. Aceitou o programa",IF(OR(X8="Não se Aplica",X8=""),IF(OR(W8="Não se Aplica",W8=""),0,W8-V8),AVERAGE(X8-W8,W8-V8)),0),0) -> 0 | AT8: =IF(AU8="S",IF(AND(Q8="1. Aceitou o programa",AB8="Realizada"),IFERROR(IF(AA8="",0,AA8-R8),0),0),0) -> 0 | AU8: =_xlfn.XLOOKUP(U8,'Lista Suspensa'!$AA$20:$AA$23,'Lista Suspensa'!$AB$20:$AB$23,"N/A") -> S
A9: Sim | B9: 46030 | C9: Captação + Navegação | D9: Triggers | E9: 93636998 | F9: JULIANA AGUIAR ALVES | H9: 34980 | I9: 30 | J9: F | K9: SP | L9: SAO PAULO | M9: VILA MARARI | N9: 60 | O9: 11-969491797 | P9: Giovanna | Q9: 1. Aceitou o programa | R9: 46072 | T9: Contato Com Sucesso | U9: Ativo | V9: 46072 | W9: Não se aplica | X9: Não se aplica | Z9: Agendada | AA9: 46184 | AB9: Realizada | AC9: 46184 | AD9: Média | AH9: Confirmado | AJ9: Sim | AK9: Sim | AL9: Pós-AVC | AM9: =MONTH(B9)&"/"&YEAR(B9) -> 1/2026 | AN9: =WEEKNUM(B9)-WEEKNUM(EOMONTH(B9,-1)+1)+1 -> 2 | AO9: =MONTH(R9)&"/"&YEAR(R9) -> 2/2026 | AP9: =WEEKNUM(R9)-WEEKNUM(EOMONTH(R9,-1)+1)+1 -> 3 | AQ9: =IF(AU9="S",IF(Q9="1. Aceitou o programa",R9-B9,0),0) -> 42 | AR9: =IF(AU9="S",IF(AND(S9<>"",R9<>""),S9-R9,0),0) -> 0 | AS9: =IF(AU9="S",IF(Q9="1. Aceitou o programa",IF(OR(X9="Não se Aplica",X9=""),IF(OR(W9="Não se Aplica",W9=""),0,W9-V9),AVERAGE(X9-W9,W9-V9)),0),0) -> 0 | AT9: =IF(AU9="S",IF(AND(Q9="1. Aceitou o programa",AB9="Realizada"),IFERROR(IF(AA9="",0,AA9-R9),0),0),0) -> 112 | AU9: =_xlfn.XLOOKUP(U9,'Lista Suspensa'!$AA$20:$AA$23,'Lista Suspensa'!$AB$20:$AB$23,"N/A") -> S
A10: Sim | B10: 46030 | C10: Captação + Navegação | D10: Forms | E10: 76790019 | F10: JONAS FRANCISCO PIRES | H10: 29270 | I10: 46 | J10: M | K10: SP | L10: SAO PAULO | M10: Avenida Padre Antonio Jose Dos Santos, 296 - Cidade Monçoes CEP 04563000 Sao Paulo SP | N10: 50 | O10: 11947462849 | P10: Caio | Q10: 3. Recusa por falta de interesse | S10: 46077 | T10: Contato Com Sucesso | U10: Fora da Linha | V10: 46077 | W10: 46125 | Y10: VOZ FEMININA RESPONDIA APENAS NÃO PARA AS PERGUNTAS | AJ10: Desflagado | AL10: Pós-AVC | AM10: =MONTH(B10)&"/"&YEAR(B10) -> 1/2026 | AN10: =WEEKNUM(B10)-WEEKNUM(EOMONTH(B10,-1)+1)+1 -> 2 | AO10: =MONTH(R10)&"/"&YEAR(R10) -> 1/1900 | AP10: =WEEKNUM(R10)-WEEKNUM(EOMONTH(R10,-1)+1)+1 -> #NUM! | AQ10: =IF(AU10="S",IF(Q10="1. Aceitou o programa",R10-B10,0),0) -> 0 | AR10: =IF(AU10="S",IF(AND(S10<>"",R10<>""),S10-R10,0),0) -> 0 | AS10: =IF(AU10="S",IF(Q10="1. Aceitou o programa",IF(OR(X10="Não se Aplica",X10=""),IF(OR(W10="Não se Aplica",W10=""),0,W10-V10),AVERAGE(X10-W10,W10-V10)),0),0) -> 0 | AT10: =IF(AU10="S",IF(AND(Q10="1. Aceitou o programa",AB10="Realizada"),IFERROR(IF(AA10="",0,AA10-R10),0),0),0) -> 0 | AU10: =_xlfn.XLOOKUP(U10,'Lista Suspensa'!$AA$20:$AA$23,'Lista Suspensa'!$AB$20:$AB$23,"N/A") -> S
A11: Sim | B11: 46030 | C11: Captação + Navegação | D11: Forms | E11: 86198842 | F11: YON WOOK PARK | H11: 23977 | I11: 60 | J11: M | K11: SP | L11: SAO PAULO | M11: R Loureiro Da Cruz, 11 - Aclimaçao CEP 01529020 Sao Paulo SP | N11: 60 | O11: 11987630172 | P11: Caio | Q11: 3. Recusa por falta de interesse | S11: 46077 | T11: Contato Com Sucesso | U11: Fora da Linha | V11: 46077 | W11: 46125 | Y11: DESLIGOU DE FORMA ABRUPTA | AL11: Pós-AVC | AM11: =MONTH(B11)&"/"&YEAR(B11) -> 1/2026 | AN11: =WEEKNUM(B11)-WEEKNUM(EOMONTH(B11,-1)+1)+1 -> 2 | AO11: =MONTH(R11)&"/"&YEAR(R11) -> 1/1900 | AP11: =WEEKNUM(R11)-WEEKNUM(EOMONTH(R11,-1)+1)+1 -> #NUM! | AQ11: =IF(AU11="S",IF(Q11="1. Aceitou o programa",R11-B11,0),0) -> 0 | AR11: =IF(AU11="S",IF(AND(S11<>"",R11<>""),S11-R11,0),0) -> 0 | AS11: =IF(AU11="S",IF(Q11="1. Aceitou o programa",IF(OR(X11="Não se Aplica",X11=""),IF(OR(W11="Não se Aplica",W11=""),0,W11-V11),AVERAGE(X11-W11,W11-V11)),0),0) -> 0 | AT11: =IF(AU11="S",IF(AND(Q11="1. Aceitou o programa",AB11="Realizada"),IFERROR(IF(AA11="",0,AA11-R11),0),0),0) -> 0 | AU11: =_xlfn.XLOOKUP(U11,'Lista Suspensa'!$AA$20:$AA$23,'Lista Suspensa'!$AB$20:$AB$23,"N/A") -> S
A12: Sim | B12: 46030 | C12: Captação + Navegação | D12: Forms | E12: 79565265 | F12: MARIO CANDIDO | H12: 18094 | I12: 76 | J12: M | K12: SP | L12: SAO PAULO | M12: R Francisco Alves, 721 - Jardim Sonia Maria CEP 09380360 Maua SP | N12: 60 | O12: 11985495973 | P12: Caio | Q12: 6. Contato sem sucesso | S12: 46150 | T12: Contato Sem Sucesso | U12: Fora da Linha | V12: 46077 | W12: 46125 | X12: 46142 | Y12: CHAMADA BLOQUEADA | AL12: Pós-AVC | AM12: =MONTH(B12)&"/"&YEAR(B12) -> 1/2026 | AN12: =WEEKNUM(B12)-WEEKNUM(EOMONTH(B12,-1)+1)+1 -> 2 | AO12: =MONTH(R12)&"/"&YEAR(R12) -> 1/1900 | AP12: =WEEKNUM(R12)-WEEKNUM(EOMONTH(R12,-1)+1)+1 -> #NUM! | AQ12: =IF(AU12="S",IF(Q12="1. Aceitou o programa",R12-B12,0),0) -> 0 | AR12: =IF(AU12="S",IF(AND(S12<>"",R12<>""),S12-R12,0),0) -> 0 | AS12: =IF(AU12="S",IF(Q12="1. Aceitou o programa",IF(OR(X12="Não se Aplica",X12=""),IF(OR(W12="Não se Aplica",W12=""),0,W12-V12),AVERAGE(X12-W12,W12-V12)),0),0) -> 0 | AT12: =IF(AU12="S",IF(AND(Q12="1. Aceitou o programa",AB12="Realizada"),IFERROR(IF(AA12="",0,AA12-R12),0),0),0) -> 0 | AU12: =_xlfn.XLOOKUP(U12,'Lista Suspensa'!$AA$20:$AA$23,'Lista Suspensa'!$AB$20:$AB$23,"N/A") -> S
A13: Sim | B13: 46030 | C13: Captação + Navegação | D13: Forms | E13: 95179124 | F13: VALDECI APARECIDO BASSO | H13: 24037 | I13: 126 | J13: M | K13: SP | L13: SAO PAULO | M13: ND | N13: 110 | O13: 11959020743 | P13: Caio | Q13: 1. Aceitou o programa | R13: 46189 | S13: 46150 | T13: Contato Com Sucesso | U13: Ativo | V13: 46077 | W13: 46125 | X13: 46142 | Y13: NÃO ATENDE | Z13: Agendada | AA13: 46196 | AJ13: Sim | AL13: Pós-AVC | AM13: =MONTH(B13)&"/"&YEAR(B13) -> 1/2026 | AN13: =WEEKNUM(B13)-WEEKNUM(EOMONTH(B13,-1)+1)+1 -> 2 | AO13: =MONTH(R13)&"/"&YEAR(R13) -> 6/2026 | AP13: =WEEKNUM(R13)-WEEKNUM(EOMONTH(R13,-1)+1)+1 -> 3 | AQ13: =IF(AU13="S",IF(Q13="1. Aceitou o programa",R13-B13,0),0) -> 159 | AR13: =IF(AU13="S",IF(AND(S13<>"",R13<>""),S13-R13,0),0) -> -39 | AS13: =IF(AU13="S",IF(Q13="1. Aceitou o programa",IF(OR(X13="Não se Aplica",X13=""),IF(OR(W13="Não se Aplica",W13=""),0,W13-V13),AVERAGE(X13-W13,W13-V13)),0),0) -> 32.5 | AT13: =IF(AU13="S",IF(AND(Q13="1. Aceitou o programa",AB13="Realizada"),IFERROR(IF(AA13="",0,AA13-R13),0),0),0) -> 0 | AU13: =_xlfn.XLOOKUP(U13,'Lista Suspensa'!$AA$20:$AA$23,'Lista Suspensa'!$AB$20:$AB$23,"N/A") -> S
A14: Sim | B14: 46035 | C14: Captação + Navegação | D14: Forms | E14: 792036077 | F14: RINAUDA MARTA NOMURA | H14: 15891 | I14: 82 | J14: F | K14: SP | L14: R OSIRIS MAGALHAES DE ALMEIDA, 725, Jardim Monte Kemel | M14: R OSIRIS MAGALHAES DE ALMEIDA, 725, Jardim Monte Kemel | N14: 100 | O14: 11993929169 | P14: Caio | Q14: 1. Aceitou o programa | R14: 46077 | T14: Contato Com Sucesso | U14: Ativo | V14: 46078 | W14: Não se aplica | X14: Não se aplica | Y14: FALO COM A CINTIA | Z14: Agendada | AA14: 46170 | AB14: Realizada | AD14: Baixa | AE14: 0 | AF14: Amil - Ud Cubatão Sp - Hospital Da Luz | AG14: Amil - Ud Cubatão Sp - Hospital Da Luz | AH14: Confirmado | AJ14: Sim | AK14: Sim | AL14: Pós-AVC | AM14: =MONTH(B14)&"/"&YEAR(B14) -> 1/2026 | AN14: =WEEKNUM(B14)-WEEKNUM(EOMONTH(B14,-1)+1)+1 -> 3 | AO14: =MONTH(R14)&"/"&YEAR(R14) -> 2/2026 | AP14: =WEEKNUM(R14)-WEEKNUM(EOMONTH(R14,-1)+1)+1 -> 4 | AQ14: =IF(AU14="S",IF(Q14="1. Aceitou o programa",R14-B14,0),0) -> 42 | AR14: =IF(AU14="S",IF(AND(S14<>"",R14<>""),S14-R14,0),0) -> 0 | AS14: =IF(AU14="S",IF(Q14="1. Aceitou o programa",IF(OR(X14="Não se Aplica",X14=""),IF(OR(W14="Não se Aplica",W14=""),0,W14-V14),AVERAGE(X14-W14,W14-V14)),0),0) -> 0 | AT14: =IF(AU14="S",IF(AND(Q14="1. Aceitou o programa",AB14="Realizada"),IFERROR(IF(AA14="",0,AA14-R14),0),0),0) -> 93 | AU14: =_xlfn.XLOOKUP(U14,'Lista Suspensa'!$AA$20:$AA$23,'Lista Suspensa'!$AB$20:$AB$23,"N/A") -> S
A15: Sim | B15: 46041 | C15: Captação + Navegação | D15: Forms | E15: 93805811 | F15: ROBERTA ELOISA DE AZEVEDO | H15: 30783 | I15: 42 | J15: F | K15: SP | L15: SAO PAULO | M15: ND | N15: 380 | O15: 11974058870 | P15: Caio | Q15: 3. Recusa por falta de interesse | S15: 46078 | T15: Contato Com Sucesso | U15: Fora da Linha | V15: 46078 | W15: 46125 | Y15: OCUPADA - AG. DISPONIBILIADE - Hemorragia subaracnoidea | Z15: Aguardando Agendamento | AL15: Pós-AVC | AM15: =MONTH(B15)&"/"&YEAR(B15) -> 1/2026 | AN15: =WEEKNUM(B15)-WEEKNUM(EOMONTH(B15,-1)+1)+1 -> 4 | AO15: =MONTH(R15)&"/"&YEAR(R15) -> 1/1900 | AP15: =WEEKNUM(R15)-WEEKNUM(EOMONTH(R15,-1)+1)+1 -> #NUM! | AQ15: =IF(AU15="S",IF(Q15="1. Aceitou o programa",R15-B15,0),0) -> 0 | AR15: =IF(AU15="S",IF(AND(S15<>"",R15<>""),S15-R15,0),0) -> 0 | AS15: =IF(AU15="S",IF(Q15="1. Aceitou o programa",IF(OR(X15="Não se Aplica",X15=""),IF(OR(W15="Não se Aplica",W15=""),0,W15-V15),AVERAGE(X15-W15,W15-V15)),0),0) -> 0 | AT15: =IF(AU15="S",IF(AND(Q15="1. Aceitou o programa",AB15="Realizada"),IFERROR(IF(AA15="",0,AA15-R15),0),0),0) -> 0 | AU15: =_xlfn.XLOOKUP(U15,'Lista Suspensa'!$AA$20:$AA$23,'Lista Suspensa'!$AB$20:$AB$23,"N/A") -> S
A16: Sim | B16: 46041 | C16: Captação + Navegação | D16: Forms | E16: 789137178 | F16: PEDRINA DEDES FERREIRA | H16: 12964 | I16: 90 | J16: F | K16: SP | L16: ANTONIO ANGELO CUZZIOL, 41, TABOÃO, SÃO BERNARDO DO CAMPO | M16: ANTONIO ANGELO CUZZIOL, 41, TABOÃO, SÃO BERNARDO DO CAMPO | N16: 100 | O16: 11968981957 | P16: Caio | Q16: 4. Inelegível fora do escopo | S16: 46078 | T16: Contato Com Sucesso | U16: Fora da Linha | V16: 46078 | Y16: JÁ DE ALTA DA FISIO | AL16: Pós-AVC | AM16: =MONTH(B16)&"/"&YEAR(B16) -> 1/2026 | AN16: =WEEKNUM(B16)-WEEKNUM(EOMONTH(B16,-1)+1)+1 -> 4 | AO16: =MONTH(R16)&"/"&YEAR(R16) -> 1/1900 | AP16: =WEEKNUM(R16)-WEEKNUM(EOMONTH(R16,-1)+1)+1 -> #NUM! | AQ16: =IF(AU16="S",IF(Q16="1. Aceitou o programa",R16-B16,0),0) -> 0 | AR16: =IF(AU16="S",IF(AND(S16<>"",R16<>""),S16-R16,0),0) -> 0 | AS16: =IF(AU16="S",IF(Q16="1. Aceitou o programa",IF(OR(X16="Não se Aplica",X16=""),IF(OR(W16="Não se Aplica",W16=""),0,W16-V16),AVERAGE(X16-W16,W16-V16)),0),0) -> 0 | AT16: =IF(AU16="S",IF(AND(Q16="1. Aceitou o programa",AB16="Realizada"),IFERROR(IF(AA16="",0,AA16-R16),0),0),0) -> 0 | AU16: =_xlfn.XLOOKUP(U16,'Lista Suspensa'!$AA$20:$AA$23,'Lista Suspensa'!$AB$20:$AB$23,"N/A") -> S
A17: Não | B17: 46042 | C17: Navegação | D17: Captado pela Amil/Call Center | E17: 451948360 | F17: RITA DE CASSIA BANDEIRA REIMBERG | H17: 25805 | I17: 55 | J17: F | K17: SP | L17: SAO PAULO | M17: ND | O17: 11988437339 | P17: Caio | Q17: 1. Aceitou o programa | R17: 46125 | T17: Contato Com Sucesso | U17: Ativo | V17: 46093 | W17: 46125 | X17: Não se aplica | Y17: TU DE COLUNA - CONFIRMADO AVC // 2021 E 2023 (TROMBOFILIAS) | Z17: Agendada | AA17: 46126 | AB17: Realizada | AD17: Média | AE17: 4 | AF17: Interno - Amil Geral | AJ17: Sim | AK17: Sim | AL17: Pós-AVC | AM17: =MONTH(B17)&"/"&YEAR(B17) -> 1/2026 | AN17: =WEEKNUM(B17)-WEEKNUM(EOMONTH(B17,-1)+1)+1 -> 4 | AO17: =MONTH(R17)&"/"&YEAR(R17) -> 4/2026 | AP17: =WEEKNUM(R17)-WEEKNUM(EOMONTH(R17,-1)+1)+1 -> 3 | AQ17: =IF(AU17="S",IF(Q17="1. Aceitou o programa",R17-B17,0),0) -> 83 | AR17: =IF(AU17="S",IF(AND(S17<>"",R17<>""),S17-R17,0),0) -> 0 | AS17: =IF(AU17="S",IF(Q17="1. Aceitou o programa",IF(OR(X17="Não se Aplica",X17=""),IF(OR(W17="Não se Aplica",W17=""),0,W17-V17),AVERAGE(X17-W17,W17-V17)),0),0) -> 32 | AT17: =IF(AU17="S",IF(AND(Q17="1. Aceitou o programa",AB17="Realizada"),IFERROR(IF(AA17="",0,AA17-R17),0),0),0) -> 1 | AU17: =_xlfn.XLOOKUP(U17,'Lista Suspensa'!$AA$20:$AA$23,'Lista Suspensa'!$AB$20:$AB$23,"N/A") -> S
A18: Sim | B18: 46043 | C18: Captação + Navegação | D18: Forms | E18: 450026779 | F18: ANTONIO JOSE MILANI | H18: 14411 | I18: 86 | J18: M | K18: SP | L18: SAO PAULO | M18: ND | N18: 100 | O18: 11976243144 | P18: Caio | Q18: 1. Aceitou o programa | R18: 46125 | T18: Contato Com Sucesso | U18: Ativo | V18: 46079 | W18: 46125 | X18: Não se aplica | Y18: NÃO ATENDE | Z18: Agendada | AA18: 46126 | AJ18: Sim | AK18: Sim | AL18: Pós-AVC | AM18: =MONTH(B18)&"/"&YEAR(B18) -> 1/2026 | AN18: =WEEKNUM(B18)-WEEKNUM(EOMONTH(B18,-1)+1)+1 -> 4 | AO18: =MONTH(R18)&"/"&YEAR(R18) -> 4/2026 | AP18: =WEEKNUM(R18)-WEEKNUM(EOMONTH(R18,-1)+1)+1 -> 3 | AQ18: =IF(AU18="S",IF(Q18="1. Aceitou o programa",R18-B18,0),0) -> 82 | AR18: =IF(AU18="S",IF(AND(S18<>"",R18<>""),S18-R18,0),0) -> 0 | AS18: =IF(AU18="S",IF(Q18="1. Aceitou o programa",IF(OR(X18="Não se Aplica",X18=""),IF(OR(W18="Não se Aplica",W18=""),0,W18-V18),AVERAGE(X18-W18,W18-V18)),0),0) -> 46 | AT18: =IF(AU18="S",IF(AND(Q18="1. Aceitou o programa",AB18="Realizada"),IFERROR(IF(AA18="",0,AA18-R18),0),0),0) -> 0 | AU18: =_xlfn.XLOOKUP(U18,'Lista Suspensa'!$AA$20:$AA$23,'Lista Suspensa'!$AB$20:$AB$23,"N/A") -> S
A19: Sim | B19: 46043 | C19: Captação + Navegação | D19: Forms | E19: 805067043 | F19: ANTONIO ANGELO BROGGIO | H19: 16285 | I19: 81 | J19: M | K19: SP | L19: SAO PAULO | M19: ND | N19: 100 | O19: 11981446100 | P19: Caio | Q19: 4. Inelegível fora do escopo | S19: 46078 | T19: Contato Com Sucesso | U19: Fora da Linha | V19: 46078 | Y19: INSTITUCIONALZIADO | AL19: Pós-AVC | AM19: =MONTH(B19)&"/"&YEAR(B19) -> 1/2026 | AN19: =WEEKNUM(B19)-WEEKNUM(EOMONTH(B19,-1)+1)+1 -> 4 | AO19: =MONTH(R19)&"/"&YEAR(R19) -> 1/1900 | AP19: =WEEKNUM(R19)-WEEKNUM(EOMONTH(R19,-1)+1)+1 -> #NUM! | AQ19: =IF(AU19="S",IF(Q19="1. Aceitou o programa",R19-B19,0),0) -> 0 | AR19: =IF(AU19="S",IF(AND(S19<>"",R19<>""),S19-R19,0),0) -> 0 | AS19: =IF(AU19="S",IF(Q19="1. Aceitou o programa",IF(OR(X19="Não se Aplica",X19=""),IF(OR(W19="Não se Aplica",W19=""),0,W19-V19),AVERAGE(X19-W19,W19-V19)),0),0) -> 0 | AT19: =IF(AU19="S",IF(AND(Q19="1. Aceitou o programa",AB19="Realizada"),IFERROR(IF(AA19="",0,AA19-R19),0),0),0) -> 0 | AU19: =_xlfn.XLOOKUP(U19,'Lista Suspensa'!$AA$20:$AA$23,'Lista Suspensa'!$AB$20:$AB$23,"N/A") -> S
A20: Sim | B20: 46044 | C20: Captação + Navegação | D20: Forms | E20: 457869844 | F20: LUIZ LEOMAR DE SOUZA | H20: 16155 | I20: 82 | J20: M | K20: SP | L20: SAO PAULO | M20: ND | N20: 100 | O20: 11982331392 | P20: Caio | Q20: 4. Inelegível fora do escopo | S20: 46079 | T20: Contato Com Sucesso | U20: Fora da Linha | V20: 46079 | Y20: NEGA AVC | AL20: Pós-AVC | AM20: =MONTH(B20)&"/"&YEAR(B20) -> 1/2026 | AN20: =WEEKNUM(B20)-WEEKNUM(EOMONTH(B20,-1)+1)+1 -> 4 | AO20: =MONTH(R20)&"/"&YEAR(R20) -> 1/1900 | AP20: =WEEKNUM(R20)-WEEKNUM(EOMONTH(R20,-1)+1)+1 -> #NUM! | AQ20: =IF(AU20="S",IF(Q20="1. Aceitou o programa",R20-B20,0),0) -> 0 | AR20: =IF(AU20="S",IF(AND(S20<>"",R20<>""),S20-R20,0),0) -> 0 | AS20: =IF(AU20="S",IF(Q20="1. Aceitou o programa",IF(OR(X20="Não se Aplica",X20=""),IF(OR(W20="Não se Aplica",W20=""),0,W20-V20),AVERAGE(X20-W20,W20-V20)),0),0) -> 0 | AT20: =IF(AU20="S",IF(AND(Q20="1. Aceitou o programa",AB20="Realizada"),IFERROR(IF(AA20="",0,AA20-R20),0),0),0) -> 0 | AU20: =_xlfn.XLOOKUP(U20,'Lista Suspensa'!$AA$20:$AA$23,'Lista Suspensa'!$AB$20:$AB$23,"N/A") -> S
A21: Não | B21: 46051 | C21: Navegação | D21: Captado pela Amil/Call Center | E21: 450914879 | F21: EDILIANA DE ANDRADE SOUZA | H21: 30364 | I21: 43 | J21: F | K21: SP | L21: SAO PAULO | M21: ND | O21: 11984780557 | P21: Caio | Q21: 1. Aceitou o programa | R21: 46125 | T21: Contato Com Sucesso | U21: Ativo | V21: 46051 | W21: 46125 | X21: Não se aplica | Y21: há dois anos, segue com hemiparesia. | Z21: Agendada | AA21: 46126 | AB21: Realizada | AJ21: Sim | AK21: Sim | AL21: Pós-AVC | AM21: =MONTH(B21)&"/"&YEAR(B21) -> 1/2026 | AN21: =WEEKNUM(B21)-WEEKNUM(EOMONTH(B21,-1)+1)+1 -> 5 | AO21: =MONTH(R21)&"/"&YEAR(R21) -> 4/2026 | AP21: =WEEKNUM(R21)-WEEKNUM(EOMONTH(R21,-1)+1)+1 -> 3 | AQ21: =IF(AU21="S",IF(Q21="1. Aceitou o programa",R21-B21,0),0) -> 74 | AR21: =IF(AU21="S",IF(AND(S21<>"",R21<>""),S21-R21,0),0) -> 0 | AS21: =IF(AU21="S",IF(Q21="1. Aceitou o programa",IF(OR(X21="Não se Aplica",X21=""),IF(OR(W21="Não se Aplica",W21=""),0,W21-V21),AVERAGE(X21-W21,W21-V21)),0),0) -> 74 | AT21: =IF(AU21="S",IF(AND(Q21="1. Aceitou o programa",AB21="Realizada"),IFERROR(IF(AA21="",0,AA21-R21),0),0),0) -> 1 | AU21: =_xlfn.XLOOKUP(U21,'Lista Suspensa'!$AA$20:$AA$23,'Lista Suspensa'!$AB$20:$AB$23,"N/A") -> S
A22: Sim | B22: 46055 | C22: Captação + Navegação | D22: Forms | E22: 79541447 | F22: MAURO COSTA BITENCOURT | H22: 25065 | I22: 57 | J22: M | K22: SP | L22: PARQUE SANTO ANTONIO | M22: ND | N22: 40 | O22: 11961520901 | P22: Caio | Q22: 1. Aceitou o programa | R22: 46077 | T22: Contato Com Sucesso | U22: Ativo | V22: 46079 | W22: Não se aplica | X22: Não se aplica | Y22: AVC - 01/02/2026 - APARENTEMENTE DISLALIA | Z22: Aguardando Agendamento | AJ22: Sim | AK22: Sim | AL22: Pós-AVC | AM22: =MONTH(B22)&"/"&YEAR(B22) -> 2/2026 | AN22: =WEEKNUM(B22)-WEEKNUM(EOMONTH(B22,-1)+1)+1 -> 1 | AO22: =MONTH(R22)&"/"&YEAR(R22) -> 2/2026 | AP22: =WEEKNUM(R22)-WEEKNUM(EOMONTH(R22,-1)+1)+1 -> 4 | AQ22: =IF(AU22="S",IF(Q22="1. Aceitou o programa",R22-B22,0),0) -> 22 | AR22: =IF(AU22="S",IF(AND(S22<>"",R22<>""),S22-R22,0),0) -> 0 | AS22: =IF(AU22="S",IF(Q22="1. Aceitou o programa",IF(OR(X22="Não se Aplica",X22=""),IF(OR(W22="Não se Aplica",W22=""),0,W22-V22),AVERAGE(X22-W22,W22-V22)),0),0) -> 0 | AT22: =IF(AU22="S",IF(AND(Q22="1. Aceitou o programa",AB22="Realizada"),IFERROR(IF(AA22="",0,AA22-R22),0),0),0) -> 0 | AU22: =_xlfn.XLOOKUP(U22,'Lista Suspensa'!$AA$20:$AA$23,'Lista Suspensa'!$AB$20:$AB$23,"N/A") -> S
A23: Não | B23: 46058 | C23: Captação + Navegação | D23: Migrou do Fluxo de Negativa | E23: 87326861 | F23: Maria Aparecida Castelli | H23: 17841 | J23: F | K23: SP | L23: SAO PAULO | O23: (11) 9958-49371 | P23: Hellen | Q23: 1. Aceitou o programa | R23: 46058 | T23: Contato Com Sucesso | U23: Ativo | V23: 46058 | W23: Não se aplica | X23: Não se aplica | Z23: Agendada | AA23: 46126 | AB23: Realizada | AD23: Baixa | AE23: 1 | AF23: Interno - Amil Geral | AI23: Sim | AJ23: Sim | AK23: Sim | AL23: Pós-AVC | AM23: =MONTH(B23)&"/"&YEAR(B23) -> 2/2026 | AN23: =WEEKNUM(B23)-WEEKNUM(EOMONTH(B23,-1)+1)+1 -> 1 | AO23: =MONTH(R23)&"/"&YEAR(R23) -> 2/2026 | AP23: =WEEKNUM(R23)-WEEKNUM(EOMONTH(R23,-1)+1)+1 -> 1 | AQ23: =IF(AU23="S",IF(Q23="1. Aceitou o programa",R23-B23,0),0) -> 0 | AR23: =IF(AU23="S",IF(AND(S23<>"",R23<>""),S23-R23,0),0) -> 0 | AS23: =IF(AU23="S",IF(Q23="1. Aceitou o programa",IF(OR(X23="Não se Aplica",X23=""),IF(OR(W23="Não se Aplica",W23=""),0,W23-V23),AVERAGE(X23-W23,W23-V23)),0),0) -> 0 | AT23: =IF(AU23="S",IF(AND(Q23="1. Aceitou o programa",AB23="Realizada"),IFERROR(IF(AA23="",0,AA23-R23),0),0),0) -> 68 | AU23: =_xlfn.XLOOKUP(U23,'Lista Suspensa'!$AA$20:$AA$23,'Lista Suspensa'!$AB$20:$AB$23,"N/A") -> S
A24: Não | B24: 46058 | C24: Captação + Navegação | D24: Migrou do Fluxo de Negativa | E24: 800025164 | F24: Marlene Aparecida Cambili Almazan | H24: 16409 | J24: F | K24: SP | L24: SAO PAULO | O24: (11) 9994-38848 (11) 9640-58575 | P24: Hellen | Q24: 1. Aceitou o programa | R24: 46058 | T24: Contato Com Sucesso | U24: Ativo | V24: 46058 | W24: Não se aplica | X24: Não se aplica | Z24: Agendada | AJ24: Sim | AK24: Sim | AL24: Pós-AVC | AM24: =MONTH(B24)&"/"&YEAR(B24) -> 2/2026 | AN24: =WEEKNUM(B24)-WEEKNUM(EOMONTH(B24,-1)+1)+1 -> 1 | AO24: =MONTH(R24)&"/"&YEAR(R24) -> 2/2026 | AP24: =WEEKNUM(R24)-WEEKNUM(EOMONTH(R24,-1)+1)+1 -> 1 | AQ24: =IF(AU24="S",IF(Q24="1. Aceitou o programa",R24-B24,0),0) -> 0 | AR24: =IF(AU24="S",IF(AND(S24<>"",R24<>""),S24-R24,0),0) -> 0 | AS24: =IF(AU24="S",IF(Q24="1. Aceitou o programa",IF(OR(X24="Não se Aplica",X24=""),IF(OR(W24="Não se Aplica",W24=""),0,W24-V24),AVERAGE(X24-W24,W24-V24)),0),0) -> 0 | AT24: =IF(AU24="S",IF(AND(Q24="1. Aceitou o programa",AB24="Realizada"),IFERROR(IF(AA24="",0,AA24-R24),0),0),0) -> 0 | AU24: =_xlfn.XLOOKUP(U24,'Lista Suspensa'!$AA$20:$AA$23,'Lista Suspensa'!$AB$20:$AB$23,"N/A") -> S
A25: Sim | B25: 46058 | C25: Captação + Navegação | D25: Forms | E25: 772399328 | F25: JOSEFINA PEREIRA DE ANDRADE | H25: 17299 | I25: 79 | J25: F | K25: SP | L25: TABOAO | M25: ND | N25: 100 | O25: 11971270511 | P25: Caio | Q25: 6. Contato sem sucesso | S25: 46150 | T25: Contato Sem Sucesso | U25: Fora da Linha | V25: 46079 | W25: 46125 | X25: 46142 | Y25: NÃO ATENDE | AL25: Pós-AVC | AM25: =MONTH(B25)&"/"&YEAR(B25) -> 2/2026 | AN25: =WEEKNUM(B25)-WEEKNUM(EOMONTH(B25,-1)+1)+1 -> 1 | AO25: =MONTH(R25)&"/"&YEAR(R25) -> 1/1900 | AP25: =WEEKNUM(R25)-WEEKNUM(EOMONTH(R25,-1)+1)+1 -> #NUM! | AQ25: =IF(AU25="S",IF(Q25="1. Aceitou o programa",R25-B25,0),0) -> 0 | AR25: =IF(AU25="S",IF(AND(S25<>"",R25<>""),S25-R25,0),0) -> 0 | AS25: =IF(AU25="S",IF(Q25="1. Aceitou o programa",IF(OR(X25="Não se Aplica",X25=""),IF(OR(W25="Não se Aplica",W25=""),0,W25-V25),AVERAGE(X25-W25,W25-V25)),0),0) -> 0 | AT25: =IF(AU25="S",IF(AND(Q25="1. Aceitou o programa",AB25="Realizada"),IFERROR(IF(AA25="",0,AA25-R25),0),0),0) -> 0 | AU25: =_xlfn.XLOOKUP(U25,'Lista Suspensa'!$AA$20:$AA$23,'Lista Suspensa'!$AB$20:$AB$23,"N/A") -> S
A26: Sim | B26: 46065 | C26: Captação + Navegação | D26: Forms | E26: 452002621 | F26: EDILEUSA CELESTINO DE ALMEIDA | H26: 26526 | I26: 53 | J26: F | K26: SP | L26: VILA MARARI | M26: ND | N26: 100 | O26: 11982627039 | P26: Caio | Q26: 1. Aceitou o programa | R26: 46077 | T26: Contato Com Sucesso | U26: Ativo | V26: 46079 | W26: Não se aplica | X26: Não se aplica | Y26: FEV/2026 - AVC // DISLALIA // escala ok | Z26: Agendada | AA26: 46082 | AB26: Realizada | AJ26: Sim | AK26: Sim | AL26: Pós-AVC | AM26: =MONTH(B26)&"/"&YEAR(B26) -> 2/2026 | AN26: =WEEKNUM(B26)-WEEKNUM(EOMONTH(B26,-1)+1)+1 -> 2 | AO26: =MONTH(R26)&"/"&YEAR(R26) -> 2/2026 | AP26: =WEEKNUM(R26)-WEEKNUM(EOMONTH(R26,-1)+1)+1 -> 4 | AQ26: =IF(AU26="S",IF(Q26="1. Aceitou o programa",R26-B26,0),0) -> 12 | AR26: =IF(AU26="S",IF(AND(S26<>"",R26<>""),S26-R26,0),0) -> 0 | AS26: =IF(AU26="S",IF(Q26="1. Aceitou o programa",IF(OR(X26="Não se Aplica",X26=""),IF(OR(W26="Não se Aplica",W26=""),0,W26-V26),AVERAGE(X26-W26,W26-V26)),0),0) -> 0 | AT26: =IF(AU26="S",IF(AND(Q26="1. Aceitou o programa",AB26="Realizada"),IFERROR(IF(AA26="",0,AA26-R26),0),0),0) -> 5 | AU26: =_xlfn.XLOOKUP(U26,'Lista Suspensa'!$AA$20:$AA$23,'Lista Suspensa'!$AB$20:$AB$23,"N/A") -> S
A27: Sim | B27: 46065 | C27: Captação + Navegação | D27: Forms | E27: 810659794 | F27: LEIA OLIVEIRA | H27: 22028 | I27: 126 | J27: F | K27: SP | L27: VILA SOUZA | M27: ND | N27: 100 | O27: 11970777649 | P27: Caio | Q27: 4. Inelegível fora do escopo | S27: 46079 | T27: Contato Com Sucesso | U27: Fora da Linha | V27: 46079 | Y27: FILHA Caroline - AVC 02/26 - Dislalia e sequela motora - INSTITUCIONALIZADA | Z27: Agendada | AA27: 46054 | AB27: Realizada | AJ27: Desflagado | AL27: Pós-AVC | AM27: =MONTH(B27)&"/"&YEAR(B27) -> 2/2026 | AN27: =WEEKNUM(B27)-WEEKNUM(EOMONTH(B27,-1)+1)+1 -> 2 | AO27: =MONTH(R27)&"/"&YEAR(R27) -> 1/1900 | AP27: =WEEKNUM(R27)-WEEKNUM(EOMONTH(R27,-1)+1)+1 -> #NUM! | AQ27: =IF(AU27="S",IF(Q27="1. Aceitou o programa",R27-B27,0),0) -> 0 | AR27: =IF(AU27="S",IF(AND(S27<>"",R27<>""),S27-R27,0),0) -> 0 | AS27: =IF(AU27="S",IF(Q27="1. Aceitou o programa",IF(OR(X27="Não se Aplica",X27=""),IF(OR(W27="Não se Aplica",W27=""),0,W27-V27),AVERAGE(X27-W27,W27-V27)),0),0) -> 0 | AT27: =IF(AU27="S",IF(AND(Q27="1. Aceitou o programa",AB27="Realizada"),IFERROR(IF(AA27="",0,AA27-R27),0),0),0) -> 0 | AU27: =_xlfn.XLOOKUP(U27,'Lista Suspensa'!$AA$20:$AA$23,'Lista Suspensa'!$AB$20:$AB$23,"N/A") -> S
A28: Sim | B28: 46072 | C28: Captação + Navegação | D28: Forms | E28: 94429498 | F28: ROSANI BRIGIDA DE LANNA BATISTA | H28: 31933 | I28: 38 | J28: F | K28: SP | L28: CENTRO | M28: ND | N28: 110 | O28: 11963422365 | P28: Caio | Q28: 1. Aceitou o programa | R28: 46127 | T28: Contato Com Sucesso | U28: Ativo | V28: 46079 | W28: 46125 | X28: Não se aplica | Y28: FALO COM ESPOSO - Não quer e não me deixou explicar | Z28: Agendada | AA28: 46127 | AB28: Realizada | AJ28: Sim | AK28: Sim | AL28: Pós-AVC | AM28: =MONTH(B28)&"/"&YEAR(B28) -> 2/2026 | AN28: =WEEKNUM(B28)-WEEKNUM(EOMONTH(B28,-1)+1)+1 -> 3 | AO28: =MONTH(R28)&"/"&YEAR(R28) -> 4/2026 | AP28: =WEEKNUM(R28)-WEEKNUM(EOMONTH(R28,-1)+1)+1 -> 3 | AQ28: =IF(AU28="S",IF(Q28="1. Aceitou o programa",R28-B28,0),0) -> 55 | AR28: =IF(AU28="S",IF(AND(S28<>"",R28<>""),S28-R28,0),0) -> 0 | AS28: =IF(AU28="S",IF(Q28="1. Aceitou o programa",IF(OR(X28="Não se Aplica",X28=""),IF(OR(W28="Não se Aplica",W28=""),0,W28-V28),AVERAGE(X28-W28,W28-V28)),0),0) -> 46 | AT28: =IF(AU28="S",IF(AND(Q28="1. Aceitou o programa",AB28="Realizada"),IFERROR(IF(AA28="",0,AA28-R28),0),0),0) -> 0 | AU28: =_xlfn.XLOOKUP(U28,'Lista Suspensa'!$AA$20:$AA$23,'Lista Suspensa'!$AB$20:$AB$23,"N/A") -> S
A29: Sim | B29: 46078 | C29: Captação + Navegação | D29: Forms | E29: 94188885 | F29: MARCOS BELTRAN | H29: 21627 | I29: 67 | J29: M | K29: SP | L29: PONTE GRANDE | M29: ND | N29: 110 | O29: 11996669409 | P29: Caio | Q29: 3. Recusa por falta de interesse | S29: 46092 | T29: Contato Com Sucesso | U29: Fora da Linha | V29: 46092 | W29: 46125 | Y29: RELATOU ESTAR BEM VIA MENSAGEM, NÃO DEU CONTINUIDADE | Z29: Agendada | AA29: 46157 | AB29: Não realizada - Falta | AJ29: Desflagado | AL29: Pós-AVC | AM29: =MONTH(B29)&"/"&YEAR(B29) -> 2/2026 | AN29: =WEEKNUM(B29)-WEEKNUM(EOMONTH(B29,-1)+1)+1 -> 4 | AO29: =MONTH(R29)&"/"&YEAR(R29) -> 1/1900 | AP29: =WEEKNUM(R29)-WEEKNUM(EOMONTH(R29,-1)+1)+1 -> #NUM! | AQ29: =IF(AU29="S",IF(Q29="1. Aceitou o programa",R29-B29,0),0) -> 0 | AR29: =IF(AU29="S",IF(AND(S29<>"",R29<>""),S29-R29,0),0) -> 0 | AS29: =IF(AU29="S",IF(Q29="1. Aceitou o programa",IF(OR(X29="Não se Aplica",X29=""),IF(OR(W29="Não se Aplica",W29=""),0,W29-V29),AVERAGE(X29-W29,W29-V29)),0),0) -> 0 | AT29: =IF(AU29="S",IF(AND(Q29="1. Aceitou o programa",AB29="Realizada"),IFERROR(IF(AA29="",0,AA29-R29),0),0),0) -> 0 | AU29: =_xlfn.XLOOKUP(U29,'Lista Suspensa'!$AA$20:$AA$23,'Lista Suspensa'!$AB$20:$AB$23,"N/A") -> S
A30: Sim | B30: 46079 | C30: Navegação | D30: Captado pela Amil/Call Center | E30: 301361053 | F30: JOSE ANTONIO MARTINEZ Y PEREZ | H30: 21713 | I30: 66 | J30: M | K30: SP | L30: SAO PAULO | M30: ND | O30: 11967669822 | P30: Caio | Q30: 4. Inelegível fora do escopo | S30: 46142 | T30: Contato Com Sucesso | U30: Fora da Linha | V30: 46092 | W30: 46142 | X30: Não se aplica | Y30: EM PLATO | AJ30: Desflagado | AK30: Sim | AL30: Pós-AVC | AM30: =MONTH(B30)&"/"&YEAR(B30) -> 2/2026 | AN30: =WEEKNUM(B30)-WEEKNUM(EOMONTH(B30,-1)+1)+1 -> 4 | AO30: =MONTH(R30)&"/"&YEAR(R30) -> 1/1900 | AP30: =WEEKNUM(R30)-WEEKNUM(EOMONTH(R30,-1)+1)+1 -> #NUM! | AQ30: =IF(AU30="S",IF(Q30="1. Aceitou o programa",R30-B30,0),0) -> 0 | AR30: =IF(AU30="S",IF(AND(S30<>"",R30<>""),S30-R30,0),0) -> 0 | AS30: =IF(AU30="S",IF(Q30="1. Aceitou o programa",IF(OR(X30="Não se Aplica",X30=""),IF(OR(W30="Não se Aplica",W30=""),0,W30-V30),AVERAGE(X30-W30,W30-V30)),0),0) -> 0 | AT30: =IF(AU30="S",IF(AND(Q30="1. Aceitou o programa",AB30="Realizada"),IFERROR(IF(AA30="",0,AA30-R30),0),0),0) -> 0 | AU30: =_xlfn.XLOOKUP(U30,'Lista Suspensa'!$AA$20:$AA$23,'Lista Suspensa'!$AB$20:$AB$23,"N/A") -> S
A31: Sim | B31: 46091 | C31: Captação + Navegação | D31: Forms | E31: 451632320 | F31: IDALICIO FERREIRA OLIVEIRA | H31: 16055 | I31: 82 | J31: M | K31: SP | L31: PARQUE RESIDENCIAL COCAIA | M31: ND | N31: 100 | O31: 11995084735 | P31: Caio | Q31: 1. Aceitou o programa | R31: 46092 | T31: Contato Com Sucesso | U31: Ativo | V31: 46092 | W31: Não se aplica | X31: Não se aplica | Y31: LURDES (FILHA) - AVC HÁ 8 DIAS - DISLALIA LEVE | Z31: Aguardando Agendamento | AJ31: Sim | AK31: Sim | AL31: Pós-AVC | AM31: =MONTH(B31)&"/"&YEAR(B31) -> 3/2026 | AN31: =WEEKNUM(B31)-WEEKNUM(EOMONTH(B31,-1)+1)+1 -> 2 | AO31: =MONTH(R31)&"/"&YEAR(R31) -> 3/2026 | AP31: =WEEKNUM(R31)-WEEKNUM(EOMONTH(R31,-1)+1)+1 -> 2 | AQ31: =IF(AU31="S",IF(Q31="1. Aceitou o programa",R31-B31,0),0) -> 1 | AR31: =IF(AU31="S",IF(AND(S31<>"",R31<>""),S31-R31,0),0) -> 0 | AS31: =IF(AU31="S",IF(Q31="1. Aceitou o programa",IF(OR(X31="Não se Aplica",X31=""),IF(OR(W31="Não se Aplica",W31=""),0,W31-V31),AVERAGE(X31-W31,W31-V31)),0),0) -> 0 | AT31: =IF(AU31="S",IF(AND(Q31="1. Aceitou o programa",AB31="Realizada"),IFERROR(IF(AA31="",0,AA31-R31),0),0),0) -> 0 | AU31: =_xlfn.XLOOKUP(U31,'Lista Suspensa'!$AA$20:$AA$23,'Lista Suspensa'!$AB$20:$AB$23,"N/A") -> S
A32: Sim | B32: 46091 | C32: Captação + Navegação | D32: Forms | E32: 79230426 | F32: NELSON FANTIM | H32: 15494 | I32: 83 | J32: M | K32: SP | L32: CIDADE PATRIARCA | M32: ND | N32: 50 | O32: 11975451357 | P32: Caio | Q32: 1. Aceitou o programa | R32: 46092 | T32: Contato Com Sucesso | U32: Ativo | V32: 46092 | W32: Não se aplica | X32: Não se aplica | Y32: FALO COM IVONE - ESPOSA / HEMIPLEGIA BILATERAL - 01/03 e 02/03 | Z32: Aguardando Agendamento | AH32: Confirmado | AJ32: Sim | AK32: Sim | AL32: Pós-AVC | AM32: =MONTH(B32)&"/"&YEAR(B32) -> 3/2026 | AN32: =WEEKNUM(B32)-WEEKNUM(EOMONTH(B32,-1)+1)+1 -> 2 | AO32: =MONTH(R32)&"/"&YEAR(R32) -> 3/2026 | AP32: =WEEKNUM(R32)-WEEKNUM(EOMONTH(R32,-1)+1)+1 -> 2 | AQ32: =IF(AU32="S",IF(Q32="1. Aceitou o programa",R32-B32,0),0) -> 1 | AR32: =IF(AU32="S",IF(AND(S32<>"",R32<>""),S32-R32,0),0) -> 0 | AS32: =IF(AU32="S",IF(Q32="1. Aceitou o programa",IF(OR(X32="Não se Aplica",X32=""),IF(OR(W32="Não se Aplica",W32=""),0,W32-V32),AVERAGE(X32-W32,W32-V32)),0),0) -> 0 | AT32: =IF(AU32="S",IF(AND(Q32="1. Aceitou o programa",AB32="Realizada"),IFERROR(IF(AA32="",0,AA32-R32),0),0),0) -> 0 | AU32: =_xlfn.XLOOKUP(U32,'Lista Suspensa'!$AA$20:$AA$23,'Lista Suspensa'!$AB$20:$AB$23,"N/A") -> S
A33: Sim | B33: 46093 | C33: Navegação | D33: Captado pela Amil/Call Center | E33: 87532912 | F33: JOAO LUIZ DE OLIVEIRA JUNIOR | H33: 29307 | I33: 46 | J33: M | K33: SP | L33: CONJUNTO RESIDENCIAL JOSE BONIFACIO | M33: ND | N33: 100 | O33: 11932178446 | P33: Caio | Q33: 1. Aceitou o programa | R33: 46091 | T33: Contato Com Sucesso | U33: Ativo | V33: 16.03.2026 | W33: Não se aplica | X33: Não se aplica | Y33: HEMIP. A DIR. + DISLALIA - FISIO 2 X SEMANA // SEM FONO POR ORA | Z33: Aguardando Agendamento | AJ33: Sim | AK33: Sim | AL33: Pós-AVC | AM33: =MONTH(B33)&"/"&YEAR(B33) -> 3/2026 | AN33: =WEEKNUM(B33)-WEEKNUM(EOMONTH(B33,-1)+1)+1 -> 2 | AO33: =MONTH(R33)&"/"&YEAR(R33) -> 3/2026 | AP33: =WEEKNUM(R33)-WEEKNUM(EOMONTH(R33,-1)+1)+1 -> 2 | AQ33: =IF(AU33="S",IF(Q33="1. Aceitou o programa",R33-B33,0),0) -> -2 | AR33: =IF(AU33="S",IF(AND(S33<>"",R33<>""),S33-R33,0),0) -> 0 | AS33: =IF(AU33="S",IF(Q33="1. Aceitou o programa",IF(OR(X33="Não se Aplica",X33=""),IF(OR(W33="Não se Aplica",W33=""),0,W33-V33),AVERAGE(X33-W33,W33-V33)),0),0) -> 0 | AT33: =IF(AU33="S",IF(AND(Q33="1. Aceitou o programa",AB33="Realizada"),IFERROR(IF(AA33="",0,AA33-R33),0),0),0) -> 0 | AU33: =_xlfn.XLOOKUP(U33,'Lista Suspensa'!$AA$20:$AA$23,'Lista Suspensa'!$AB$20:$AB$23,"N/A") -> S
A34: Sim | B34: 46098 | C34: Captação + Navegação | D34: GSC | E34: 80514839 | F34: JOSÉ DANTAS DA SILVA | H34: 22167 | I34: 65 | J34: M | K34: SP | L34: GUARULHOS | M34: ND | N34: 700 | O34: 11999782669 | P34: Hellen | Q34: 1. Aceitou o programa | R34: 46125 | T34: Contato Com Sucesso | U34: Ativo | V34: 46100 | W34: 46125 | X34: Não se aplica | Z34: Agendada | AA34: 46126 | AB34: Não realizada - Falta | AJ34: Sim | AK34: Sim | AL34: Pós-AVC | AM34: =MONTH(B34)&"/"&YEAR(B34) -> 3/2026 | AN34: =WEEKNUM(B34)-WEEKNUM(EOMONTH(B34,-1)+1)+1 -> 3 | AO34: =MONTH(R34)&"/"&YEAR(R34) -> 4/2026 | AP34: =WEEKNUM(R34)-WEEKNUM(EOMONTH(R34,-1)+1)+1 -> 3 | AQ34: =IF(AU34="S",IF(Q34="1. Aceitou o programa",R34-B34,0),0) -> 27 | AR34: =IF(AU34="S",IF(AND(S34<>"",R34<>""),S34-R34,0),0) -> 0 | AS34: =IF(AU34="S",IF(Q34="1. Aceitou o programa",IF(OR(X34="Não se Aplica",X34=""),IF(OR(W34="Não se Aplica",W34=""),0,W34-V34),AVERAGE(X34-W34,W34-V34)),0),0) -> 25 | AT34: =IF(AU34="S",IF(AND(Q34="1. Aceitou o programa",AB34="Realizada"),IFERROR(IF(AA34="",0,AA34-R34),0),0),0) -> 0 | AU34: =_xlfn.XLOOKUP(U34,'Lista Suspensa'!$AA$20:$AA$23,'Lista Suspensa'!$AB$20:$AB$23,"N/A") -> S
A35: Sim | B35: 46099 | C35: Captação + Navegação | D35: Forms | E35: 783548516 | F35: APARECIDA DA SILVA PEREIRA | H35: 15963 | I35: 82 | J35: F | K35: SP | L35: SAO PAULO | M35: ND | N35: 100 | O35: 11974093645 | P35: Caio | Q35: 1. Aceitou o programa | R35: 46125 | T35: Contato Com Sucesso | U35: Ativo | V35: 46100 | W35: 46125 | X35: Não se aplica | Z35: Agendada | AA35: 46127 | AB35: Realizada | AD35: Baixa | AE35: 0 | AF35: Externo - Geral | AI35: Sim | AJ35: Sim | AK35: Sim | AL35: Pós-AVC | AM35: =MONTH(B35)&"/"&YEAR(B35) -> 3/2026 | AN35: =WEEKNUM(B35)-WEEKNUM(EOMONTH(B35,-1)+1)+1 -> 3 | AO35: =MONTH(R35)&"/"&YEAR(R35) -> 4/2026 | AP35: =WEEKNUM(R35)-WEEKNUM(EOMONTH(R35,-1)+1)+1 -> 3 | AQ35: =IF(AU35="S",IF(Q35="1. Aceitou o programa",R35-B35,0),0) -> 26 | AR35: =IF(AU35="S",IF(AND(S35<>"",R35<>""),S35-R35,0),0) -> 0 | AS35: =IF(AU35="S",IF(Q35="1. Aceitou o programa",IF(OR(X35="Não se Aplica",X35=""),IF(OR(W35="Não se Aplica",W35=""),0,W35-V35),AVERAGE(X35-W35,W35-V35)),0),0) -> 25 | AT35: =IF(AU35="S",IF(AND(Q35="1. Aceitou o programa",AB35="Realizada"),IFERROR(IF(AA35="",0,AA35-R35),0),0),0) -> 2 | AU35: =_xlfn.XLOOKUP(U35,'Lista Suspensa'!$AA$20:$AA$23,'Lista Suspensa'!$AB$20:$AB$23,"N/A") -> S
A36: Sim | B36: 46099 | C36: Captação + Navegação | D36: Forms | E36: 77842835 | F36: ELIU YOSHIMITSU MATSUTANI | G36: 5783748897 | H36: 23433 | I36: 62 | J36: M | K36: SP | L36: MOGI DAS CRUZES | M36: ND | N36: 60 | O36: 11975061669 | P36: Caio | Q36: 1. Aceitou o programa | R36: 46142 | T36: Contato Com Sucesso | U36: Ativo | V36: 46100 | W36: 46125 | X36: 46142 | Z36: Agendada | AA36: 06/05/2026 14:20 | AB36: Não realizada - Falta | AC36: 46161 | AJ36: Sim | AK36: Sim | AL36: Pós-AVC | AM36: =MONTH(B36)&"/"&YEAR(B36) -> 3/2026 | AN36: =WEEKNUM(B36)-WEEKNUM(EOMONTH(B36,-1)+1)+1 -> 3 | AO36: =MONTH(R36)&"/"&YEAR(R36) -> 4/2026 | AP36: =WEEKNUM(R36)-WEEKNUM(EOMONTH(R36,-1)+1)+1 -> 5 | AQ36: =IF(AU36="S",IF(Q36="1. Aceitou o programa",R36-B36,0),0) -> 43 | AR36: =IF(AU36="S",IF(AND(S36<>"",R36<>""),S36-R36,0),0) -> 0 | AS36: =IF(AU36="S",IF(Q36="1. Aceitou o programa",IF(OR(X36="Não se Aplica",X36=""),IF(OR(W36="Não se Aplica",W36=""),0,W36-V36),AVERAGE(X36-W36,W36-V36)),0),0) -> 21 | AT36: =IF(AU36="S",IF(AND(Q36="1. Aceitou o programa",AB36="Realizada"),IFERROR(IF(AA36="",0,AA36-R36),0),0),0) -> 0 | AU36: =_xlfn.XLOOKUP(U36,'Lista Suspensa'!$AA$20:$AA$23,'Lista Suspensa'!$AB$20:$AB$23,"N/A") -> S
A37: Sim | B37: 46105 | C37: Captação + Navegação | D37: Forms | E37: 84044774 | F37: LUIZ VIEIRA DA SILVA | G37: 56958757300 | H37: 27422 | I37: 51 | J37: M | K37: SP | L37: SAO PAULO | M37: VILA PROGRESSO (ZONA LESTE) | N37: 60 | O37: 11949003012 | P37: Caio | Q37: 1. Aceitou o programa | R37: 46125 | T37: Contato Com Sucesso | U37: Ativo | V37: 46107 | W37: 46125 | X37: Não se aplica | Z37: Agendada | AA37: 46126 | AB37: Realizada | AD37: Baixa | AE37: 0 | AF37: Externo - Geral | AI37: Sim | AJ37: Sim | AK37: Sim | AL37: Pós-AVC | AM37: =MONTH(B37)&"/"&YEAR(B37) -> 3/2026 | AN37: =WEEKNUM(B37)-WEEKNUM(EOMONTH(B37,-1)+1)+1 -> 4 | AO37: =MONTH(R37)&"/"&YEAR(R37) -> 4/2026 | AP37: =WEEKNUM(R37)-WEEKNUM(EOMONTH(R37,-1)+1)+1 -> 3 | AQ37: =IF(AU37="S",IF(Q37="1. Aceitou o programa",R37-B37,0),0) -> 20 | AR37: =IF(AU37="S",IF(AND(S37<>"",R37<>""),S37-R37,0),0) -> 0 | AS37: =IF(AU37="S",IF(Q37="1. Aceitou o programa",IF(OR(X37="Não se Aplica",X37=""),IF(OR(W37="Não se Aplica",W37=""),0,W37-V37),AVERAGE(X37-W37,W37-V37)),0),0) -> 18 | AT37: =IF(AU37="S",IF(AND(Q37="1. Aceitou o programa",AB37="Realizada"),IFERROR(IF(AA37="",0,AA37-R37),0),0),0) -> 1 | AU37: =_xlfn.XLOOKUP(U37,'Lista Suspensa'!$AA$20:$AA$23,'Lista Suspensa'!$AB$20:$AB$23,"N/A") -> S
A38: Sim | B38: 46105 | C38: Captação + Navegação | D38: Forms | E38: 450182800 | F38: AKIKO KATSUKI YANAGUIMOTO | G38: 668772883 | H38: 15401 | I38: 84 | J38: F | K38: SP | L38: SAO PAULO | M38: VILA BRASILINA | N38: 100 | O38: 11996049931 | P38: Caio | Q38: 6. Contato sem sucesso | S38: 46150 | T38: Contato Sem Sucesso | U38: Fora da Linha | V38: 46107 | W38: 46125 | X38: 46142 | AL38: Pós-AVC | AM38: =MONTH(B38)&"/"&YEAR(B38) -> 3/2026 | AN38: =WEEKNUM(B38)-WEEKNUM(EOMONTH(B38,-1)+1)+1 -> 4 | AO38: =MONTH(R38)&"/"&YEAR(R38) -> 1/1900 | AP38: =WEEKNUM(R38)-WEEKNUM(EOMONTH(R38,-1)+1)+1 -> #NUM! | AQ38: =IF(AU38="S",IF(Q38="1. Aceitou o programa",R38-B38,0),0) -> 0 | AR38: =IF(AU38="S",IF(AND(S38<>"",R38<>""),S38-R38,0),0) -> 0 | AS38: =IF(AU38="S",IF(Q38="1. Aceitou o programa",IF(OR(X38="Não se Aplica",X38=""),IF(OR(W38="Não se Aplica",W38=""),0,W38-V38),AVERAGE(X38-W38,W38-V38)),0),0) -> 0 | AT38: =IF(AU38="S",IF(AND(Q38="1. Aceitou o programa",AB38="Realizada"),IFERROR(IF(AA38="",0,AA38-R38),0),0),0) -> 0 | AU38: =_xlfn.XLOOKUP(U38,'Lista Suspensa'!$AA$20:$AA$23,'Lista Suspensa'!$AB$20:$AB$23,"N/A") -> S
A39: Sim | B39: 46107 | C39: Captação + Navegação | D39: Forms | E39: 451737474 | F39: AMANDIO FERREIRA RAINHO | G39: 61741361834 | H39: 12079 | I39: 93 | J39: M | K39: SP | L39: SAO PAULO | M39: JARDIM MONTE KEMEL | N39: 400 | O39: 11932029314 | P39: Caio | Q39: 6. Contato sem sucesso | S39: 46150 | T39: Contato Sem Sucesso | U39: Fora da Linha | V39: 46107 | W39: 46125 | X39: 46147 | Y39: 16/04/2026 30/04 05/05 | AL39: Pós-AVC | AM39: =MONTH(B39)&"/"&YEAR(B39) -> 3/2026 | AN39: =WEEKNUM(B39)-WEEKNUM(EOMONTH(B39,-1)+1)+1 -> 4 | AO39: =MONTH(R39)&"/"&YEAR(R39) -> 1/1900 | AP39: =WEEKNUM(R39)-WEEKNUM(EOMONTH(R39,-1)+1)+1 -> #NUM! | AQ39: =IF(AU39="S",IF(Q39="1. Aceitou o programa",R39-B39,0),0) -> 0 | AR39: =IF(AU39="S",IF(AND(S39<>"",R39<>""),S39-R39,0),0) -> 0 | AS39: =IF(AU39="S",IF(Q39="1. Aceitou o programa",IF(OR(X39="Não se Aplica",X39=""),IF(OR(W39="Não se Aplica",W39=""),0,W39-V39),AVERAGE(X39-W39,W39-V39)),0),0) -> 0 | AT39: =IF(AU39="S",IF(AND(Q39="1. Aceitou o programa",AB39="Realizada"),IFERROR(IF(AA39="",0,AA39-R39),0),0),0) -> 0 | AU39: =_xlfn.XLOOKUP(U39,'Lista Suspensa'!$AA$20:$AA$23,'Lista Suspensa'!$AB$20:$AB$23,"N/A") -> S
A40: Sim | B40: 46120 | C40: Captação + Navegação | D40: Forms | E40: 94866348 | F40: PATRICIA KELLY FERNANDES DOS SANTOS | G40: 41095646893 | H40: 33755 | I40: 33 | J40: F | K40: SP | L40: SAO PAULO | M40: Jardim Novo Pantanal | N40: 300 | O40: 11984468110 | P40: Hellen | Q40: 1. Aceitou o programa | R40: 46125 | T40: Contato Com Sucesso | U40: Ativo | V40: 46125 | W40: Não se aplica | X40: Não se aplica | Z40: Agendada | AA40: 46127 | AB40: Realizada | AJ40: Sim | AK40: Sim | AL40: Pós-AVC | AM40: =MONTH(B40)&"/"&YEAR(B40) -> 4/2026 | AN40: =WEEKNUM(B40)-WEEKNUM(EOMONTH(B40,-1)+1)+1 -> 2 | AO40: =MONTH(R40)&"/"&YEAR(R40) -> 4/2026 | AP40: =WEEKNUM(R40)-WEEKNUM(EOMONTH(R40,-1)+1)+1 -> 3 | AQ40: =IF(AU40="S",IF(Q40="1. Aceitou o programa",R40-B40,0),0) -> 5 | AR40: =IF(AU40="S",IF(AND(S40<>"",R40<>""),S40-R40,0),0) -> 0 | AS40: =IF(AU40="S",IF(Q40="1. Aceitou o programa",IF(OR(X40="Não se Aplica",X40=""),IF(OR(W40="Não se Aplica",W40=""),0,W40-V40),AVERAGE(X40-W40,W40-V40)),0),0) -> 0 | AT40: =IF(AU40="S",IF(AND(Q40="1. Aceitou o programa",AB40="Realizada"),IFERROR(IF(AA40="",0,AA40-R40),0),0),0) -> 2 | AU40: =_xlfn.XLOOKUP(U40,'Lista Suspensa'!$AA$20:$AA$23,'Lista Suspensa'!$AB$20:$AB$23,"N/A") -> S
...

Sheet Análise
B2: Linha | C2: Pós-AVC
B3: Motivo Envio
B4: Situação Atual do Paciente | C4: Total
B7: Mês/Ano | C7: 46143 | D7: >> Inserir no formato Mês / Ano apenas - como 01/2026, 02/2026, etc.
B9: Início | C9: 46023
B10: Fim | C10: 46165
B12: CONTAGEM DE PACIENTES
B14: Status BNF Linha | C14: Semana | H14: Mês | K14: Parâmetros | L14: Semana | S14: Status BNF Linha | T14: Absoluto | U14: Percentual | W14: Parâmetros
C15: 1 | D15: 2 | E15: 3 | F15: 4 | G15: 5 | H15: Absoluto | I15: Percentual | L15: 1 | M15: 2 | N15: 3 | O15: 4 | P15: 5 | Q15: Mês | S15: 1. Aceitou o programa | T15: =COUNTIFS(Consolidado!$AL:$AL,IF(ISBLANK($C$2),"<>",$C$2),Consolidado!$Q:$Q,Análise!S15,Consolidado!$B:$B,"<="&Análise!$C$10,Consolidado!$B:$B,">="&Análise!$C$9,Consolidado!$C:$C,IF(ISBLANK($C$3),"<>",$C$3),Consolidado!$AU:$AU,"S") -> 40 | U15: =IFERROR(T15/$T$40,0) -> 0.66666667 | W15: Taxa de Captação | Y15: =IFERROR(T15/T40,0) -> 0.66666667
B16: 1. Aceitou o programa | C16: =COUNTIFS(Consolidado!$AN:$AN,Análise!C$15,Consolidado!$AM:$AM,Análise!$C$7,Consolidado!$AL:$AL,IF(ISBLANK($C$2),"<>",$C$2),Consolidado!$Q:$Q,Análise!$B16,Consolidado!$C:$C,IF(ISBLANK($C$3),"<>",$C$3),Consolidado!$AU:$AU,"S") -> 0 | D16: =COUNTIFS(Consolidado!$AN:$AN,Análise!D$15,Consolidado!$AM:$AM,Análise!$C$7,Consolidado!$AL:$AL,IF(ISBLANK($C$2),"<>",$C$2),Consolidado!$Q:$Q,Análise!$B16,Consolidado!$C:$C,IF(ISBLANK($C$3),"<>",$C$3),Consolidado!$AU:$AU,"S") -> 3 | E16: =COUNTIFS(Consolidado!$AN:$AN,Análise!E$15,Consolidado!$AM:$AM,Análise!$C$7,Consolidado!$AL:$AL,IF(ISBLANK($C$2),"<>",$C$2),Consolidado!$Q:$Q,Análise!$B16,Consolidado!$C:$C,IF(ISBLANK($C$3),"<>",$C$3),Consolidado!$AU:$AU,"S") -> 0 | F16: =COUNTIFS(Consolidado!$AN:$AN,Análise!F$15,Consolidado!$AM:$AM,Análise!$C$7,Consolidado!$AL:$AL,IF(ISBLANK($C$2),"<>",$C$2),Consolidado!$Q:$Q,Análise!$B16,Consolidado!$C:$C,IF(ISBLANK($C$3),"<>",$C$3),Consolidado!$AU:$AU,"S") -> 1 | G16: =COUNTIFS(Consolidado!$AN:$AN,Análise!G$15,Consolidado!$AM:$AM,Análise!$C$7,Consolidado!$AL:$AL,IF(ISBLANK($C$2),"<>",$C$2),Consolidado!$Q:$Q,Análise!$B16,Consolidado!$C:$C,IF(ISBLANK($C$3),"<>",$C$3),Consolidado!$AU:$AU,"S") -> 0 | H16: =SUM(C16:G16) -> 4 | I16: =+IFERROR(H16/$H$41,0) -> 0.8 | K16: Total | L16: =+C41 -> 0 | M16: =+D41 -> 3 | N16: =+E41 -> 0 | O16: =+F41 -> 2 | P16: =+G41 -> 0 | Q16: =+H41 -> 5 | S16: 2. Em avaliação para participar do programa | T16: =COUNTIFS(Consolidado!$AL:$AL,IF(ISBLANK($C$2),"<>",$C$2),Consolidado!$Q:$Q,Análise!S16,Consolidado!$B:$B,"<="&Análise!$C$10,Consolidado!$B:$B,">="&Análise!$C$9,Consolidado!$C:$C,IF(ISBLANK($C$3),"<>",$C$3),Consolidado!$AU:$AU,"S") -> 0 | U16: =IFERROR(T16/$T$40,0) -> 0 | W16: SLA Captação Médio | Y16: =IFERROR(SUMIFS(Consolidado!AQ:AQ,Consolidado!$AL:$AL,IF(ISBLANK($C$2),"<>",$C$2),Consolidado!$B:$B,"<="&Análise!$C$10,Consolidado!$B:$B,">="&Análise!$C$9,Consolidado!$C:$C,IF(ISBLANK($C$3),"<>",$C$3))/T15,0) -> 29.575
B17: 2. Em avaliação para participar do programa | C17: =COUNTIFS(Consolidado!$AN:$AN,Análise!C$15,Consolidado!$AM:$AM,Análise!$C$7,Consolidado!$AL:$AL,IF(ISBLANK($C$2),"<>",$C$2),Consolidado!$Q:$Q,Análise!$B17,Consolidado!$C:$C,IF(ISBLANK($C$3),"<>",$C$3),Consolidado!$AU:$AU,"S") -> 0 | D17: =COUNTIFS(Consolidado!$AN:$AN,Análise!D$15,Consolidado!$AM:$AM,Análise!$C$7,Consolidado!$AL:$AL,IF(ISBLANK($C$2),"<>",$C$2),Consolidado!$Q:$Q,Análise!$B17,Consolidado!$C:$C,IF(ISBLANK($C$3),"<>",$C$3),Consolidado!$AU:$AU,"S") -> 0 | E17: =COUNTIFS(Consolidado!$AN:$AN,Análise!E$15,Consolidado!$AM:$AM,Análise!$C$7,Consolidado!$AL:$AL,IF(ISBLANK($C$2),"<>",$C$2),Consolidado!$Q:$Q,Análise!$B17,Consolidado!$C:$C,IF(ISBLANK($C$3),"<>",$C$3),Consolidado!$AU:$AU,"S") -> 0 | F17: =COUNTIFS(Consolidado!$AN:$AN,Análise!F$15,Consolidado!$AM:$AM,Análise!$C$7,Consolidado!$AL:$AL,IF(ISBLANK($C$2),"<>",$C$2),Consolidado!$Q:$Q,Análise!$B17,Consolidado!$C:$C,IF(ISBLANK($C$3),"<>",$C$3),Consolidado!$AU:$AU,"S") -> 0 | G17: =COUNTIFS(Consolidado!$AN:$AN,Análise!G$15,Consolidado!$AM:$AM,Análise!$C$7,Consolidado!$AL:$AL,IF(ISBLANK($C$2),"<>",$C$2),Consolidado!$Q:$Q,Análise!$B17,Consolidado!$C:$C,IF(ISBLANK($C$3),"<>",$C$3),Consolidado!$AU:$AU,"S") -> 0 | H17: =SUM(C17:G17) -> 0 | I17: =+IFERROR(H17/$H$41,0) -> 0 | K17: 1. Aceitou o programa | L17: =+C16 -> 0 | M17: =+D16 -> 3 | N17: =+E16 -> 0 | O17: =+F16 -> 1 | P17: =+G16 -> 0 | Q17: =+H16 -> 4 | S17: 3. Recusa por conta da assinatura do termo | T17: =COUNTIFS(Consolidado!$AL:$AL,IF(ISBLANK($C$2),"<>",$C$2),Consolidado!$Q:$Q,Análise!S17,Consolidado!$B:$B,"<="&Análise!$C$10,Consolidado!$B:$B,">="&Análise!$C$9,Consolidado!$C:$C,IF(ISBLANK($C$3),"<>",$C$3),Consolidado!$AU:$AU,"S") -> 0 | U17: =IFERROR(T17/$T$40,0) -> 0 | W17: SLA Tent. Contato Médio | Y17: =IFERROR(SUMIFS(Consolidado!AS:AS,Consolidado!$AL:$AL,IF(ISBLANK($C$2),"<>",$C$2),Consolidado!$B:$B,"<="&Análise!$C$10,Consolidado!$B:$B,">="&Análise!$C$9,Consolidado!$C:$C,IF(ISBLANK($C$3),"<>",$C$3))/COUNTIFS(Consolidado!$AL:$AL,IF(ISBLANK($C$2),"<>",$C$2),Consolidado!$Q:$Q,S$15,Consolidado!$B:$B,"<="&Análise!$C$10,Consolidado!$B:$B,">="&Análise!$C$9,Consolidado!$C:$C,IF(ISBLANK($C$3),"<>",$C$3),Consolidado!$AS:$AS,"<>"&0),0) -> 21.214286
B18: 3. Recusa por conta da assinatura do termo | C18: =COUNTIFS(Consolidado!$AN:$AN,Análise!C$15,Consolidado!$AM:$AM,Análise!$C$7,Consolidado!$AL:$AL,IF(ISBLANK($C$2),"<>",$C$2),Consolidado!$Q:$Q,Análise!$B18,Consolidado!$C:$C,IF(ISBLANK($C$3),"<>",$C$3),Consolidado!$AU:$AU,"S") -> 0 | D18: =COUNTIFS(Consolidado!$AN:$AN,Análise!D$15,Consolidado!$AM:$AM,Análise!$C$7,Consolidado!$AL:$AL,IF(ISBLANK($C$2),"<>",$C$2),Consolidado!$Q:$Q,Análise!$B18,Consolidado!$C:$C,IF(ISBLANK($C$3),"<>",$C$3),Consolidado!$AU:$AU,"S") -> 0 | E18: =COUNTIFS(Consolidado!$AN:$AN,Análise!E$15,Consolidado!$AM:$AM,Análise!$C$7,Consolidado!$AL:$AL,IF(ISBLANK($C$2),"<>",$C$2),Consolidado!$Q:$Q,Análise!$B18,Consolidado!$C:$C,IF(ISBLANK($C$3),"<>",$C$3),Consolidado!$AU:$AU,"S") -> 0 | F18: =COUNTIFS(Consolidado!$AN:$AN,Análise!F$15,Consolidado!$AM:$AM,Análise!$C$7,Consolidado!$AL:$AL,IF(ISBLANK($C$2),"<>",$C$2),Consolidado!$Q:$Q,Análise!$B18,Consolidado!$C:$C,IF(ISBLANK($C$3),"<>",$C$3),Consolidado!$AU:$AU,"S") -> 0 | G18: =COUNTIFS(Consolidado!$AN:$AN,Análise!G$15,Consolidado!$AM:$AM,Análise!$C$7,Consolidado!$AL:$AL,IF(ISBLANK($C$2),"<>",$C$2),Consolidado!$Q:$Q,Análise!$B18,Consolidado!$C:$C,IF(ISBLANK($C$3),"<>",$C$3),Consolidado!$AU:$AU,"S") -> 0 | H18: =SUM(C18:G18) -> 0 | I18: =+IFERROR(H18/$H$41,0) -> 0 | K18: Taxa de Captação | L18: =IFERROR(L17/L16,"") | M18: =IFERROR(M17/M16,"") -> 1 | N18: =IFERROR(N17/N16,"") | O18: =IFERROR(O17/O16,"") -> 0.5 | P18: =IFERROR(P17/P16,"") | Q18: =IFERROR(Q17/Q16,"") -> 0.8 | S18: 3. Recusa por desconfiança do programa | T18: =COUNTIFS(Consolidado!$AL:$AL,IF(ISBLANK($C$2),"<>",$C$2),Consolidado!$Q:$Q,Análise!S18,Consolidado!$B:$B,"<="&Análise!$C$10,Consolidado!$B:$B,">="&Análise!$C$9,Consolidado!$C:$C,IF(ISBLANK($C$3),"<>",$C$3),Consolidado!$AU:$AU,"S") -> 0 | U18: =IFERROR(T18/$T$40,0) -> 0 | W18: SLA Consulta Médio | Y18: =IFERROR(SUMIFS(Consolidado!AT:AT,Consolidado!$AL:$AL,IF(ISBLANK($C$2),"<>",$C$2),Consolidado!$B:$B,"<="&Análise!$C$10,Consolidado!$B:$B,">="&Análise!$C$9,Consolidado!$C:$C,IF(ISBLANK($C$3),"<>",$C$3))/COUNTIFS(Consolidado!$AL:$AL,IF(ISBLANK($C$2),"<>",$C$2),Consolidado!$Q:$Q,S$15,Consolidado!$B:$B,"<="&Análise!$C$10,Consolidado!$B:$B,">="&Análise!$C$9,Consolidado!$C:$C,IF(ISBLANK($C$3),"<>",$C$3),Consolidado!$AT:$AT,"<>"&0),0) -> 20.792484
B19: 3. Recusa por desconfiança do programa | C19: =COUNTIFS(Consolidado!$AN:$AN,Análise!C$15,Consolidado!$AM:$AM,Análise!$C$7,Consolidado!$AL:$AL,IF(ISBLANK($C$2),"<>",$C$2),Consolidado!$Q:$Q,Análise!$B19,Consolidado!$C:$C,IF(ISBLANK($C$3),"<>",$C$3),Consolidado!$AU:$AU,"S") -> 0 | D19: =COUNTIFS(Consolidado!$AN:$AN,Análise!D$15,Consolidado!$AM:$AM,Análise!$C$7,Consolidado!$AL:$AL,IF(ISBLANK($C$2),"<>",$C$2),Consolidado!$Q:$Q,Análise!$B19,Consolidado!$C:$C,IF(ISBLANK($C$3),"<>",$C$3),Consolidado!$AU:$AU,"S") -> 0 | E19: =COUNTIFS(Consolidado!$AN:$AN,Análise!E$15,Consolidado!$AM:$AM,Análise!$C$7,Consolidado!$AL:$AL,IF(ISBLANK($C$2),"<>",$C$2),Consolidado!$Q:$Q,Análise!$B19,Consolidado!$C:$C,IF(ISBLANK($C$3),"<>",$C$3),Consolidado!$AU:$AU,"S") -> 0 | F19: =COUNTIFS(Consolidado!$AN:$AN,Análise!F$15,Consolidado!$AM:$AM,Análise!$C$7,Consolidado!$AL:$AL,IF(ISBLANK($C$2),"<>",$C$2),Consolidado!$Q:$Q,Análise!$B19,Consolidado!$C:$C,IF(ISBLANK($C$3),"<>",$C$3),Consolidado!$AU:$AU,"S") -> 0 | G19: =COUNTIFS(Consolidado!$AN:$AN,Análise!G$15,Consolidado!$AM:$AM,Análise!$C$7,Consolidado!$AL:$AL,IF(ISBLANK($C$2),"<>",$C$2),Consolidado!$Q:$Q,Análise!$B19,Consolidado!$C:$C,IF(ISBLANK($C$3),"<>",$C$3),Consolidado!$AU:$AU,"S") -> 0 | H19: =SUM(C19:G19) -> 0 | I19: =+IFERROR(H19/$H$41,0) -> 0 | K19: SLA Captação Médio | L19: =IFERROR(SUMIFS(Consolidado!$AQ:$AQ,Consolidado!$AN:$AN,Análise!L15,Consolidado!$AM:$AM,Análise!$C$7,Consolidado!$AL:$AL,IF(ISBLANK($C$2),"<>",$C$2),Consolidado!$C:$C,IF(ISBLANK($C$3),"<>",$C$3))/L$17,0) -> 0 | M19: =IFERROR(SUMIFS(Consolidado!$AQ:$AQ,Consolidado!$AN:$AN,Análise!M15,Consolidado!$AM:$AM,Análise!$C$7,Consolidado!$AL:$AL,IF(ISBLANK($C$2),"<>",$C$2),Consolidado!$C:$C,IF(ISBLANK($C$3),"<>",$C$3))/M$17,0) -> 22.666667 | N19: =IFERROR(SUMIFS(Consolidado!$AQ:$AQ,Consolidado!$AN:$AN,Análise!N15,Consolidado!$AM:$AM,Análise!$C$7,Consolidado!$AL:$AL,IF(ISBLANK($C$2),"<>",$C$2),Consolidado!$C:$C,IF(ISBLANK($C$3),"<>",$C$3))/N$17,0) -> 0 | O19: =IFERROR(SUMIFS(Consolidado!$AQ:$AQ,Consolidado!$AN:$AN,Análise!O15,Consolidado!$AM:$AM,Análise!$C$7,Consolidado!$AL:$AL,IF(ISBLANK($C$2),"<>",$C$2),Consolidado!$C:$C,IF(ISBLANK($C$3),"<>",$C$3))/O$17,0) -> 15 | P19: =IFERROR(SUMIFS(Consolidado!$AQ:$AQ,Consolidado!$AN:$AN,Análise!P15,Consolidado!$AM:$AM,Análise!$C$7,Consolidado!$AL:$AL,IF(ISBLANK($C$2),"<>",$C$2),Consolidado!$C:$C,IF(ISBLANK($C$3),"<>",$C$3))/P$17,0) -> 0 | Q19: =IFERROR(SUMIFS(Consolidado!AQ:AQ,Consolidado!$AM:$AM,Análise!$C$7,Consolidado!$AL:$AL,IF(ISBLANK($C$2),"<>",$C$2),Consolidado!$C:$C,IF(ISBLANK($C$3),"<>",$C$3))/$Q17,0) -> 20.75 | S19: 3. Recusa por falta de interesse | T19: =COUNTIFS(Consolidado!$AL:$AL,IF(ISBLANK($C$2),"<>",$C$2),Consolidado!$Q:$Q,Análise!S19,Consolidado!$B:$B,"<="&Análise!$C$10,Consolidado!$B:$B,">="&Análise!$C$9,Consolidado!$C:$C,IF(ISBLANK($C$3),"<>",$C$3),Consolidado!$AU:$AU,"S") -> 6 | U19: =IFERROR(T19/$T$40,0) -> 0.1 | W19: SLA Exclusão Médio | Y19: =IFERROR(SUMIFS(Consolidado!$AR:$AR,Consolidado!$B:$B,"<="&Análise!$C$10,Consolidado!$B:$B,">="&Análise!$C$9,Consolidado!$AM:$AM,Análise!$C$7,Consolidado!$AL:$AL,IF(ISBLANK($C$2),"<>",$C$2),Consolidado!$C:$C,IF(ISBLANK($C$3),"<>",$C$3))/COUNTIFS(Consolidado!$R:$R,"<>",Consolidado!$S:$S,"<>",Consolidado!$AM:$AM,Análise!$C$7,Consolidado!$AL:$AL,IF(ISBLANK($C$2),"<>",$C$2),Consolidado!$C:$C,IF(ISBLANK($C$3),"<>",$C$3),Consolidado!$B:$B,"<="&Análise!$C$10,Consolidado!$B:$B,">="&Análise!$C$9),0) -> 0
