Workbook

Sheet Consolidado
A1: Prioridade no Contato? | B1: Data Envio Paciente | C1: Motivo Envio | D1: Origem | E1: MO | F1: Nome do paciente | G1: CPF | H1: Data de Nascimento | I1: Idade | J1: Genero | K1: Estado | L1: Município | M1: Bairro | N1: Nível de Rede | O1: Telefone atualizado | P1: Profissional | Q1: Status BNF Linha | R1: Data de Inclusão | S1: Data da Alta, Inatividade ou Recusa | T1: Status Do Contato | U1: Situação Atual Do Paciente | V1: Tentativa de Contato 1 | W1: Tentativa de Contato 2 | X1: Tentativa de Contato 3 | Y1: Observações Importantes | Z1: Status Pré Consulta Enfermagem | AA1: Data 1ª Consulta de Enfermagem | AB1: Status da 1ª Consulta Enfermagem | AC1: Se reagendado, sinalizar datas | AD1: Complexidade | AE1: Resultado da Escala | AF1: Meta INR | AG1: INR De Admissão | AH1: Local de Acomapanhamento inicial | AI1: Local de Acomapanhamento atual | AJ1: Diagnóstico confirmado? | AK1: Direcionado a HUBS? | AL1: Flag | AM1: Encaminhado p/ Consolidado? | AN1: Linha | AO1: Mês/Ano | AP1: Semana | AQ1: Mês/Ano Inclusão | AR1: Semana Inclusão | AS1: SLA Captação | AT1: SLA Exclusão | AU1: SLA Tent. Contatos | AV1: SLA Consulta | AW1: Ativo/Inativo
A2: Não | B2: 46147 | C2: Transbordo/Navegação | D2: Captado pela Amil/Call Center | E2: 85446146 | F2: RAFAEL TANGANELLI PALLAMIN | G2: 34644803804 | H2: 31458 | I2: 40 | J2: M | K2: SP | L2: CAJAMAR | N2: NÍVEL 450 | O2: 11-997679993 | P2: ISMAEL | Q2: 1. Aceitou o programa | R2: 46171 | T2: Contato Com Sucesso | U2: Ativo | V2: 46149 | W2: 46161 | X2: 46171 | Z2: Agendada | AA2: 46180.653 | AB2: Não realizada - Falta | AL2: Sim | AM2: Sim | AN2: Anticoagulante | AO2: =MONTH(B2)&"/"&YEAR(B2) -> 5/2026 | AP2: =WEEKNUM(B2)-WEEKNUM(EOMONTH(B2,-1)+1)+1 -> 2 | AQ2: =MONTH(R2)&"/"&YEAR(R2) -> 5/2026 | AR2: =WEEKNUM(R2)-WEEKNUM(EOMONTH(R2,-1)+1)+1 -> 5 | AS2: =IF(AW2="S",IF(Q2="1. Aceitou o programa",R2-B2,0),0) -> 0 | AT2: =IF(AW2="S",IF(AND(S2<>"",R2<>""),S2-R2,0),0) -> 0 | AU2: =IF(AW2="S",IF(Q2="1. Aceitou o programa",IF(OR(X2="Não se Aplica",X2=""),IF(OR(W2="Não se Aplica",W2=""),0,W2-V2),AVERAGE(X2-W2,W2-V2)),0),0) -> 0 | AV2: =IF(AW2="S",IF(AND(Q2="1. Aceitou o programa",AB2="Realizada"),IFERROR(IF(AA2="",0,AA2-R2),0),0),0) -> 0 | AW2: =_xlfn.XLOOKUP(W2,'Lista Suspensa'!$AA$20:$AA$23,'Lista Suspensa'!$AB$20:$AB$23,"N/A") -> N/A
A3: Não | B3: 46147 | C3: Transbordo/Navegação | D3: Captado pela Amil/Call Center | E3: 89181160 | F3: MARILIA MARIA MENDES QUINTAL | G3: 18853578858 | H3: 26800 | I3: 53 | J3: F | K3: SP | L3: DIADEMA | N3: NÍVEL 50 | O3: 11-980889917 | P3: ISMAEL | Q3: 5. Alta por exclusão do plano | R3: 46171 | S3: 46181 | T3: Contato Com Sucesso | U3: Fora da Linha | V3: 46161 | W3: 46171 | X3: Não se aplica | Y3: Migração de plano (SulAmerica) | Z3: Agendada | AA3: 46181.472 | AB3: Realizada | AL3: Desflagado | AN3: Anticoagulante | AO3: =MONTH(B3)&"/"&YEAR(B3) -> 5/2026 | AP3: =WEEKNUM(B3)-WEEKNUM(EOMONTH(B3,-1)+1)+1 -> 2 | AQ3: =MONTH(R3)&"/"&YEAR(R3) -> 5/2026 | AR3: =WEEKNUM(R3)-WEEKNUM(EOMONTH(R3,-1)+1)+1 -> 5 | AS3: =IF(AW3="S",IF(Q3="1. Aceitou o programa",R3-B3,0),0) -> 0 | AT3: =IF(AW3="S",IF(AND(S3<>"",R3<>""),S3-R3,0),0) -> 0 | AU3: =IF(AW3="S",IF(Q3="1. Aceitou o programa",IF(OR(X3="Não se Aplica",X3=""),IF(OR(W3="Não se Aplica",W3=""),0,W3-V3),AVERAGE(X3-W3,W3-V3)),0),0) -> 0 | AV3: =IF(AW3="S",IF(AND(Q3="1. Aceitou o programa",AB3="Realizada"),IFERROR(IF(AA3="",0,AA3-R3),0),0),0) -> 0 | AW3: =_xlfn.XLOOKUP(W3,'Lista Suspensa'!$AA$20:$AA$23,'Lista Suspensa'!$AB$20:$AB$23,"N/A") -> N/A
A4: Não | B4: 46147 | C4: Transbordo/Navegação | D4: Captado pela Amil/Call Center | E4: 75036529 | F4: SIDNEI SOARES DO ROSARIO | G4: 89504372791 | H4: 24128 | I4: 60 | J4: M | K4: RJ | L4: RIO DE JANEIRO | N4: NÍVEL 50 | O4: 21-964464107 | P4: ISMAEL | Q4: 1. Aceitou o programa | R4: 46171 | T4: Contato Com Sucesso | U4: Ativo | V4: 46161 | W4: 46171 | X4: Não se aplica | Z4: Agendada | AA4: 46181.542 | AB4: Não realizada - Falta | AL4: Sim | AM4: Sim | AN4: Anticoagulante | AO4: =MONTH(B4)&"/"&YEAR(B4) -> 5/2026 | AP4: =WEEKNUM(B4)-WEEKNUM(EOMONTH(B4,-1)+1)+1 -> 2 | AQ4: =MONTH(R4)&"/"&YEAR(R4) -> 5/2026 | AR4: =WEEKNUM(R4)-WEEKNUM(EOMONTH(R4,-1)+1)+1 -> 5 | AS4: =IF(AW4="S",IF(Q4="1. Aceitou o programa",R4-B4,0),0) -> 0 | AT4: =IF(AW4="S",IF(AND(S4<>"",R4<>""),S4-R4,0),0) -> 0 | AU4: =IF(AW4="S",IF(Q4="1. Aceitou o programa",IF(OR(X4="Não se Aplica",X4=""),IF(OR(W4="Não se Aplica",W4=""),0,W4-V4),AVERAGE(X4-W4,W4-V4)),0),0) -> 0 | AV4: =IF(AW4="S",IF(AND(Q4="1. Aceitou o programa",AB4="Realizada"),IFERROR(IF(AA4="",0,AA4-R4),0),0),0) -> 0 | AW4: =_xlfn.XLOOKUP(W4,'Lista Suspensa'!$AA$20:$AA$23,'Lista Suspensa'!$AB$20:$AB$23,"N/A") -> N/A
A5: Não | B5: 46147 | C5: Transbordo/Navegação | D5: Captado pela Amil/Call Center | E5: 79819936 | F5: JESSICA TELES DE CASTRO | G5: 38914973859 | H5: 33450 | I5: 34 | J5: F | K5: SP | L5: SANTO ANDRE | N5: NÍVEL 60 | O5: 11-959173739 | P5: ISMAEL | Q5: 5. Alta por inelegibilidade | R5: 46171 | S5: 46181 | T5: Contato Com Sucesso | U5: Fora da Linha | V5: 46161 | W5: 46171 | X5: Não se aplica | Z5: Agendada | AA5: 46181.597 | AB5: Realizada | AL5: Desflagado | AN5: Anticoagulante | AO5: =MONTH(B5)&"/"&YEAR(B5) -> 5/2026 | AP5: =WEEKNUM(B5)-WEEKNUM(EOMONTH(B5,-1)+1)+1 -> 2 | AQ5: =MONTH(R5)&"/"&YEAR(R5) -> 5/2026 | AR5: =WEEKNUM(R5)-WEEKNUM(EOMONTH(R5,-1)+1)+1 -> 5 | AS5: =IF(AW5="S",IF(Q5="1. Aceitou o programa",R5-B5,0),0) -> 0 | AT5: =IF(AW5="S",IF(AND(S5<>"",R5<>""),S5-R5,0),0) -> 0 | AU5: =IF(AW5="S",IF(Q5="1. Aceitou o programa",IF(OR(X5="Não se Aplica",X5=""),IF(OR(W5="Não se Aplica",W5=""),0,W5-V5),AVERAGE(X5-W5,W5-V5)),0),0) -> 0 | AV5: =IF(AW5="S",IF(AND(Q5="1. Aceitou o programa",AB5="Realizada"),IFERROR(IF(AA5="",0,AA5-R5),0),0),0) -> 0 | AW5: =_xlfn.XLOOKUP(W5,'Lista Suspensa'!$AA$20:$AA$23,'Lista Suspensa'!$AB$20:$AB$23,"N/A") -> N/A
A6: Não | B6: 46147 | C6: Transbordo/Navegação | D6: Captado pela Amil/Call Center | E6: 89188339 | F6: MARIA DO CARMO PEIXOTO DOS SANTOS | G6: 6942777897 | H6: 23854 | I6: 61 | J6: F | K6: SP | L6: SAO BERNARDO DO CAMPO | N6: NÍVEL 80 | O6: 11-997956469 | P6: ISMAEL | Q6: 1. Aceitou o programa | R6: 46171 | T6: Contato Com Sucesso | U6: Ativo | V6: 46161 | W6: 46171 | X6: Não se aplica | Z6: Agendada | AA6: 46181.556 | AB6: Realizada | AF6: 2,5-3,5 | AG6: 2.93 | AH6: Não Informou | AI6: Não Informou | AJ6: Confirmado | AL6: Sim | AM6: Sim | AN6: Anticoagulante | AO6: =MONTH(B6)&"/"&YEAR(B6) -> 5/2026 | AP6: =WEEKNUM(B6)-WEEKNUM(EOMONTH(B6,-1)+1)+1 -> 2 | AQ6: =MONTH(R6)&"/"&YEAR(R6) -> 5/2026 | AR6: =WEEKNUM(R6)-WEEKNUM(EOMONTH(R6,-1)+1)+1 -> 5 | AS6: =IF(AW6="S",IF(Q6="1. Aceitou o programa",R6-B6,0),0) -> 0 | AT6: =IF(AW6="S",IF(AND(S6<>"",R6<>""),S6-R6,0),0) -> 0 | AU6: =IF(AW6="S",IF(Q6="1. Aceitou o programa",IF(OR(X6="Não se Aplica",X6=""),IF(OR(W6="Não se Aplica",W6=""),0,W6-V6),AVERAGE(X6-W6,W6-V6)),0),0) -> 0 | AV6: =IF(AW6="S",IF(AND(Q6="1. Aceitou o programa",AB6="Realizada"),IFERROR(IF(AA6="",0,AA6-R6),0),0),0) -> 0 | AW6: =_xlfn.XLOOKUP(W6,'Lista Suspensa'!$AA$20:$AA$23,'Lista Suspensa'!$AB$20:$AB$23,"N/A") -> N/A
A7: Não | B7: 46147 | C7: Transbordo/Navegação | D7: Captado pela Amil/Call Center | E7: 774791853 | F7: JOAO ONHA NETO | G7: 57698481891 | H7: 19073 | I7: 74 | J7: M | K7: SP | L7: SAO PAULO | N7: NÍVEL 300 | O7: 11-918465404 | P7: ISMAEL | Q7: 1. Aceitou o programa | R7: 46171 | T7: Contato Com Sucesso | U7: Ativo | V7: 46161 | W7: 46171 | X7: Não se aplica | Z7: Agendada | AA7: 46183 | AB7: Realizada | AL7: Sim | AM7: Sim | AN7: Anticoagulante | AO7: =MONTH(B7)&"/"&YEAR(B7) -> 5/2026 | AP7: =WEEKNUM(B7)-WEEKNUM(EOMONTH(B7,-1)+1)+1 -> 2 | AQ7: =MONTH(R7)&"/"&YEAR(R7) -> 5/2026 | AR7: =WEEKNUM(R7)-WEEKNUM(EOMONTH(R7,-1)+1)+1 -> 5 | AS7: =IF(AW7="S",IF(Q7="1. Aceitou o programa",R7-B7,0),0) -> 0 | AT7: =IF(AW7="S",IF(AND(S7<>"",R7<>""),S7-R7,0),0) -> 0 | AU7: =IF(AW7="S",IF(Q7="1. Aceitou o programa",IF(OR(X7="Não se Aplica",X7=""),IF(OR(W7="Não se Aplica",W7=""),0,W7-V7),AVERAGE(X7-W7,W7-V7)),0),0) -> 0 | AV7: =IF(AW7="S",IF(AND(Q7="1. Aceitou o programa",AB7="Realizada"),IFERROR(IF(AA7="",0,AA7-R7),0),0),0) -> 0 | AW7: =_xlfn.XLOOKUP(W7,'Lista Suspensa'!$AA$20:$AA$23,'Lista Suspensa'!$AB$20:$AB$23,"N/A") -> N/A
A8: Não | B8: 46147 | C8: Transbordo/Navegação | D8: Captado pela Amil/Call Center | E8: 300996381 | F8: JOSE DONIZETI PASSARETTI | G8: 94259348868 | H8: 21493 | I8: 67 | J8: M | K8: SP | L8: SAO PAULO | N8: NÍVEL 600 | O8: 11-940088681 | P8: ISMAEL | Q8: 1. Aceitou o programa | R8: 46171 | T8: Contato Com Sucesso | U8: Ativo | V8: 46161 | W8: 46171 | X8: Não se aplica | Z8: Agendada | AA8: 46181.528 | AB8: Realizada | AL8: Sim | AM8: Sim | AN8: Anticoagulante | AO8: =MONTH(B8)&"/"&YEAR(B8) -> 5/2026 | AP8: =WEEKNUM(B8)-WEEKNUM(EOMONTH(B8,-1)+1)+1 -> 2 | AQ8: =MONTH(R8)&"/"&YEAR(R8) -> 5/2026 | AR8: =WEEKNUM(R8)-WEEKNUM(EOMONTH(R8,-1)+1)+1 -> 5 | AS8: =IF(AW8="S",IF(Q8="1. Aceitou o programa",R8-B8,0),0) -> 0 | AT8: =IF(AW8="S",IF(AND(S8<>"",R8<>""),S8-R8,0),0) -> 0 | AU8: =IF(AW8="S",IF(Q8="1. Aceitou o programa",IF(OR(X8="Não se Aplica",X8=""),IF(OR(W8="Não se Aplica",W8=""),0,W8-V8),AVERAGE(X8-W8,W8-V8)),0),0) -> 0 | AV8: =IF(AW8="S",IF(AND(Q8="1. Aceitou o programa",AB8="Realizada"),IFERROR(IF(AA8="",0,AA8-R8),0),0),0) -> 0 | AW8: =_xlfn.XLOOKUP(W8,'Lista Suspensa'!$AA$20:$AA$23,'Lista Suspensa'!$AB$20:$AB$23,"N/A") -> N/A
A9: Não | B9: 46147 | C9: Transbordo/Navegação | D9: Captado pela Amil/Call Center | E9: 20910320 | F9: LEANDRO DOS SANTOS | G9: 18802713898 | H9: 27016 | I9: 52 | J9: M | K9: SP | L9: SAO PAULO | N9: NÍVEL 400 | O9: 11-941412995 | P9: ISMAEL | Q9: 1. Aceitou o programa | R9: 46171 | T9: Contato Com Sucesso | U9: Ativo | V9: 46161 | W9: 46171 | X9: Não se aplica | Z9: Agendada | AA9: 46181.514 | AB9: Não realizada - Falta | AL9: Sim | AM9: Sim | AN9: Anticoagulante | AO9: =MONTH(B9)&"/"&YEAR(B9) -> 5/2026 | AP9: =WEEKNUM(B9)-WEEKNUM(EOMONTH(B9,-1)+1)+1 -> 2 | AQ9: =MONTH(R9)&"/"&YEAR(R9) -> 5/2026 | AR9: =WEEKNUM(R9)-WEEKNUM(EOMONTH(R9,-1)+1)+1 -> 5 | AS9: =IF(AW9="S",IF(Q9="1. Aceitou o programa",R9-B9,0),0) -> 0 | AT9: =IF(AW9="S",IF(AND(S9<>"",R9<>""),S9-R9,0),0) -> 0 | AU9: =IF(AW9="S",IF(Q9="1. Aceitou o programa",IF(OR(X9="Não se Aplica",X9=""),IF(OR(W9="Não se Aplica",W9=""),0,W9-V9),AVERAGE(X9-W9,W9-V9)),0),0) -> 0 | AV9: =IF(AW9="S",IF(AND(Q9="1. Aceitou o programa",AB9="Realizada"),IFERROR(IF(AA9="",0,AA9-R9),0),0),0) -> 0 | AW9: =_xlfn.XLOOKUP(W9,'Lista Suspensa'!$AA$20:$AA$23,'Lista Suspensa'!$AB$20:$AB$23,"N/A") -> N/A
A10: Sim | B10: 46147 | C10: Transbordo/Navegação | D10: Captado pela Amil/Call Center | E10: 452291500 | F10: ANA PAULA BRITO DOS SANTOS | G10: 34125773831 | H10: 29952 | I10: 44 | J10: F | K10: SP | L10: SAO PAULO | N10: NÍVEL 300 | O10: 11-954400383 | P10: ISMAEL | Q10: 1. Aceitou o programa | R10: 46171 | T10: Contato Com Sucesso | U10: Ativo | V10: 46153 | W10: 46171 | X10: 46164 | Z10: Agendada | AA10: 46181 | AB10: Realizada | AF10: N/A | AG10: N/A | AH10: Hospital Alvorada Moema | AI10: Hospital Alvorada Moema | AJ10: Confirmado | AL10: Sim | AM10: Sim | AN10: Anticoagulante | AO10: =MONTH(B10)&"/"&YEAR(B10) -> 5/2026 | AP10: =WEEKNUM(B10)-WEEKNUM(EOMONTH(B10,-1)+1)+1 -> 2 | AQ10: =MONTH(R10)&"/"&YEAR(R10) -> 5/2026 | AR10: =WEEKNUM(R10)-WEEKNUM(EOMONTH(R10,-1)+1)+1 -> 5 | AS10: =IF(AW10="S",IF(Q10="1. Aceitou o programa",R10-B10,0),0) -> 0 | AT10: =IF(AW10="S",IF(AND(S10<>"",R10<>""),S10-R10,0),0) -> 0 | AU10: =IF(AW10="S",IF(Q10="1. Aceitou o programa",IF(OR(X10="Não se Aplica",X10=""),IF(OR(W10="Não se Aplica",W10=""),0,W10-V10),AVERAGE(X10-W10,W10-V10)),0),0) -> 0 | AV10: =IF(AW10="S",IF(AND(Q10="1. Aceitou o programa",AB10="Realizada"),IFERROR(IF(AA10="",0,AA10-R10),0),0),0) -> 0 | AW10: =_xlfn.XLOOKUP(W10,'Lista Suspensa'!$AA$20:$AA$23,'Lista Suspensa'!$AB$20:$AB$23,"N/A") -> N/A
A11: Não | B11: 46147 | C11: Transbordo/Navegação | D11: Captado pela Amil/Call Center | E11: 812979214 | F11: ANTONIA PINHEIRO MACHADO | G11: 12630875822 | H11: 25955 | I11: 55 | J11: F | K11: SP | L11: SAO PAULO | N11: NÍVEL 100 | O11: 11-965135667 | P11: ISMAEL | Q11: 1. Aceitou o programa | R11: 46171 | T11: Contato Com Sucesso | U11: Ativo | V11: 46161 | W11: 46171 | X11: Não se aplica | Z11: Agendada | AA11: 46181.569 | AB11: Realizada | AF11: 2,5 3,5 | AG11: 2.31 | AH11: Amil - Unidade Avançada Luz Butantã | AI11: Amil - Unidade Avançada Luz Butantã | AJ11: Confirmado | AL11: Sim | AM11: Sim | AN11: Anticoagulante | AO11: =MONTH(B11)&"/"&YEAR(B11) -> 5/2026 | AP11: =WEEKNUM(B11)-WEEKNUM(EOMONTH(B11,-1)+1)+1 -> 2 | AQ11: =MONTH(R11)&"/"&YEAR(R11) -> 5/2026 | AR11: =WEEKNUM(R11)-WEEKNUM(EOMONTH(R11,-1)+1)+1 -> 5 | AS11: =IF(AW11="S",IF(Q11="1. Aceitou o programa",R11-B11,0),0) -> 0 | AT11: =IF(AW11="S",IF(AND(S11<>"",R11<>""),S11-R11,0),0) -> 0 | AU11: =IF(AW11="S",IF(Q11="1. Aceitou o programa",IF(OR(X11="Não se Aplica",X11=""),IF(OR(W11="Não se Aplica",W11=""),0,W11-V11),AVERAGE(X11-W11,W11-V11)),0),0) -> 0 | AV11: =IF(AW11="S",IF(AND(Q11="1. Aceitou o programa",AB11="Realizada"),IFERROR(IF(AA11="",0,AA11-R11),0),0),0) -> 0 | AW11: =_xlfn.XLOOKUP(W11,'Lista Suspensa'!$AA$20:$AA$23,'Lista Suspensa'!$AB$20:$AB$23,"N/A") -> N/A
A12: Não | B12: 46147 | C12: Transbordo/Navegação | D12: Captado pela Amil/Call Center | E12: 94079415 | F12: PATRICIA MARIA DA SILVA | G12: 29917617841 | H12: 30015 | I12: 44 | J12: F | K12: SP | L12: SAO PAULO | N12: NÍVEL 110 | O12: 11-981105130 | P12: ISMAEL | Q12: 5. Alta por inelegibilidade | R12: 46171 | S12: 46181 | T12: Contato Com Sucesso | U12: Fora da Linha | V12: 46161 | W12: 46171 | X12: Não se aplica | Z12: Agendada | AA12: 46181.417 | AB12: Realizada | AJ12: Negativo | AL12: Desflagado | AN12: Anticoagulante | AO12: =MONTH(B12)&"/"&YEAR(B12) -> 5/2026 | AP12: =WEEKNUM(B12)-WEEKNUM(EOMONTH(B12,-1)+1)+1 -> 2 | AQ12: =MONTH(R12)&"/"&YEAR(R12) -> 5/2026 | AR12: =WEEKNUM(R12)-WEEKNUM(EOMONTH(R12,-1)+1)+1 -> 5 | AS12: =IF(AW12="S",IF(Q12="1. Aceitou o programa",R12-B12,0),0) -> 0 | AT12: =IF(AW12="S",IF(AND(S12<>"",R12<>""),S12-R12,0),0) -> 0 | AU12: =IF(AW12="S",IF(Q12="1. Aceitou o programa",IF(OR(X12="Não se Aplica",X12=""),IF(OR(W12="Não se Aplica",W12=""),0,W12-V12),AVERAGE(X12-W12,W12-V12)),0),0) -> 0 | AV12: =IF(AW12="S",IF(AND(Q12="1. Aceitou o programa",AB12="Realizada"),IFERROR(IF(AA12="",0,AA12-R12),0),0),0) -> 0 | AW12: =_xlfn.XLOOKUP(W12,'Lista Suspensa'!$AA$20:$AA$23,'Lista Suspensa'!$AB$20:$AB$23,"N/A") -> N/A
A13: Não | B13: 46147 | C13: Transbordo/Navegação | D13: Captado pela Amil/Call Center | E13: 596340168 | F13: JOSE AILTON DA SILVA | G13: 53492030459 | H13: 23657 | I13: 61 | J13: M | K13: SP | L13: SAO PAULO | N13: NÍVEL 50 | O13: 11-985905292 | P13: ISMAEL | Q13: 1. Aceitou o programa | R13: 46171 | T13: Contato Com Sucesso | U13: Ativo | V13: 46161 | W13: 46171 | X13: Não se aplica | Z13: Agendada | AA13: 46179.569 | AB13: Realizada | AL13: Sim | AM13: Sim | AN13: Anticoagulante | AO13: =MONTH(B13)&"/"&YEAR(B13) -> 5/2026 | AP13: =WEEKNUM(B13)-WEEKNUM(EOMONTH(B13,-1)+1)+1 -> 2 | AQ13: =MONTH(R13)&"/"&YEAR(R13) -> 5/2026 | AR13: =WEEKNUM(R13)-WEEKNUM(EOMONTH(R13,-1)+1)+1 -> 5 | AS13: =IF(AW13="S",IF(Q13="1. Aceitou o programa",R13-B13,0),0) -> 0 | AT13: =IF(AW13="S",IF(AND(S13<>"",R13<>""),S13-R13,0),0) -> 0 | AU13: =IF(AW13="S",IF(Q13="1. Aceitou o programa",IF(OR(X13="Não se Aplica",X13=""),IF(OR(W13="Não se Aplica",W13=""),0,W13-V13),AVERAGE(X13-W13,W13-V13)),0),0) -> 0 | AV13: =IF(AW13="S",IF(AND(Q13="1. Aceitou o programa",AB13="Realizada"),IFERROR(IF(AA13="",0,AA13-R13),0),0),0) -> 0 | AW13: =_xlfn.XLOOKUP(W13,'Lista Suspensa'!$AA$20:$AA$23,'Lista Suspensa'!$AB$20:$AB$23,"N/A") -> N/A
A14: Não | B14: 46147 | C14: Transbordo/Navegação | D14: Captado pela Amil/Call Center | E14: 770743480 | F14: PEDRO GEROMIN | G14: 2229293834 | H14: 16130 | I14: 82 | J14: M | K14: SP | L14: SAO PAULO | N14: NÍVEL 300 | O14: 11-994883501 | P14: ISMAEL | Q14: 1. Aceitou o programa | R14: 46171 | T14: Contato Com Sucesso | U14: Ativo | V14: 46161 | W14: 46171 | X14: Não se aplica | Z14: Agendada | AA14: 46181.611 | AB14: Não realizada - Falta | AL14: Sim | AM14: Sim | AN14: Anticoagulante | AO14: =MONTH(B14)&"/"&YEAR(B14) -> 5/2026 | AP14: =WEEKNUM(B14)-WEEKNUM(EOMONTH(B14,-1)+1)+1 -> 2 | AQ14: =MONTH(R14)&"/"&YEAR(R14) -> 5/2026 | AR14: =WEEKNUM(R14)-WEEKNUM(EOMONTH(R14,-1)+1)+1 -> 5 | AS14: =IF(AW14="S",IF(Q14="1. Aceitou o programa",R14-B14,0),0) -> 0 | AT14: =IF(AW14="S",IF(AND(S14<>"",R14<>""),S14-R14,0),0) -> 0 | AU14: =IF(AW14="S",IF(Q14="1. Aceitou o programa",IF(OR(X14="Não se Aplica",X14=""),IF(OR(W14="Não se Aplica",W14=""),0,W14-V14),AVERAGE(X14-W14,W14-V14)),0),0) -> 0 | AV14: =IF(AW14="S",IF(AND(Q14="1. Aceitou o programa",AB14="Realizada"),IFERROR(IF(AA14="",0,AA14-R14),0),0),0) -> 0 | AW14: =_xlfn.XLOOKUP(W14,'Lista Suspensa'!$AA$20:$AA$23,'Lista Suspensa'!$AB$20:$AB$23,"N/A") -> N/A
A15: Não | B15: 46147 | C15: Transbordo/Navegação | D15: Captado pela Amil/Call Center | E15: 94126070 | F15: AMANDA CORDEIRO WILLWOHL | G15: 39910171805 | H15: 33546 | I15: 34 | J15: F | K15: SP | L15: SAO PAULO | N15: NÍVEL 110 | O15: 11-996807475 | P15: ISMAEL | Q15: 1. Aceitou o programa | R15: 46171 | T15: Contato Com Sucesso | U15: Ativo | V15: 46161 | W15: 46171 | X15: Não se aplica | Z15: Agendada | AA15: 46181.583 | AB15: Realizada | AD15: Baixa | AF15: 2,5 3,5 | AG15: 2.98 | AH15: Amil - Unidade Avançada Luz Butantã | AI15: Amil - Unidade Avançada Luz Butantã | AJ15: Confirmado | AL15: Sim | AM15: Sim | AN15: Anticoagulante | AO15: =MONTH(B15)&"/"&YEAR(B15) -> 5/2026 | AP15: =WEEKNUM(B15)-WEEKNUM(EOMONTH(B15,-1)+1)+1 -> 2 | AQ15: =MONTH(R15)&"/"&YEAR(R15) -> 5/2026 | AR15: =WEEKNUM(R15)-WEEKNUM(EOMONTH(R15,-1)+1)+1 -> 5 | AS15: =IF(AW15="S",IF(Q15="1. Aceitou o programa",R15-B15,0),0) -> 0 | AT15: =IF(AW15="S",IF(AND(S15<>"",R15<>""),S15-R15,0),0) -> 0 | AU15: =IF(AW15="S",IF(Q15="1. Aceitou o programa",IF(OR(X15="Não se Aplica",X15=""),IF(OR(W15="Não se Aplica",W15=""),0,W15-V15),AVERAGE(X15-W15,W15-V15)),0),0) -> 0 | AV15: =IF(AW15="S",IF(AND(Q15="1. Aceitou o programa",AB15="Realizada"),IFERROR(IF(AA15="",0,AA15-R15),0),0),0) -> 0 | AW15: =_xlfn.XLOOKUP(W15,'Lista Suspensa'!$AA$20:$AA$23,'Lista Suspensa'!$AB$20:$AB$23,"N/A") -> N/A
A16: Não | B16: 46147 | C16: Transbordo/Navegação | D16: Captado pela Amil/Call Center | E16: 89386945 | F16: LUIZ ROGERIO DE SOUZA | G16: 13310639819 | H16: 24889 | I16: 58 | J16: M | K16: SP | L16: SAO PAULO | N16: NÍVEL 380 | O16: 11-997884950 | P16: ISMAEL | Q16: 1. Aceitou o programa | R16: 46171 | T16: Contato Com Sucesso | U16: Ativo | V16: 46161 | W16: 46171 | Z16: Agendada | AA16: 46176.556 | AB16: Não realizada - Falta | AL16: Sim | AM16: Sim | AN16: Anticoagulante | AO16: =MONTH(B16)&"/"&YEAR(B16) -> 5/2026 | AP16: =WEEKNUM(B16)-WEEKNUM(EOMONTH(B16,-1)+1)+1 -> 2 | AQ16: =MONTH(R16)&"/"&YEAR(R16) -> 5/2026 | AR16: =WEEKNUM(R16)-WEEKNUM(EOMONTH(R16,-1)+1)+1 -> 5 | AS16: =IF(AW16="S",IF(Q16="1. Aceitou o programa",R16-B16,0),0) -> 0 | AT16: =IF(AW16="S",IF(AND(S16<>"",R16<>""),S16-R16,0),0) -> 0 | AU16: =IF(AW16="S",IF(Q16="1. Aceitou o programa",IF(OR(X16="Não se Aplica",X16=""),IF(OR(W16="Não se Aplica",W16=""),0,W16-V16),AVERAGE(X16-W16,W16-V16)),0),0) -> 0 | AV16: =IF(AW16="S",IF(AND(Q16="1. Aceitou o programa",AB16="Realizada"),IFERROR(IF(AA16="",0,AA16-R16),0),0),0) -> 0 | AW16: =_xlfn.XLOOKUP(W16,'Lista Suspensa'!$AA$20:$AA$23,'Lista Suspensa'!$AB$20:$AB$23,"N/A") -> N/A
A17: Não | B17: 46147 | C17: Transbordo/Navegação | D17: Captado pela Amil/Call Center | E17: 85107055 | F17: WAGNER RODRIGUES DOS REIS | G17: 9591597703 | H17: 30042 | I17: 44 | J17: M | K17: RJ | L17: SAO PAULO | N17: NÍVEL 380 | O17: 21-986108134 | P17: ISMAEL | Q17: 1. Aceitou o programa | R17: 46171 | T17: Contato Com Sucesso | U17: Ativo | V17: 46161 | W17: 46171 | X17: Não se aplica | Z17: Agendada | AA17: 46181.486 | AB17: Realizada | AD17: Baixa | AF17: 2,0 3,0 | AG17: N/A | AH17: Não Informou | AI17: Não Informou | AJ17: Confirmado | AL17: Sim | AM17: Sim | AN17: Anticoagulante | AO17: =MONTH(B17)&"/"&YEAR(B17) -> 5/2026 | AP17: =WEEKNUM(B17)-WEEKNUM(EOMONTH(B17,-1)+1)+1 -> 2 | AQ17: =MONTH(R17)&"/"&YEAR(R17) -> 5/2026 | AR17: =WEEKNUM(R17)-WEEKNUM(EOMONTH(R17,-1)+1)+1 -> 5 | AS17: =IF(AW17="S",IF(Q17="1. Aceitou o programa",R17-B17,0),0) -> 0 | AT17: =IF(AW17="S",IF(AND(S17<>"",R17<>""),S17-R17,0),0) -> 0 | AU17: =IF(AW17="S",IF(Q17="1. Aceitou o programa",IF(OR(X17="Não se Aplica",X17=""),IF(OR(W17="Não se Aplica",W17=""),0,W17-V17),AVERAGE(X17-W17,W17-V17)),0),0) -> 0 | AV17: =IF(AW17="S",IF(AND(Q17="1. Aceitou o programa",AB17="Realizada"),IFERROR(IF(AA17="",0,AA17-R17),0),0),0) -> 0 | AW17: =_xlfn.XLOOKUP(W17,'Lista Suspensa'!$AA$20:$AA$23,'Lista Suspensa'!$AB$20:$AB$23,"N/A") -> N/A
A18: Não | B18: 46147 | C18: Transbordo/Navegação | D18: Captado pela Amil/Call Center | E18: 83007610 | F18: CLAUDIA EVANGELISTA DE OLIVEIRA JORDAO | G18: 68781318715 | H18: 23956 | I18: 60 | J18: F | K18: RJ | L18: CACHOEIRAS DE MACACU | N18: NÍVEL 60 | O18: 21-981946076 | P18: ISMAEL | Q18: 1. Aceitou o programa | R18: 46149 | T18: Contato Com Sucesso | U18: Ativo | V18: 46149 | W18: Não se aplica | X18: Não se aplica | Z18: Agendada | AA18: 46156 | AB18: Realizada | AF18: 2.3 | AG18: 2.3 | AH18: CARDIOLOGISTA - CREDENCIADO ULTIMA CONSULTA HÁ 3 DIAS | AJ18: Confirmado | AL18: Sim | AM18: Sim | AN18: Anticoagulante | AO18: =MONTH(B18)&"/"&YEAR(B18) -> 5/2026 | AP18: =WEEKNUM(B18)-WEEKNUM(EOMONTH(B18,-1)+1)+1 -> 2 | AQ18: =MONTH(R18)&"/"&YEAR(R18) -> 5/2026 | AR18: =WEEKNUM(R18)-WEEKNUM(EOMONTH(R18,-1)+1)+1 -> 2 | AS18: =IF(AW18="S",IF(Q18="1. Aceitou o programa",R18-B18,0),0) -> 0 | AT18: =IF(AW18="S",IF(AND(S18<>"",R18<>""),S18-R18,0),0) -> 0 | AU18: =IF(AW18="S",IF(Q18="1. Aceitou o programa",IF(OR(X18="Não se Aplica",X18=""),IF(OR(W18="Não se Aplica",W18=""),0,W18-V18),AVERAGE(X18-W18,W18-V18)),0),0) -> 0 | AV18: =IF(AW18="S",IF(AND(Q18="1. Aceitou o programa",AB18="Realizada"),IFERROR(IF(AA18="",0,AA18-R18),0),0),0) -> 0 | AW18: =_xlfn.XLOOKUP(W18,'Lista Suspensa'!$AA$20:$AA$23,'Lista Suspensa'!$AB$20:$AB$23,"N/A") -> N/A
A19: Não | B19: 46147 | C19: Transbordo/Navegação | D19: Captado pela Amil/Call Center | E19: 78401806 | F19: CLAUDINEI DA SILVA FREITAS | G19: 18472517810 | H19: 28393 | I19: 48 | J19: M | K19: SP | L19: CARAPICUIBA | N19: NÍVEL 380 | O19: 11-967288344 | P19: ISMAEL | Q19: 1. Aceitou o programa | R19: 46149 | T19: Contato Com Sucesso | U19: Ativo | V19: 46149 | W19: Não se aplica | X19: Não se aplica | Z19: Agendada | AA19: 46156 | AB19: Realizada | AF19: 46125 | AG19: 46125 | AH19: CARDIOLOGIA - HOSP SAMARITANO | AJ19: Confirmado | AL19: Sim | AM19: Sim | AN19: Anticoagulante | AO19: =MONTH(B19)&"/"&YEAR(B19) -> 5/2026 | AP19: =WEEKNUM(B19)-WEEKNUM(EOMONTH(B19,-1)+1)+1 -> 2 | AQ19: =MONTH(R19)&"/"&YEAR(R19) -> 5/2026 | AR19: =WEEKNUM(R19)-WEEKNUM(EOMONTH(R19,-1)+1)+1 -> 2 | AS19: =IF(AW19="S",IF(Q19="1. Aceitou o programa",R19-B19,0),0) -> 0 | AT19: =IF(AW19="S",IF(AND(S19<>"",R19<>""),S19-R19,0),0) -> 0 | AU19: =IF(AW19="S",IF(Q19="1. Aceitou o programa",IF(OR(X19="Não se Aplica",X19=""),IF(OR(W19="Não se Aplica",W19=""),0,W19-V19),AVERAGE(X19-W19,W19-V19)),0),0) -> 0 | AV19: =IF(AW19="S",IF(AND(Q19="1. Aceitou o programa",AB19="Realizada"),IFERROR(IF(AA19="",0,AA19-R19),0),0),0) -> 0 | AW19: =_xlfn.XLOOKUP(W19,'Lista Suspensa'!$AA$20:$AA$23,'Lista Suspensa'!$AB$20:$AB$23,"N/A") -> N/A
A20: Sim | B20: 46147 | C20: Transbordo/Navegação | D20: Captado pela Amil/Call Center | E20: 94565113 | F20: CLAUDINEI CAVEQUIA | G20: 4044801878 | H20: 22928 | I20: 63 | J20: M | K20: SP | L20: CARAPICUIBA | N20: NÍVEL 60 | O20: 11-984696019 | P20: ISMAEL | Q20: 1. Aceitou o programa | R20: 46161 | T20: Contato Com Sucesso | U20: Ativo | V20: 46148 | W20: Não se aplica | X20: Não se aplica | Z20: Agendada | AA20: 46171 | AB20: Realizada | AF20: 2, - 3, | AG20: 1.41 | AL20: Sim | AM20: Sim | AN20: Anticoagulante | AO20: =MONTH(B20)&"/"&YEAR(B20) -> 5/2026 | AP20: =WEEKNUM(B20)-WEEKNUM(EOMONTH(B20,-1)+1)+1 -> 2 | AQ20: =MONTH(R20)&"/"&YEAR(R20) -> 5/2026 | AR20: =WEEKNUM(R20)-WEEKNUM(EOMONTH(R20,-1)+1)+1 -> 4 | AS20: =IF(AW20="S",IF(Q20="1. Aceitou o programa",R20-B20,0),0) -> 0 | AT20: =IF(AW20="S",IF(AND(S20<>"",R20<>""),S20-R20,0),0) -> 0 | AU20: =IF(AW20="S",IF(Q20="1. Aceitou o programa",IF(OR(X20="Não se Aplica",X20=""),IF(OR(W20="Não se Aplica",W20=""),0,W20-V20),AVERAGE(X20-W20,W20-V20)),0),0) -> 0 | AV20: =IF(AW20="S",IF(AND(Q20="1. Aceitou o programa",AB20="Realizada"),IFERROR(IF(AA20="",0,AA20-R20),0),0),0) -> 0 | AW20: =_xlfn.XLOOKUP(W20,'Lista Suspensa'!$AA$20:$AA$23,'Lista Suspensa'!$AB$20:$AB$23,"N/A") -> N/A
A21: Sim | B21: 46147 | C21: Transbordo/Navegação | D21: Captado pela Amil/Call Center | E21: 95663093 | F21: ANTONIO ANSELMO DOS SANTOS JUNIOR | G21: 26132772898 | H21: 28220 | I21: 49 | J21: M | K21: SP | L21: DIADEMA | N21: NÍVEL 60 | O21: 11-960344767 | P21: ISMAEL | Q21: 1. Aceitou o programa | R21: 46148 | T21: Contato Com Sucesso | U21: Ativo | V21: 46148 | W21: Não se aplica | X21: Não se aplica | Z21: Agendada | AA21: 46155 | AB21: Não realizada - Falta | AJ21: Confirmado | AL21: Sim | AM21: Sim | AN21: Anticoagulante | AO21: =MONTH(B21)&"/"&YEAR(B21) -> 5/2026 | AP21: =WEEKNUM(B21)-WEEKNUM(EOMONTH(B21,-1)+1)+1 -> 2 | AQ21: =MONTH(R21)&"/"&YEAR(R21) -> 5/2026 | AR21: =WEEKNUM(R21)-WEEKNUM(EOMONTH(R21,-1)+1)+1 -> 2 | AS21: =IF(AW21="S",IF(Q21="1. Aceitou o programa",R21-B21,0),0) -> 0 | AT21: =IF(AW21="S",IF(AND(S21<>"",R21<>""),S21-R21,0),0) -> 0 | AU21: =IF(AW21="S",IF(Q21="1. Aceitou o programa",IF(OR(X21="Não se Aplica",X21=""),IF(OR(W21="Não se Aplica",W21=""),0,W21-V21),AVERAGE(X21-W21,W21-V21)),0),0) -> 0 | AV21: =IF(AW21="S",IF(AND(Q21="1. Aceitou o programa",AB21="Realizada"),IFERROR(IF(AA21="",0,AA21-R21),0),0),0) -> 0 | AW21: =_xlfn.XLOOKUP(W21,'Lista Suspensa'!$AA$20:$AA$23,'Lista Suspensa'!$AB$20:$AB$23,"N/A") -> N/A
A22: Sim | B22: 46155 | C22: Captação + Navegação | D22: Casos Prioritário - E-mail | E22: 95618846 | F22: ANDERSON FERREIRA NEVES | G22: 31307844898 | H22: 30011 | I22: 44 | J22: M | K22: SP | L22: OSASCO | M22: PIRATININGA | N22: NÍVEL 110 | O22: 11947339050 | P22: ISMAEL | Q22: 1. Aceitou o programa | R22: 46161 | T22: Contato Com Sucesso | U22: Ativo | V22: 46161 | W22: Não se aplica | X22: Não se aplica | Z22: Agendada | AA22: 46170 | AB22: Realizada | AD22: Baixa | AF22: 1.8 | AG22: 1.8 | AH22: Não Informou | AJ22: Confirmado | AL22: Sim | AM22: Sim | AN22: Anticoagulante | AO22: =MONTH(B22)&"/"&YEAR(B22) -> 5/2026 | AP22: =WEEKNUM(B22)-WEEKNUM(EOMONTH(B22,-1)+1)+1 -> 3 | AQ22: =MONTH(R22)&"/"&YEAR(R22) -> 5/2026 | AR22: =WEEKNUM(R22)-WEEKNUM(EOMONTH(R22,-1)+1)+1 -> 4 | AS22: =IF(AW22="S",IF(Q22="1. Aceitou o programa",R22-B22,0),0) -> 0 | AT22: =IF(AW22="S",IF(AND(S22<>"",R22<>""),S22-R22,0),0) -> 0 | AU22: =IF(AW22="S",IF(Q22="1. Aceitou o programa",IF(OR(X22="Não se Aplica",X22=""),IF(OR(W22="Não se Aplica",W22=""),0,W22-V22),AVERAGE(X22-W22,W22-V22)),0),0) -> 0 | AV22: =IF(AW22="S",IF(AND(Q22="1. Aceitou o programa",AB22="Realizada"),IFERROR(IF(AA22="",0,AA22-R22),0),0),0) -> 0 | AW22: =_xlfn.XLOOKUP(W22,'Lista Suspensa'!$AA$20:$AA$23,'Lista Suspensa'!$AB$20:$AB$23,"N/A") -> N/A
A23: Não | B23: 46147 | C23: Transbordo/Navegação | D23: Captado pela Amil/Call Center | E23: 89678263 | F23: JENNIFFER KAROLAYNE SIMOES DE JESUS | G23: 15336198757 | H23: 36564 | I23: 26 | J23: F | K23: RJ | L23: DUQUE DE CAXIAS | N23: NÍVEL 120 | O23: 21-964703647 | P23: ISMAEL | Q23: 1. Aceitou o programa | R23: 46150 | T23: Contato Com Sucesso | U23: Ativo | V23: 46150 | W23: Não se aplica | X23: Não se aplica | Z23: Agendada | AA23: 46157 | AB23: Não realizada - Falta | AJ23: Confirmado | AL23: Sim | AM23: Sim | AN23: Anticoagulante | AO23: =MONTH(B23)&"/"&YEAR(B23) -> 5/2026 | AP23: =WEEKNUM(B23)-WEEKNUM(EOMONTH(B23,-1)+1)+1 -> 2 | AQ23: =MONTH(R23)&"/"&YEAR(R23) -> 5/2026 | AR23: =WEEKNUM(R23)-WEEKNUM(EOMONTH(R23,-1)+1)+1 -> 2 | AS23: =IF(AW23="S",IF(Q23="1. Aceitou o programa",R23-B23,0),0) -> 0 | AT23: =IF(AW23="S",IF(AND(S23<>"",R23<>""),S23-R23,0),0) -> 0 | AU23: =IF(AW23="S",IF(Q23="1. Aceitou o programa",IF(OR(X23="Não se Aplica",X23=""),IF(OR(W23="Não se Aplica",W23=""),0,W23-V23),AVERAGE(X23-W23,W23-V23)),0),0) -> 0 | AV23: =IF(AW23="S",IF(AND(Q23="1. Aceitou o programa",AB23="Realizada"),IFERROR(IF(AA23="",0,AA23-R23),0),0),0) -> 0 | AW23: =_xlfn.XLOOKUP(W23,'Lista Suspensa'!$AA$20:$AA$23,'Lista Suspensa'!$AB$20:$AB$23,"N/A") -> N/A
A24: Não | B24: 46147 | C24: Transbordo/Navegação | D24: Captado pela Amil/Call Center | E24: 94094307 | F24: JOSEFA MARCIA DE SOUZA CARVALHO AMORIM | G24: 7271761454 | H24: 32709 | I24: 36 | J24: F | K24: SP | L24: EMBU DAS ARTES | N24: NÍVEL 60 | O24: 11-961014338 | P24: ISMAEL | Q24: 1. Aceitou o programa | R24: 46150 | T24: Contato Com Sucesso | U24: Ativo | V24: 46150 | W24: Não se aplica | X24: Não se aplica | Z24: Agendada | AA24: 46157 | AB24: Realizada | AJ24: Confirmado | AL24: Sim | AM24: Sim | AN24: Anticoagulante | AO24: =MONTH(B24)&"/"&YEAR(B24) -> 5/2026 | AP24: =WEEKNUM(B24)-WEEKNUM(EOMONTH(B24,-1)+1)+1 -> 2 | AQ24: =MONTH(R24)&"/"&YEAR(R24) -> 5/2026 | AR24: =WEEKNUM(R24)-WEEKNUM(EOMONTH(R24,-1)+1)+1 -> 2 | AS24: =IF(AW24="S",IF(Q24="1. Aceitou o programa",R24-B24,0),0) -> 0 | AT24: =IF(AW24="S",IF(AND(S24<>"",R24<>""),S24-R24,0),0) -> 0 | AU24: =IF(AW24="S",IF(Q24="1. Aceitou o programa",IF(OR(X24="Não se Aplica",X24=""),IF(OR(W24="Não se Aplica",W24=""),0,W24-V24),AVERAGE(X24-W24,W24-V24)),0),0) -> 0 | AV24: =IF(AW24="S",IF(AND(Q24="1. Aceitou o programa",AB24="Realizada"),IFERROR(IF(AA24="",0,AA24-R24),0),0),0) -> 0 | AW24: =_xlfn.XLOOKUP(W24,'Lista Suspensa'!$AA$20:$AA$23,'Lista Suspensa'!$AB$20:$AB$23,"N/A") -> N/A
A25: Não | B25: 46147 | C25: Transbordo/Navegação | D25: Captado pela Amil/Call Center | E25: 89546544 | F25: JOCELIO DANTAS DANIEL | G25: 28462431824 | H25: 29150 | I25: 46 | J25: M | K25: SP | L25: EMBU DAS ARTES | N25: NÍVEL 80 | O25: 11-988627369 | P25: ISMAEL | Q25: 1. Aceitou o programa | R25: 46150 | T25: Contato Com Sucesso | U25: Ativo | V25: 46150 | W25: Não se aplica | X25: Não se aplica | Z25: Agendada | AA25: 46157 | AB25: Não realizada - Falta | AJ25: Confirmado | AL25: Sim | AM25: Sim | AN25: Anticoagulante | AO25: =MONTH(B25)&"/"&YEAR(B25) -> 5/2026 | AP25: =WEEKNUM(B25)-WEEKNUM(EOMONTH(B25,-1)+1)+1 -> 2 | AQ25: =MONTH(R25)&"/"&YEAR(R25) -> 5/2026 | AR25: =WEEKNUM(R25)-WEEKNUM(EOMONTH(R25,-1)+1)+1 -> 2 | AS25: =IF(AW25="S",IF(Q25="1. Aceitou o programa",R25-B25,0),0) -> 0 | AT25: =IF(AW25="S",IF(AND(S25<>"",R25<>""),S25-R25,0),0) -> 0 | AU25: =IF(AW25="S",IF(Q25="1. Aceitou o programa",IF(OR(X25="Não se Aplica",X25=""),IF(OR(W25="Não se Aplica",W25=""),0,W25-V25),AVERAGE(X25-W25,W25-V25)),0),0) -> 0 | AV25: =IF(AW25="S",IF(AND(Q25="1. Aceitou o programa",AB25="Realizada"),IFERROR(IF(AA25="",0,AA25-R25),0),0),0) -> 0 | AW25: =_xlfn.XLOOKUP(W25,'Lista Suspensa'!$AA$20:$AA$23,'Lista Suspensa'!$AB$20:$AB$23,"N/A") -> N/A
A26: Não | B26: 46147 | C26: Transbordo/Navegação | D26: Captado pela Amil/Call Center | E26: 89375027 | F26: LEANDRO KUNRT | G26: 42347573810 | H26: 32433 | I26: 37 | J26: M | K26: SP | L26: FERRAZ DE VASCONCELOS | N26: NÍVEL 380 | O26: 11-989190044 | P26: ISMAEL | Q26: 1. Aceitou o programa | R26: 46150 | T26: Contato Com Sucesso | U26: Ativo | V26: 46150 | W26: Não se aplica | X26: Não se aplica | Z26: Agendada | AA26: 46157 | AB26: Não realizada - Falta | AJ26: Confirmado | AL26: Sim | AM26: Sim | AN26: Anticoagulante | AO26: =MONTH(B26)&"/"&YEAR(B26) -> 5/2026 | AP26: =WEEKNUM(B26)-WEEKNUM(EOMONTH(B26,-1)+1)+1 -> 2 | AQ26: =MONTH(R26)&"/"&YEAR(R26) -> 5/2026 | AR26: =WEEKNUM(R26)-WEEKNUM(EOMONTH(R26,-1)+1)+1 -> 2 | AS26: =IF(AW26="S",IF(Q26="1. Aceitou o programa",R26-B26,0),0) -> 0 | AT26: =IF(AW26="S",IF(AND(S26<>"",R26<>""),S26-R26,0),0) -> 0 | AU26: =IF(AW26="S",IF(Q26="1. Aceitou o programa",IF(OR(X26="Não se Aplica",X26=""),IF(OR(W26="Não se Aplica",W26=""),0,W26-V26),AVERAGE(X26-W26,W26-V26)),0),0) -> 0 | AV26: =IF(AW26="S",IF(AND(Q26="1. Aceitou o programa",AB26="Realizada"),IFERROR(IF(AA26="",0,AA26-R26),0),0),0) -> 0 | AW26: =_xlfn.XLOOKUP(W26,'Lista Suspensa'!$AA$20:$AA$23,'Lista Suspensa'!$AB$20:$AB$23,"N/A") -> N/A
A27: Não | B27: 46147 | C27: Transbordo/Navegação | D27: Captado pela Amil/Call Center | E27: 594217326 | F27: MARCIA RODRIGUES DE JESUS SIDO | G27: 8688603871 | H27: 24246 | I27: 60 | J27: F | K27: SP | L27: GUARULHOS | N27: NÍVEL 50 | O27: 11-912753132 | P27: ISMAEL | Q27: 1. Aceitou o programa | R27: 46161 | T27: Contato Com Sucesso | U27: Ativo | V27: 46150 | W27: Não se aplica | X27: Não se aplica | Z27: Agendada | AA27: 46170 | AB27: Não realizada - Falta | AL27: Sim | AM27: Sim | AN27: Anticoagulante | AO27: =MONTH(B27)&"/"&YEAR(B27) -> 5/2026 | AP27: =WEEKNUM(B27)-WEEKNUM(EOMONTH(B27,-1)+1)+1 -> 2 | AQ27: =MONTH(R27)&"/"&YEAR(R27) -> 5/2026 | AR27: =WEEKNUM(R27)-WEEKNUM(EOMONTH(R27,-1)+1)+1 -> 4 | AS27: =IF(AW27="S",IF(Q27="1. Aceitou o programa",R27-B27,0),0) -> 0 | AT27: =IF(AW27="S",IF(AND(S27<>"",R27<>""),S27-R27,0),0) -> 0 | AU27: =IF(AW27="S",IF(Q27="1. Aceitou o programa",IF(OR(X27="Não se Aplica",X27=""),IF(OR(W27="Não se Aplica",W27=""),0,W27-V27),AVERAGE(X27-W27,W27-V27)),0),0) -> 0 | AV27: =IF(AW27="S",IF(AND(Q27="1. Aceitou o programa",AB27="Realizada"),IFERROR(IF(AA27="",0,AA27-R27),0),0),0) -> 0 | AW27: =_xlfn.XLOOKUP(W27,'Lista Suspensa'!$AA$20:$AA$23,'Lista Suspensa'!$AB$20:$AB$23,"N/A") -> N/A
A28: Não | B28: 46147 | C28: Transbordo/Navegação | D28: Captado pela Amil/Call Center | E28: 92925523 | F28: THAMIRES RODRIGUES CAVALCANTI DA SILVA | G28: 39146124870 | H28: 33486 | I28: 34 | J28: F | K28: SP | L28: GUARULHOS | N28: NÍVEL 60 | O28: 11-965379441 | P28: ISMAEL | Q28: 1. Aceitou o programa | R28: 46161 | T28: Contato Com Sucesso | U28: Ativo | V28: 46150 | W28: Não se aplica | X28: Não se aplica | Z28: Agendada | AA28: 46169 | AB28: Realizada | AC28: 46178.597 | AL28: Sim | AM28: Sim | AN28: Anticoagulante | AO28: =MONTH(B28)&"/"&YEAR(B28) -> 5/2026 | AP28: =WEEKNUM(B28)-WEEKNUM(EOMONTH(B28,-1)+1)+1 -> 2 | AQ28: =MONTH(R28)&"/"&YEAR(R28) -> 5/2026 | AR28: =WEEKNUM(R28)-WEEKNUM(EOMONTH(R28,-1)+1)+1 -> 4 | AS28: =IF(AW28="S",IF(Q28="1. Aceitou o programa",R28-B28,0),0) -> 0 | AT28: =IF(AW28="S",IF(AND(S28<>"",R28<>""),S28-R28,0),0) -> 0 | AU28: =IF(AW28="S",IF(Q28="1. Aceitou o programa",IF(OR(X28="Não se Aplica",X28=""),IF(OR(W28="Não se Aplica",W28=""),0,W28-V28),AVERAGE(X28-W28,W28-V28)),0),0) -> 0 | AV28: =IF(AW28="S",IF(AND(Q28="1. Aceitou o programa",AB28="Realizada"),IFERROR(IF(AA28="",0,AA28-R28),0),0),0) -> 0 | AW28: =_xlfn.XLOOKUP(W28,'Lista Suspensa'!$AA$20:$AA$23,'Lista Suspensa'!$AB$20:$AB$23,"N/A") -> N/A
A29: Não | B29: 46147 | C29: Transbordo/Navegação | D29: Captado pela Amil/Call Center | E29: 779795792 | F29: GENERINA SOUSA LEAL | G29: 11121949835 | H29: 24741 | I29: 58 | J29: F | K29: SP | L29: GUARULHOS | N29: NÍVEL 400 | O29: 11-981729598 | P29: ISMAEL | Q29: 1. Aceitou o programa | R29: 46150 | T29: Contato Com Sucesso | U29: Ativo | V29: 46150 | W29: Não se aplica | X29: Não se aplica | Z29: Agendada | AA29: 46157 | AB29: Não realizada - Falta | AJ29: Confirmado | AL29: Sim | AM29: Sim | AN29: Anticoagulante | AO29: =MONTH(B29)&"/"&YEAR(B29) -> 5/2026 | AP29: =WEEKNUM(B29)-WEEKNUM(EOMONTH(B29,-1)+1)+1 -> 2 | AQ29: =MONTH(R29)&"/"&YEAR(R29) -> 5/2026 | AR29: =WEEKNUM(R29)-WEEKNUM(EOMONTH(R29,-1)+1)+1 -> 2 | AS29: =IF(AW29="S",IF(Q29="1. Aceitou o programa",R29-B29,0),0) -> 0 | AT29: =IF(AW29="S",IF(AND(S29<>"",R29<>""),S29-R29,0),0) -> 0 | AU29: =IF(AW29="S",IF(Q29="1. Aceitou o programa",IF(OR(X29="Não se Aplica",X29=""),IF(OR(W29="Não se Aplica",W29=""),0,W29-V29),AVERAGE(X29-W29,W29-V29)),0),0) -> 0 | AV29: =IF(AW29="S",IF(AND(Q29="1. Aceitou o programa",AB29="Realizada"),IFERROR(IF(AA29="",0,AA29-R29),0),0),0) -> 0 | AW29: =_xlfn.XLOOKUP(W29,'Lista Suspensa'!$AA$20:$AA$23,'Lista Suspensa'!$AB$20:$AB$23,"N/A") -> N/A
A30: Não | B30: 46147 | C30: Transbordo/Navegação | D30: Captado pela Amil/Call Center | E30: 96630691 | F30: FABIANA ARAUJO MOREIRA COELHO | G30: 9971591464 | H30: 33835 | I30: 33 | J30: F | K30: SP | L30: GUARULHOS | N30: NÍVEL 60 | O30: 11-992417387 | P30: ISMAEL | Q30: 1. Aceitou o programa | R30: 46150 | T30: Contato Com Sucesso | U30: Ativo | V30: 46150 | W30: Não se aplica | X30: Não se aplica | Z30: Agendada | AA30: 46157 | AB30: Realizada | AJ30: Confirmado | AL30: Sim | AM30: Sim | AN30: Anticoagulante | AO30: =MONTH(B30)&"/"&YEAR(B30) -> 5/2026 | AP30: =WEEKNUM(B30)-WEEKNUM(EOMONTH(B30,-1)+1)+1 -> 2 | AQ30: =MONTH(R30)&"/"&YEAR(R30) -> 5/2026 | AR30: =WEEKNUM(R30)-WEEKNUM(EOMONTH(R30,-1)+1)+1 -> 2 | AS30: =IF(AW30="S",IF(Q30="1. Aceitou o programa",R30-B30,0),0) -> 0 | AT30: =IF(AW30="S",IF(AND(S30<>"",R30<>""),S30-R30,0),0) -> 0 | AU30: =IF(AW30="S",IF(Q30="1. Aceitou o programa",IF(OR(X30="Não se Aplica",X30=""),IF(OR(W30="Não se Aplica",W30=""),0,W30-V30),AVERAGE(X30-W30,W30-V30)),0),0) -> 0 | AV30: =IF(AW30="S",IF(AND(Q30="1. Aceitou o programa",AB30="Realizada"),IFERROR(IF(AA30="",0,AA30-R30),0),0),0) -> 0 | AW30: =_xlfn.XLOOKUP(W30,'Lista Suspensa'!$AA$20:$AA$23,'Lista Suspensa'!$AB$20:$AB$23,"N/A") -> N/A
A31: Não | B31: 46147 | C31: Transbordo/Navegação | D31: Captado pela Amil/Call Center | E31: 094956702 | F31: Andreza Braga Luiz | G31: 29938784844 | H31: 28439 | I31: 48 | J31: F | K31: SP | L31: SAO PAULO | M31: JARAGUA | N31: 60 | O31: 11995016267 | P31: ISMAEL | Q31: 5. Alta por outros motivos | R31: 46161 | S31: 46178 | T31: Contato Com Sucesso | U31: Fora da Linha | V31: 46161 | W31: Não se aplica | X31: Não se aplica | Y31: CONTATO INCORRETO | Z31: Agendada | AA31: 46178 | AB31: Não realizada - Falta | AC31: 46178.653 | AL31: Desflagado | AM31: Sim | AN31: Anticoagulante | AO31: =MONTH(B31)&"/"&YEAR(B31) -> 5/2026 | AP31: =WEEKNUM(B31)-WEEKNUM(EOMONTH(B31,-1)+1)+1 -> 2 | AQ31: =MONTH(R31)&"/"&YEAR(R31) -> 5/2026 | AR31: =WEEKNUM(R31)-WEEKNUM(EOMONTH(R31,-1)+1)+1 -> 4 | AS31: =IF(AW31="S",IF(Q31="1. Aceitou o programa",R31-B31,0),0) -> 0 | AT31: =IF(AW31="S",IF(AND(S31<>"",R31<>""),S31-R31,0),0) -> 0 | AU31: =IF(AW31="S",IF(Q31="1. Aceitou o programa",IF(OR(X31="Não se Aplica",X31=""),IF(OR(W31="Não se Aplica",W31=""),0,W31-V31),AVERAGE(X31-W31,W31-V31)),0),0) -> 0 | AV31: =IF(AW31="S",IF(AND(Q31="1. Aceitou o programa",AB31="Realizada"),IFERROR(IF(AA31="",0,AA31-R31),0),0),0) -> 0 | AW31: =_xlfn.XLOOKUP(W31,'Lista Suspensa'!$AA$20:$AA$23,'Lista Suspensa'!$AB$20:$AB$23,"N/A") -> N/A
A32: Não | B32: 46147 | C32: Transbordo/Navegação | D32: Captado pela Amil/Call Center | E32: 92776986 | F32: JOSE CLAUDIO DE JESUS | G32: 6491505898 | H32: 23503 | I32: 62 | J32: M | K32: SP | L32: GUARULHOS | N32: NÍVEL 40 | O32: 11-998759859 | P32: ISMAEL | Q32: 1. Aceitou o programa | R32: 46150 | T32: Contato Com Sucesso | U32: Ativo | V32: 46150 | W32: Não se aplica | X32: Não se aplica | Z32: Agendada | AA32: 46157 | AB32: Não realizada - Falta | AJ32: Confirmado | AL32: Sim | AM32: Sim | AN32: Anticoagulante | AO32: =MONTH(B32)&"/"&YEAR(B32) -> 5/2026 | AP32: =WEEKNUM(B32)-WEEKNUM(EOMONTH(B32,-1)+1)+1 -> 2 | AQ32: =MONTH(R32)&"/"&YEAR(R32) -> 5/2026 | AR32: =WEEKNUM(R32)-WEEKNUM(EOMONTH(R32,-1)+1)+1 -> 2 | AS32: =IF(AW32="S",IF(Q32="1. Aceitou o programa",R32-B32,0),0) -> 0 | AT32: =IF(AW32="S",IF(AND(S32<>"",R32<>""),S32-R32,0),0) -> 0 | AU32: =IF(AW32="S",IF(Q32="1. Aceitou o programa",IF(OR(X32="Não se Aplica",X32=""),IF(OR(W32="Não se Aplica",W32=""),0,W32-V32),AVERAGE(X32-W32,W32-V32)),0),0) -> 0 | AV32: =IF(AW32="S",IF(AND(Q32="1. Aceitou o programa",AB32="Realizada"),IFERROR(IF(AA32="",0,AA32-R32),0),0),0) -> 0 | AW32: =_xlfn.XLOOKUP(W32,'Lista Suspensa'!$AA$20:$AA$23,'Lista Suspensa'!$AB$20:$AB$23,"N/A") -> N/A
A33: Não | B33: 46147 | C33: Transbordo/Navegação | D33: Captado pela Amil/Call Center | E33: 93576426 | F33: RITA BETANIA DINIZ PEREIRA | G33: 18758099883 | H33: 25934 | I33: 55 | J33: F | K33: SP | L33: GUARULHOS | N33: NÍVEL 110 | O33: 11959754352 | P33: ISMAEL | Q33: 1. Aceitou o programa | R33: 46170 | T33: Contato Com Sucesso | U33: Ativo | V33: 46154 | W33: 46161 | X33: 46171 | Z33: Agendada | AA33: 46148 | AB33: Realizada | AL33: Sim | AM33: Sim | AN33: Anticoagulante | AO33: =MONTH(B33)&"/"&YEAR(B33) -> 5/2026 | AP33: =WEEKNUM(B33)-WEEKNUM(EOMONTH(B33,-1)+1)+1 -> 2 | AQ33: =MONTH(R33)&"/"&YEAR(R33) -> 5/2026 | AR33: =WEEKNUM(R33)-WEEKNUM(EOMONTH(R33,-1)+1)+1 -> 5 | AS33: =IF(AW33="S",IF(Q33="1. Aceitou o programa",R33-B33,0),0) -> 0 | AT33: =IF(AW33="S",IF(AND(S33<>"",R33<>""),S33-R33,0),0) -> 0 | AU33: =IF(AW33="S",IF(Q33="1. Aceitou o programa",IF(OR(X33="Não se Aplica",X33=""),IF(OR(W33="Não se Aplica",W33=""),0,W33-V33),AVERAGE(X33-W33,W33-V33)),0),0) -> 0 | AV33: =IF(AW33="S",IF(AND(Q33="1. Aceitou o programa",AB33="Realizada"),IFERROR(IF(AA33="",0,AA33-R33),0),0),0) -> 0 | AW33: =_xlfn.XLOOKUP(W33,'Lista Suspensa'!$AA$20:$AA$23,'Lista Suspensa'!$AB$20:$AB$23,"N/A") -> N/A
A34: Não | B34: 46147 | C34: Transbordo/Navegação | D34: Captado pela Amil/Call Center | E34: 89367611 | F34: MARCELY CARDOSO BATISTA SANTOS | G34: 8992259506 | H34: 36675 | I34: 25 | J34: F | K34: SP | L34: ITAPEVI | N34: NÍVEL 60 | O34: 71-981997404 | P34: ISMAEL | Q34: 1. Aceitou o programa | R34: 46153 | T34: Contato Com Sucesso | U34: Ativo | V34: 46153 | W34: Não se aplica | X34: Não se aplica | Z34: Agendada | AA34: 46160 | AB34: Não realizada - Falta | AH34: Interno - Amil Geral | AJ34: Confirmado | AL34: Sim | AM34: Sim | AN34: Anticoagulante | AO34: =MONTH(B34)&"/"&YEAR(B34) -> 5/2026 | AP34: =WEEKNUM(B34)-WEEKNUM(EOMONTH(B34,-1)+1)+1 -> 2 | AQ34: =MONTH(R34)&"/"&YEAR(R34) -> 5/2026 | AR34: =WEEKNUM(R34)-WEEKNUM(EOMONTH(R34,-1)+1)+1 -> 3 | AS34: =IF(AW34="S",IF(Q34="1. Aceitou o programa",R34-B34,0),0) -> 0 | AT34: =IF(AW34="S",IF(AND(S34<>"",R34<>""),S34-R34,0),0) -> 0 | AU34: =IF(AW34="S",IF(Q34="1. Aceitou o programa",IF(OR(X34="Não se Aplica",X34=""),IF(OR(W34="Não se Aplica",W34=""),0,W34-V34),AVERAGE(X34-W34,W34-V34)),0),0) -> 0 | AV34: =IF(AW34="S",IF(AND(Q34="1. Aceitou o programa",AB34="Realizada"),IFERROR(IF(AA34="",0,AA34-R34),0),0),0) -> 0 | AW34: =_xlfn.XLOOKUP(W34,'Lista Suspensa'!$AA$20:$AA$23,'Lista Suspensa'!$AB$20:$AB$23,"N/A") -> N/A
A35: Não | B35: 46147 | C35: Transbordo/Navegação | D35: Captado pela Amil/Call Center | E35: 81717396 | F35: NICOLAU CONCEICAO DOS SANTOS | G35: 50494899549 | H35: 25758 | I35: 55 | J35: M | K35: SP | L35: ITAQUAQUECETUBA | N35: NÍVEL 60 | O35: 11-984641752 | P35: ISMAEL | Q35: 1. Aceitou o programa | R35: 46154 | T35: Contato Com Sucesso | U35: Ativo | V35: 46153 | W35: 46154 | X35: Não se aplica | Z35: Agendada | AA35: 46161 | AB35: Realizada | AF35: 2.7 | AG35: 2.7 | AH35: Interno - Amil Geral | AJ35: Confirmado | AL35: Sim | AM35: Sim | AN35: Anticoagulante | AO35: =MONTH(B35)&"/"&YEAR(B35) -> 5/2026 | AP35: =WEEKNUM(B35)-WEEKNUM(EOMONTH(B35,-1)+1)+1 -> 2 | AQ35: =MONTH(R35)&"/"&YEAR(R35) -> 5/2026 | AR35: =WEEKNUM(R35)-WEEKNUM(EOMONTH(R35,-1)+1)+1 -> 3 | AS35: =IF(AW35="S",IF(Q35="1. Aceitou o programa",R35-B35,0),0) -> 0 | AT35: =IF(AW35="S",IF(AND(S35<>"",R35<>""),S35-R35,0),0) -> 0 | AU35: =IF(AW35="S",IF(Q35="1. Aceitou o programa",IF(OR(X35="Não se Aplica",X35=""),IF(OR(W35="Não se Aplica",W35=""),0,W35-V35),AVERAGE(X35-W35,W35-V35)),0),0) -> 0 | AV35: =IF(AW35="S",IF(AND(Q35="1. Aceitou o programa",AB35="Realizada"),IFERROR(IF(AA35="",0,AA35-R35),0),0),0) -> 0 | AW35: =_xlfn.XLOOKUP(W35,'Lista Suspensa'!$AA$20:$AA$23,'Lista Suspensa'!$AB$20:$AB$23,"N/A") -> N/A
A36: Não | B36: 46147 | C36: Transbordo/Navegação | D36: Captado pela Amil/Call Center | E36: 87268626 | F36: GLAUCIA MARTINS MAY SPENGLER | G36: 89063341920 | H36: 27380 | I36: 51 | J36: F | K36: SC | L36: JOINVILLE | N36: NÍVEL 350 | O36: 47988029375 | P36: ISMAEL | Q36: 1. Aceitou o programa | R36: 46153 | T36: Contato Com Sucesso | U36: Ativo | V36: 46153 | W36: Não se aplica | X36: Não se aplica | Z36: Agendada | AA36: 46154 | AB36: Realizada | AJ36: Confirmado | AL36: Sim | AM36: Sim | AN36: Anticoagulante | AO36: =MONTH(B36)&"/"&YEAR(B36) -> 5/2026 | AP36: =WEEKNUM(B36)-WEEKNUM(EOMONTH(B36,-1)+1)+1 -> 2 | AQ36: =MONTH(R36)&"/"&YEAR(R36) -> 5/2026 | AR36: =WEEKNUM(R36)-WEEKNUM(EOMONTH(R36,-1)+1)+1 -> 3 | AS36: =IF(AW36="S",IF(Q36="1. Aceitou o programa",R36-B36,0),0) -> 0 | AT36: =IF(AW36="S",IF(AND(S36<>"",R36<>""),S36-R36,0),0) -> 0 | AU36: =IF(AW36="S",IF(Q36="1. Aceitou o programa",IF(OR(X36="Não se Aplica",X36=""),IF(OR(W36="Não se Aplica",W36=""),0,W36-V36),AVERAGE(X36-W36,W36-V36)),0),0) -> 0 | AV36: =IF(AW36="S",IF(AND(Q36="1. Aceitou o programa",AB36="Realizada"),IFERROR(IF(AA36="",0,AA36-R36),0),0),0) -> 0 | AW36: =_xlfn.XLOOKUP(W36,'Lista Suspensa'!$AA$20:$AA$23,'Lista Suspensa'!$AB$20:$AB$23,"N/A") -> N/A
A37: Não | B37: 46147 | C37: Transbordo/Navegação | D37: Captado pela Amil/Call Center | E37: 87486978 | F37: GEOVANNA DE AQUINO CORDEIRO | G37: 50377921858 | H37: 36950 | I37: 25 | J37: F | K37: SP | L37: MAUA | N37: NÍVEL 110 | O37: 11-993213196 | P37: ISMAEL | Q37: 1. Aceitou o programa | R37: 46153 | T37: Contato Com Sucesso | U37: Ativo | V37: 46153 | W37: Não se aplica | X37: Não se aplica | Z37: Agendada | AA37: 46155 | AB37: Não realizada - Falta | AH37: Interno - Amil Geral | AJ37: Confirmado | AL37: Sim | AM37: Sim | AN37: Anticoagulante | AO37: =MONTH(B37)&"/"&YEAR(B37) -> 5/2026 | AP37: =WEEKNUM(B37)-WEEKNUM(EOMONTH(B37,-1)+1)+1 -> 2 | AQ37: =MONTH(R37)&"/"&YEAR(R37) -> 5/2026 | AR37: =WEEKNUM(R37)-WEEKNUM(EOMONTH(R37,-1)+1)+1 -> 3 | AS37: =IF(AW37="S",IF(Q37="1. Aceitou o programa",R37-B37,0),0) -> 0 | AT37: =IF(AW37="S",IF(AND(S37<>"",R37<>""),S37-R37,0),0) -> 0 | AU37: =IF(AW37="S",IF(Q37="1. Aceitou o programa",IF(OR(X37="Não se Aplica",X37=""),IF(OR(W37="Não se Aplica",W37=""),0,W37-V37),AVERAGE(X37-W37,W37-V37)),0),0) -> 0 | AV37: =IF(AW37="S",IF(AND(Q37="1. Aceitou o programa",AB37="Realizada"),IFERROR(IF(AA37="",0,AA37-R37),0),0),0) -> 0 | AW37: =_xlfn.XLOOKUP(W37,'Lista Suspensa'!$AA$20:$AA$23,'Lista Suspensa'!$AB$20:$AB$23,"N/A") -> N/A
A38: Não | B38: 46147 | C38: Transbordo/Navegação | D38: Captado pela Amil/Call Center | E38: 87861654 | F38: MARCELO DE SOUZA TAVEIRA | G38: 19427273720 | H38: 36603 | I38: 26 | J38: M | K38: RJ | L38: NOVA IGUAÇU | N38: NÍVEL 80 | O38: 21-969018694 | P38: ISMAEL | Q38: 1. Aceitou o programa | R38: 46153 | T38: Contato Com Sucesso | U38: Ativo | V38: 46153 | W38: Não se aplica | X38: Não se aplica | Z38: Agendada | AA38: 46155 | AB38: Não realizada - Falta | AH38: Interno - Amil Geral | AJ38: Confirmado | AL38: Sim | AM38: Sim | AN38: Anticoagulante | AO38: =MONTH(B38)&"/"&YEAR(B38) -> 5/2026 | AP38: =WEEKNUM(B38)-WEEKNUM(EOMONTH(B38,-1)+1)+1 -> 2 | AQ38: =MONTH(R38)&"/"&YEAR(R38) -> 5/2026 | AR38: =WEEKNUM(R38)-WEEKNUM(EOMONTH(R38,-1)+1)+1 -> 3 | AS38: =IF(AW38="S",IF(Q38="1. Aceitou o programa",R38-B38,0),0) -> 0 | AT38: =IF(AW38="S",IF(AND(S38<>"",R38<>""),S38-R38,0),0) -> 0 | AU38: =IF(AW38="S",IF(Q38="1. Aceitou o programa",IF(OR(X38="Não se Aplica",X38=""),IF(OR(W38="Não se Aplica",W38=""),0,W38-V38),AVERAGE(X38-W38,W38-V38)),0),0) -> 0 | AV38: =IF(AW38="S",IF(AND(Q38="1. Aceitou o programa",AB38="Realizada"),IFERROR(IF(AA38="",0,AA38-R38),0),0),0) -> 0 | AW38: =_xlfn.XLOOKUP(W38,'Lista Suspensa'!$AA$20:$AA$23,'Lista Suspensa'!$AB$20:$AB$23,"N/A") -> N/A
A39: Não | B39: 46147 | C39: Transbordo/Navegação | D39: Captado pela Amil/Call Center | E39: 94030876 | F39: ADRIANA DOS SANTOS NASCIMENTO DUARTE | G39: 11136276700 | H39: 31033 | I39: 41 | J39: F | K39: RJ | L39: NOVA IGUAÇU | N39: NÍVEL 500 | O39: 21-984151272 | P39: ISMAEL | Q39: 1. Aceitou o programa | R39: 46161 | T39: Contato Com Sucesso | U39: Ativo | V39: 46148 | W39: Não se aplica | X39: Não se aplica | Z39: Agendada | AA39: 46170 | AB39: Não realizada - Falta | AC39: 46180.569 | AL39: Sim | AM39: Sim | AN39: Anticoagulante | AO39: =MONTH(B39)&"/"&YEAR(B39) -> 5/2026 | AP39: =WEEKNUM(B39)-WEEKNUM(EOMONTH(B39,-1)+1)+1 -> 2 | AQ39: =MONTH(R39)&"/"&YEAR(R39) -> 5/2026 | AR39: =WEEKNUM(R39)-WEEKNUM(EOMONTH(R39,-1)+1)+1 -> 4 | AS39: =IF(AW39="S",IF(Q39="1. Aceitou o programa",R39-B39,0),0) -> 0 | AT39: =IF(AW39="S",IF(AND(S39<>"",R39<>""),S39-R39,0),0) -> 0 | AU39: =IF(AW39="S",IF(Q39="1. Aceitou o programa",IF(OR(X39="Não se Aplica",X39=""),IF(OR(W39="Não se Aplica",W39=""),0,W39-V39),AVERAGE(X39-W39,W39-V39)),0),0) -> 0 | AV39: =IF(AW39="S",IF(AND(Q39="1. Aceitou o programa",AB39="Realizada"),IFERROR(IF(AA39="",0,AA39-R39),0),0),0) -> 0 | AW39: =_xlfn.XLOOKUP(W39,'Lista Suspensa'!$AA$20:$AA$23,'Lista Suspensa'!$AB$20:$AB$23,"N/A") -> N/A
A40: Não | B40: 46147 | C40: Transbordo/Navegação | D40: Captado pela Amil/Call Center | E40: 84837845 | F40: MARIO LUIZ DE SOUZA | G40: 366306758 | H40: 24933 | I40: 58 | J40: M | K40: RJ | L40: NOVA IGUAÇU | N40: NÍVEL 80 | O40: 21-986068432 | P40: ISMAEL | Q40: 1. Aceitou o programa | R40: 46153 | T40: Contato Com Sucesso | U40: Ativo | V40: 46153 | W40: Não se aplica | X40: Não se aplica | Z40: Agendada | AA40: 46155 | AB40: Realizada | AF40: 2.49 | AG40: 2.49 | AH40: Interno - Amil Geral | AJ40: Confirmado | AL40: Sim | AM40: Sim | AN40: Anticoagulante | AO40: =MONTH(B40)&"/"&YEAR(B40) -> 5/2026 | AP40: =WEEKNUM(B40)-WEEKNUM(EOMONTH(B40,-1)+1)+1 -> 2 | AQ40: =MONTH(R40)&"/"&YEAR(R40) -> 5/2026 | AR40: =WEEKNUM(R40)-WEEKNUM(EOMONTH(R40,-1)+1)+1 -> 3 | AS40: =IF(AW40="S",IF(Q40="1. Aceitou o programa",R40-B40,0),0) -> 0 | AT40: =IF(AW40="S",IF(AND(S40<>"",R40<>""),S40-R40,0),0) -> 0 | AU40: =IF(AW40="S",IF(Q40="1. Aceitou o programa",IF(OR(X40="Não se Aplica",X40=""),IF(OR(W40="Não se Aplica",W40=""),0,W40-V40),AVERAGE(X40-W40,W40-V40)),0),0) -> 0 | AV40: =IF(AW40="S",IF(AND(Q40="1. Aceitou o programa",AB40="Realizada"),IFERROR(IF(AA40="",0,AA40-R40),0),0),0) -> 0 | AW40: =_xlfn.XLOOKUP(W40,'Lista Suspensa'!$AA$20:$AA$23,'Lista Suspensa'!$AB$20:$AB$23,"N/A") -> N/A
...

Sheet Análise
B2: Linha | C2: Anticoagulante
B3: Motivo Envio
B4: Situação Atual do Paciente | C4: Total
B6: Mês/Ano | C6: 46143 | D6: >> Inserir no formato Mês / Ano apenas - como 01/2026, 02/2026, etc.
B8: Início | C8: 46023
B9: Fim | C9: 46171
B11: CONTAGEM DE PACIENTES
B13: Status BNF Linha | C13: Semana | H13: Mês | K13: Parâmetros | L13: Semana | S13: Status BNF Linha | T13: Absoluto | U13: Percentual | W13: Parâmetros
C14: 1 | D14: 2 | E14: 3 | F14: 4 | G14: 5 | H14: Absoluto | I14: Percentual | L14: 1 | M14: 2 | N14: 3 | O14: 4 | P14: 5 | Q14: Mês | S14: 1. Aceitou o programa | T14: =COUNTIFS(Consolidado!$AN:$AN,IF(ISBLANK($C$2),"<>",$C$2),Consolidado!$Q:$Q,Análise!S14,Consolidado!$B:$B,"<="&Análise!$C$9,Consolidado!$B:$B,">="&Análise!$C$8,Consolidado!$C:$C,IF(ISBLANK($C$3),"<>",$C$3),Consolidado!$AW:$AW,"S") -> 3 | U14: =IFERROR(T14/$T$39,0) -> 0.6 | W14: Taxa de Captação | Y14: =IFERROR(T14/T39,0) -> 0.6
B15: 1. Aceitou o programa | C15: =COUNTIFS(Consolidado!$AP:$AP,Análise!C$14,Consolidado!$AO:$AO,Análise!$C$6,Consolidado!$AN:$AN,IF(ISBLANK($C$2),"<>",$C$2),Consolidado!$Q:$Q,Análise!$B15,Consolidado!$C:$C,IF(ISBLANK($C$3),"<>",$C$3),Consolidado!$AW:$AW,"S") -> 0 | D15: =COUNTIFS(Consolidado!$AP:$AP,Análise!D$14,Consolidado!$AO:$AO,Análise!$C$6,Consolidado!$AN:$AN,IF(ISBLANK($C$2),"<>",$C$2),Consolidado!$Q:$Q,Análise!$B15,Consolidado!$C:$C,IF(ISBLANK($C$3),"<>",$C$3),Consolidado!$AW:$AW,"S") -> 1 | E15: =COUNTIFS(Consolidado!$AP:$AP,Análise!E$14,Consolidado!$AO:$AO,Análise!$C$6,Consolidado!$AN:$AN,IF(ISBLANK($C$2),"<>",$C$2),Consolidado!$Q:$Q,Análise!$B15,Consolidado!$C:$C,IF(ISBLANK($C$3),"<>",$C$3),Consolidado!$AW:$AW,"S") -> 0 | F15: =COUNTIFS(Consolidado!$AP:$AP,Análise!F$14,Consolidado!$AO:$AO,Análise!$C$6,Consolidado!$AN:$AN,IF(ISBLANK($C$2),"<>",$C$2),Consolidado!$Q:$Q,Análise!$B15,Consolidado!$C:$C,IF(ISBLANK($C$3),"<>",$C$3),Consolidado!$AW:$AW,"S") -> 1 | G15: =COUNTIFS(Consolidado!$AP:$AP,Análise!G$14,Consolidado!$AO:$AO,Análise!$C$6,Consolidado!$AN:$AN,IF(ISBLANK($C$2),"<>",$C$2),Consolidado!$Q:$Q,Análise!$B15,Consolidado!$C:$C,IF(ISBLANK($C$3),"<>",$C$3),Consolidado!$AW:$AW,"S") -> 1 | H15: =SUM(C15:G15) -> 3 | I15: =+IFERROR(H15/$H$40,0) -> 0.6 | K15: Total | L15: =+C40 -> 0 | M15: =+D40 -> 1 | N15: =+E40 -> 0 | O15: =+F40 -> 3 | P15: =+G40 -> 1 | Q15: =+H40 -> 5 | S15: 2. Em avaliação para participar do programa | T15: =COUNTIFS(Consolidado!$AN:$AN,IF(ISBLANK($C$2),"<>",$C$2),Consolidado!$Q:$Q,Análise!S15,Consolidado!$B:$B,"<="&Análise!$C$9,Consolidado!$B:$B,">="&Análise!$C$8,Consolidado!$C:$C,IF(ISBLANK($C$3),"<>",$C$3),Consolidado!$AW:$AW,"S") -> 0 | U15: =IFERROR(T15/$T$39,0) -> 0 | W15: SLA Captação Médio | Y15: =IFERROR(SUMIFS(Consolidado!AS:AS,Consolidado!$AN:$AN,IF(ISBLANK($C$2),"<>",$C$2),Consolidado!$B:$B,"<="&Análise!$C$9,Consolidado!$B:$B,">="&Análise!$C$8,Consolidado!$C:$C,IF(ISBLANK($C$3),"<>",$C$3))/T14,0) -> 6.3333333
B16: 2. Em avaliação para participar do programa | C16: =COUNTIFS(Consolidado!$AP:$AP,Análise!C$14,Consolidado!$AO:$AO,Análise!$C$6,Consolidado!$AN:$AN,IF(ISBLANK($C$2),"<>",$C$2),Consolidado!$Q:$Q,Análise!$B16,Consolidado!$C:$C,IF(ISBLANK($C$3),"<>",$C$3),Consolidado!$AW:$AW,"S") -> 0 | D16: =COUNTIFS(Consolidado!$AP:$AP,Análise!D$14,Consolidado!$AO:$AO,Análise!$C$6,Consolidado!$AN:$AN,IF(ISBLANK($C$2),"<>",$C$2),Consolidado!$Q:$Q,Análise!$B16,Consolidado!$C:$C,IF(ISBLANK($C$3),"<>",$C$3),Consolidado!$AW:$AW,"S") -> 0 | E16: =COUNTIFS(Consolidado!$AP:$AP,Análise!E$14,Consolidado!$AO:$AO,Análise!$C$6,Consolidado!$AN:$AN,IF(ISBLANK($C$2),"<>",$C$2),Consolidado!$Q:$Q,Análise!$B16,Consolidado!$C:$C,IF(ISBLANK($C$3),"<>",$C$3),Consolidado!$AW:$AW,"S") -> 0 | F16: =COUNTIFS(Consolidado!$AP:$AP,Análise!F$14,Consolidado!$AO:$AO,Análise!$C$6,Consolidado!$AN:$AN,IF(ISBLANK($C$2),"<>",$C$2),Consolidado!$Q:$Q,Análise!$B16,Consolidado!$C:$C,IF(ISBLANK($C$3),"<>",$C$3),Consolidado!$AW:$AW,"S") -> 0 | G16: =COUNTIFS(Consolidado!$AP:$AP,Análise!G$14,Consolidado!$AO:$AO,Análise!$C$6,Consolidado!$AN:$AN,IF(ISBLANK($C$2),"<>",$C$2),Consolidado!$Q:$Q,Análise!$B16,Consolidado!$C:$C,IF(ISBLANK($C$3),"<>",$C$3),Consolidado!$AW:$AW,"S") -> 0 | H16: =SUM(C16:G16) -> 0 | I16: =+IFERROR(H16/$H$40,0) -> 0 | K16: 1. Aceitou o programa | L16: =+C15 -> 0 | M16: =+D15 -> 1 | N16: =+E15 -> 0 | O16: =+F15 -> 1 | P16: =+G15 -> 1 | Q16: =+H15 -> 3 | S16: 3. Recusa por conta da assinatura do termo | T16: =COUNTIFS(Consolidado!$AN:$AN,IF(ISBLANK($C$2),"<>",$C$2),Consolidado!$Q:$Q,Análise!S16,Consolidado!$B:$B,"<="&Análise!$C$9,Consolidado!$B:$B,">="&Análise!$C$8,Consolidado!$C:$C,IF(ISBLANK($C$3),"<>",$C$3),Consolidado!$AW:$AW,"S") -> 0 | U16: =IFERROR(T16/$T$39,0) -> 0 | W16: SLA Tent. Contato Médio | Y16: =IFERROR(SUMIFS(Consolidado!AU:AU,Consolidado!$AN:$AN,IF(ISBLANK($C$2),"<>",$C$2),Consolidado!$B:$B,"<="&Análise!$C$9,Consolidado!$B:$B,">="&Análise!$C$8,Consolidado!$C:$C,IF(ISBLANK($C$3),"<>",$C$3))/COUNTIFS(Consolidado!$AN:$AN,IF(ISBLANK($C$2),"<>",$C$2),Consolidado!$Q:$Q,S$14,Consolidado!$B:$B,"<="&Análise!$C$9,Consolidado!$B:$B,">="&Análise!$C$8,Consolidado!$C:$C,IF(ISBLANK($C$3),"<>",$C$3),Consolidado!$AU:$AU,"<>"&0),0) -> 0
B17: 3. Recusa por conta da assinatura do termo | C17: =COUNTIFS(Consolidado!$AP:$AP,Análise!C$14,Consolidado!$AO:$AO,Análise!$C$6,Consolidado!$AN:$AN,IF(ISBLANK($C$2),"<>",$C$2),Consolidado!$Q:$Q,Análise!$B17,Consolidado!$C:$C,IF(ISBLANK($C$3),"<>",$C$3),Consolidado!$AW:$AW,"S") -> 0 | D17: =COUNTIFS(Consolidado!$AP:$AP,Análise!D$14,Consolidado!$AO:$AO,Análise!$C$6,Consolidado!$AN:$AN,IF(ISBLANK($C$2),"<>",$C$2),Consolidado!$Q:$Q,Análise!$B17,Consolidado!$C:$C,IF(ISBLANK($C$3),"<>",$C$3),Consolidado!$AW:$AW,"S") -> 0 | E17: =COUNTIFS(Consolidado!$AP:$AP,Análise!E$14,Consolidado!$AO:$AO,Análise!$C$6,Consolidado!$AN:$AN,IF(ISBLANK($C$2),"<>",$C$2),Consolidado!$Q:$Q,Análise!$B17,Consolidado!$C:$C,IF(ISBLANK($C$3),"<>",$C$3),Consolidado!$AW:$AW,"S") -> 0 | F17: =COUNTIFS(Consolidado!$AP:$AP,Análise!F$14,Consolidado!$AO:$AO,Análise!$C$6,Consolidado!$AN:$AN,IF(ISBLANK($C$2),"<>",$C$2),Consolidado!$Q:$Q,Análise!$B17,Consolidado!$C:$C,IF(ISBLANK($C$3),"<>",$C$3),Consolidado!$AW:$AW,"S") -> 0 | G17: =COUNTIFS(Consolidado!$AP:$AP,Análise!G$14,Consolidado!$AO:$AO,Análise!$C$6,Consolidado!$AN:$AN,IF(ISBLANK($C$2),"<>",$C$2),Consolidado!$Q:$Q,Análise!$B17,Consolidado!$C:$C,IF(ISBLANK($C$3),"<>",$C$3),Consolidado!$AW:$AW,"S") -> 0 | H17: =SUM(C17:G17) -> 0 | I17: =+IFERROR(H17/$H$40,0) -> 0 | K17: Taxa de Captação | L17: =IFERROR(L16/L15,"") | M17: =IFERROR(M16/M15,"") -> 1 | N17: =IFERROR(N16/N15,"") | O17: =IFERROR(O16/O15,"") -> 0.33333333 | P17: =IFERROR(P16/P15,"") -> 1 | Q17: =IFERROR(Q16/Q15,"") -> 0.6 | S17: 3. Recusa por desconfiança do programa | T17: =COUNTIFS(Consolidado!$AN:$AN,IF(ISBLANK($C$2),"<>",$C$2),Consolidado!$Q:$Q,Análise!S17,Consolidado!$B:$B,"<="&Análise!$C$9,Consolidado!$B:$B,">="&Análise!$C$8,Consolidado!$C:$C,IF(ISBLANK($C$3),"<>",$C$3),Consolidado!$AW:$AW,"S") -> 0 | U17: =IFERROR(T17/$T$39,0) -> 0 | W17: SLA Consulta Médio | Y17: =IFERROR(SUMIFS(Consolidado!AV:AV,Consolidado!$AN:$AN,IF(ISBLANK($C$2),"<>",$C$2),Consolidado!$B:$B,"<="&Análise!$C$9,Consolidado!$B:$B,">="&Análise!$C$8,Consolidado!$C:$C,IF(ISBLANK($C$3),"<>",$C$3))/COUNTIFS(Consolidado!$AN:$AN,IF(ISBLANK($C$2),"<>",$C$2),Consolidado!$Q:$Q,S$14,Consolidado!$B:$B,"<="&Análise!$C$9,Consolidado!$B:$B,">="&Análise!$C$8,Consolidado!$C:$C,IF(ISBLANK($C$3),"<>",$C$3),Consolidado!$AV:$AV,"<>"&0),0) -> 5.5
