Workbook

Sheet Consolidado
A1: Prioridade no Contato? | B1: Data Envio Paciente | C1: Motivo Envio | D1: Origem | E1: MO | F1: Nome do paciente | G1: CPF | H1: Data de Nascimento | I1: Idade | J1: Genero | K1: Estado | L1: Município | M1: Bairro | N1: Nível de Rede | O1: Telefone atualizado | P1: Profissional | Q1: Status BNF Linha | R1: Data de Inclusão | S1: Data da Alta, Inatividade ou Recusa | T1: Status Do Contato | U1: Situação Atual Do Paciente | V1: Tentativa de Contato 1 | W1: Tentativa de Contato 2 | X1: Tentativa de Contato 3 | Y1: Observações Importantes | Z1: Status Pré Consulta Enfermagem | AA1: Data 1ª Consulta de Enfermagem | AB1: Status da 1ª Consulta Enfermagem | AC1: Se reagendado, sinalizar datas | AD1: Complexidade | AE1: Resultado da Escala | AF1: Local de Acomapanhamento inicial | AG1: Local de Acomapanhamento atual | AH1: Diagnostico Confirmado? | AI1: Direcionado ao Hub? | AJ1: Flag | AK1: Encaminhado p/ Consolidado? | AL1: Linha | AM1: Mês/Ano | AN1: Semana | AO1: Mês/Ano Inclusão | AP1: Semana Inclusão | AQ1: SLA Captação | AR1: SLA Exclusão | AS1: SLA Tent. Contatos | AT1: SLA Consulta | AU1: Ativo/Inativo
A2: Não | B2: 46104 | C2: Transbordo/Navegação | D2: Captado pela Amil/Call Center | E2: 474383024 | F2: CAROLINE ONORATO DA SILVA | G2: 36161775883 | H2: 31697 | J2: F | K2: SP | L2: GUARULHOS | M2: JARDIM ALVORADA | N2: NÍVEL 200 | O2: 11-997373120 | P2: Equiipe CMDP | Q2: 1. Aceitou o programa | R2: 46167 | T2: Contato Com Sucesso | U2: Ativo | V2: 46112 | W2: 46160 | X2: 46167 | Y2: contato com sucesso em 18/05 | Z2: Agendada | AA2: 09/06/2026 09:20 | AB2: agendada | AC2: pendente | AD2: pendente | AE2: pendente | AF2: pendente | AG2: Guarulhos | AH2: pendente | AJ2: Sim | AK2: Sim | AL2: Coluna | AM2: =MONTH(B2)&"/"&YEAR(B2) -> 3/2026 | AN2: =WEEKNUM(B2)-WEEKNUM(EOMONTH(B2,-1)+1)+1 -> 4 | AO2: =MONTH(R2)&"/"&YEAR(R2) -> 5/2026 | AP2: =WEEKNUM(R2)-WEEKNUM(EOMONTH(R2,-1)+1)+1 -> 5 | AQ2: =IF(AU2="S",IF(Q2="1. Aceitou o programa",R2-B2,0),0) -> 63 | AR2: =IF(AU2="S",IF(AND(S2<>"",R2<>""),S2-R2,0),0) -> 0 | AS2: =IF(AU2="S",IF(Q2="1. Aceitou o programa",IF(OR(X2="Não se Aplica",X2=""),IF(OR(W2="Não se Aplica",W2=""),0,W2-V2),AVERAGE(X2-W2,W2-V2)),0),0) -> 27.5 | AT2: =IF(AU2="S",IF(AND(Q2="1. Aceitou o programa",AB2="Realizada"),IFERROR(IF(AA2="",0,AA2-R2),0),0),0) -> 0 | AU2: =_xlfn.XLOOKUP(U2,'Lista Suspensa'!$AA$20:$AA$23,'Lista Suspensa'!$AB$20:$AB$23,"N/A") -> S
A3: Não | B3: 46104 | C3: Transbordo/Navegação | D3: Captado pela Amil/Call Center | E3: 449697347 | F3: ELIANE BACOS | G3: 76060730825 | H3: 19460 | J3: F | K3: SP | L3: MOGI DAS CRUZES | M3: VILA NATAL | N3: NÍVEL 300 | O3: 11-998275110 | P3: Equiipe CMDP | Q3: 1. Aceitou o programa | R3: 46167 | T3: Contato Com Sucesso | U3: Ativo | V3: 46112 | W3: 46160 | X3: 46167 | Y3: contato com sucesso em 19/05 | Z3: Agendada | AA3: 09/06/2026 09:40 | AB3: agendada | AC3: pendente | AD3: pendente | AE3: pendente | AF3: pendente | AG3: Mogi | AH3: pendente | AJ3: Sim | AK3: Sim | AL3: Coluna | AM3: =MONTH(B3)&"/"&YEAR(B3) -> 3/2026 | AN3: =WEEKNUM(B3)-WEEKNUM(EOMONTH(B3,-1)+1)+1 -> 4 | AO3: =MONTH(R3)&"/"&YEAR(R3) -> 5/2026 | AP3: =WEEKNUM(R3)-WEEKNUM(EOMONTH(R3,-1)+1)+1 -> 5 | AQ3: =IF(AU3="S",IF(Q3="1. Aceitou o programa",R3-B3,0),0) -> 63 | AR3: =IF(AU3="S",IF(AND(S3<>"",R3<>""),S3-R3,0),0) -> 0 | AS3: =IF(AU3="S",IF(Q3="1. Aceitou o programa",IF(OR(X3="Não se Aplica",X3=""),IF(OR(W3="Não se Aplica",W3=""),0,W3-V3),AVERAGE(X3-W3,W3-V3)),0),0) -> 27.5 | AT3: =IF(AU3="S",IF(AND(Q3="1. Aceitou o programa",AB3="Realizada"),IFERROR(IF(AA3="",0,AA3-R3),0),0),0) -> 0 | AU3: =_xlfn.XLOOKUP(U3,'Lista Suspensa'!$AA$20:$AA$23,'Lista Suspensa'!$AB$20:$AB$23,"N/A") -> S
A4: Não | B4: 46104 | C4: Transbordo/Navegação | D4: Captado pela Amil/Call Center | E4: 419633588 | F4: ELIZABETH SAMPAIO DO AMARAL | G4: 77316819715 | H4: 20856 | J4: F | K4: RJ | L4: MARICA | M4: CHACARAS DE INOA (INOA) | N4: NÍVEL 400 | O4: 21-982470329 | P4: Equiipe CMDP | Q4: 1. Aceitou o programa | R4: 46167 | T4: Contato Com Sucesso | U4: Ativo | V4: 46112 | W4: 46160 | X4: 46167 | Y4: contato com sucesso em 25/05 | Z4: Agendada | AA4: 09/06/2026 10:00 | AB4: agendada | AC4: pendente | AD4: pendente | AE4: pendente | AF4: pendente | AG4: Niteroi | AH4: pendente | AJ4: Sim | AK4: Sim | AL4: Coluna | AM4: =MONTH(B4)&"/"&YEAR(B4) -> 3/2026 | AN4: =WEEKNUM(B4)-WEEKNUM(EOMONTH(B4,-1)+1)+1 -> 4 | AO4: =MONTH(R4)&"/"&YEAR(R4) -> 5/2026 | AP4: =WEEKNUM(R4)-WEEKNUM(EOMONTH(R4,-1)+1)+1 -> 5 | AQ4: =IF(AU4="S",IF(Q4="1. Aceitou o programa",R4-B4,0),0) -> 63 | AR4: =IF(AU4="S",IF(AND(S4<>"",R4<>""),S4-R4,0),0) -> 0 | AS4: =IF(AU4="S",IF(Q4="1. Aceitou o programa",IF(OR(X4="Não se Aplica",X4=""),IF(OR(W4="Não se Aplica",W4=""),0,W4-V4),AVERAGE(X4-W4,W4-V4)),0),0) -> 27.5 | AT4: =IF(AU4="S",IF(AND(Q4="1. Aceitou o programa",AB4="Realizada"),IFERROR(IF(AA4="",0,AA4-R4),0),0),0) -> 0 | AU4: =_xlfn.XLOOKUP(U4,'Lista Suspensa'!$AA$20:$AA$23,'Lista Suspensa'!$AB$20:$AB$23,"N/A") -> S
A5: Não | B5: 46104 | C5: Transbordo/Navegação | D5: Captado pela Amil/Call Center | E5: 82943313 | F5: GERSON RODRIGUES CORDEIRO | G5: 36961965849 | H5: 17542 | J5: M | K5: SP | L5: SAO PAULO | M5: SANTANA | N5: NÍVEL 600 | O5: 11-984311301 | P5: Equiipe CMDP | Q5: 1. Aceitou o programa | R5: 46167 | T5: Contato Com Sucesso | U5: Ativo | V5: 46112 | W5: 46160 | X5: 46167 | Y5: contato com sucesso em 25/05 | Z5: Agendada | AA5: 09/06/2026 10:20 | AB5: agendada | AC5: pendente | AD5: pendente | AE5: pendente | AF5: pendente | AG5: luz | AH5: pendente | AJ5: Sim | AK5: Sim | AL5: Coluna | AM5: =MONTH(B5)&"/"&YEAR(B5) -> 3/2026 | AN5: =WEEKNUM(B5)-WEEKNUM(EOMONTH(B5,-1)+1)+1 -> 4 | AO5: =MONTH(R5)&"/"&YEAR(R5) -> 5/2026 | AP5: =WEEKNUM(R5)-WEEKNUM(EOMONTH(R5,-1)+1)+1 -> 5 | AQ5: =IF(AU5="S",IF(Q5="1. Aceitou o programa",R5-B5,0),0) -> 63 | AR5: =IF(AU5="S",IF(AND(S5<>"",R5<>""),S5-R5,0),0) -> 0 | AS5: =IF(AU5="S",IF(Q5="1. Aceitou o programa",IF(OR(X5="Não se Aplica",X5=""),IF(OR(W5="Não se Aplica",W5=""),0,W5-V5),AVERAGE(X5-W5,W5-V5)),0),0) -> 27.5 | AT5: =IF(AU5="S",IF(AND(Q5="1. Aceitou o programa",AB5="Realizada"),IFERROR(IF(AA5="",0,AA5-R5),0),0),0) -> 0 | AU5: =_xlfn.XLOOKUP(U5,'Lista Suspensa'!$AA$20:$AA$23,'Lista Suspensa'!$AB$20:$AB$23,"N/A") -> S
A6: Não | B6: 46104 | C6: Transbordo/Navegação | D6: Captado pela Amil/Call Center | E6: 200172425 | F6: IEDA YATIYO KUNITAKE UMINO | G6: 7277510852 | H6: 24513 | J6: F | K6: SP | L6: SAO PAULO | M6: PLANALTO PAULISTA | N6: NÍVEL 600 | O6: 11-995612853 | P6: Equiipe CMDP | Q6: 1. Aceitou o programa | R6: 46167 | T6: Contato Com Sucesso | U6: Ativo | V6: 46112 | W6: 46160 | X6: 46167 | Y6: contato com sucesso em 18/05 | Z6: Agendada | AA6: 09/06/2026 10:40 | AB6: agendada | AC6: pendente | AD6: pendente | AE6: pendente | AF6: pendente | AG6: Consultório particular | AH6: pendente | AJ6: Sim | AK6: Sim | AL6: Coluna | AM6: =MONTH(B6)&"/"&YEAR(B6) -> 3/2026 | AN6: =WEEKNUM(B6)-WEEKNUM(EOMONTH(B6,-1)+1)+1 -> 4 | AO6: =MONTH(R6)&"/"&YEAR(R6) -> 5/2026 | AP6: =WEEKNUM(R6)-WEEKNUM(EOMONTH(R6,-1)+1)+1 -> 5 | AQ6: =IF(AU6="S",IF(Q6="1. Aceitou o programa",R6-B6,0),0) -> 63 | AR6: =IF(AU6="S",IF(AND(S6<>"",R6<>""),S6-R6,0),0) -> 0 | AS6: =IF(AU6="S",IF(Q6="1. Aceitou o programa",IF(OR(X6="Não se Aplica",X6=""),IF(OR(W6="Não se Aplica",W6=""),0,W6-V6),AVERAGE(X6-W6,W6-V6)),0),0) -> 27.5 | AT6: =IF(AU6="S",IF(AND(Q6="1. Aceitou o programa",AB6="Realizada"),IFERROR(IF(AA6="",0,AA6-R6),0),0),0) -> 0 | AU6: =_xlfn.XLOOKUP(U6,'Lista Suspensa'!$AA$20:$AA$23,'Lista Suspensa'!$AB$20:$AB$23,"N/A") -> S
A7: Não | B7: 46104 | C7: Transbordo/Navegação | D7: Captado pela Amil/Call Center | E7: 754514749 | F7: LAURA MARIA DE ARAUJO | G7: 59842903753 | H7: 14676 | J7: F | K7: RJ | L7: RIO DE JANEIRO | M7: TIJUCA | N7: NÍVEL 100 | O7: 21-969967203 | P7: Equiipe CMDP | Q7: 1. Aceitou o programa | R7: 46167 | T7: Contato Com Sucesso | U7: Ativo | V7: 46113 | W7: 46160 | X7: 46167 | Y7: contato com sucesso em 25/05 | Z7: Agendada | AA7: 09/06/2026 11:00 | AB7: agendada | AC7: pendente | AD7: pendente | AE7: pendente | AF7: pendente | AG7: AMIL ESPAÇO SAÚDE - TIJUCA | AH7: pendente | AJ7: Sim | AK7: Sim | AL7: Coluna | AM7: =MONTH(B7)&"/"&YEAR(B7) -> 3/2026 | AN7: =WEEKNUM(B7)-WEEKNUM(EOMONTH(B7,-1)+1)+1 -> 4 | AO7: =MONTH(R7)&"/"&YEAR(R7) -> 5/2026 | AP7: =WEEKNUM(R7)-WEEKNUM(EOMONTH(R7,-1)+1)+1 -> 5 | AQ7: =IF(AU7="S",IF(Q7="1. Aceitou o programa",R7-B7,0),0) -> 63 | AR7: =IF(AU7="S",IF(AND(S7<>"",R7<>""),S7-R7,0),0) -> 0 | AS7: =IF(AU7="S",IF(Q7="1. Aceitou o programa",IF(OR(X7="Não se Aplica",X7=""),IF(OR(W7="Não se Aplica",W7=""),0,W7-V7),AVERAGE(X7-W7,W7-V7)),0),0) -> 27 | AT7: =IF(AU7="S",IF(AND(Q7="1. Aceitou o programa",AB7="Realizada"),IFERROR(IF(AA7="",0,AA7-R7),0),0),0) -> 0 | AU7: =_xlfn.XLOOKUP(U7,'Lista Suspensa'!$AA$20:$AA$23,'Lista Suspensa'!$AB$20:$AB$23,"N/A") -> S
A8: Não | B8: 46104 | C8: Transbordo/Navegação | D8: Captado pela Amil/Call Center | E8: 752969978 | F8: LILIA MARCIA BARBOSA FELIX | G8: 87305879720 | H8: 23271 | J8: F | K8: RJ | L8: SAO GONÇALO | M8: NEVES (NEVES) | N8: NÍVEL 100 | O8: 21-989298015 | P8: Equiipe CMDP | Q8: 1. Aceitou o programa | R8: 46167 | T8: Contato Com Sucesso | U8: Ativo | V8: 46113 | W8: 46160 | X8: 46167 | Y8: contato com sucesso em 18/05 | Z8: Agendada | AA8: 09/06/2026 11:20 | AB8: agendada | AC8: pendente | AD8: pendente | AE8: pendente | AF8: pendente | AG8: AMIL ESPAÇO SAÚDE - NITERÓI | AH8: pendente | AJ8: Sim | AK8: Sim | AL8: Coluna | AM8: =MONTH(B8)&"/"&YEAR(B8) -> 3/2026 | AN8: =WEEKNUM(B8)-WEEKNUM(EOMONTH(B8,-1)+1)+1 -> 4 | AO8: =MONTH(R8)&"/"&YEAR(R8) -> 5/2026 | AP8: =WEEKNUM(R8)-WEEKNUM(EOMONTH(R8,-1)+1)+1 -> 5 | AQ8: =IF(AU8="S",IF(Q8="1. Aceitou o programa",R8-B8,0),0) -> 63 | AR8: =IF(AU8="S",IF(AND(S8<>"",R8<>""),S8-R8,0),0) -> 0 | AS8: =IF(AU8="S",IF(Q8="1. Aceitou o programa",IF(OR(X8="Não se Aplica",X8=""),IF(OR(W8="Não se Aplica",W8=""),0,W8-V8),AVERAGE(X8-W8,W8-V8)),0),0) -> 27 | AT8: =IF(AU8="S",IF(AND(Q8="1. Aceitou o programa",AB8="Realizada"),IFERROR(IF(AA8="",0,AA8-R8),0),0),0) -> 0 | AU8: =_xlfn.XLOOKUP(U8,'Lista Suspensa'!$AA$20:$AA$23,'Lista Suspensa'!$AB$20:$AB$23,"N/A") -> S
A9: Não | B9: 46104 | C9: Transbordo/Navegação | D9: Captado pela Amil/Call Center | E9: 13051288 | F9: LILIAN CASTILHO GUIMARAES | G9: 312740727 | H9: 16495 | J9: F | K9: RJ | L9: RIO DE JANEIRO | M9: VILA ISABEL | N9: NÍVEL 400 | O9: 21-995195867 | P9: Equiipe CMDP | Q9: 1. Aceitou o programa | R9: 46167 | T9: Contato Com Sucesso | U9: Ativo | V9: 46113 | W9: 46160 | X9: 46167 | Y9: contato com sucesso em 25/05 | Z9: Agendada | AA9: 09/06/2026 11:40 | AB9: agendada | AC9: pendente | AD9: pendente | AE9: pendente | AF9: pendente | AG9: Tijuca | AH9: pendente | AJ9: Sim | AK9: Sim | AL9: Coluna | AM9: =MONTH(B9)&"/"&YEAR(B9) -> 3/2026 | AN9: =WEEKNUM(B9)-WEEKNUM(EOMONTH(B9,-1)+1)+1 -> 4 | AO9: =MONTH(R9)&"/"&YEAR(R9) -> 5/2026 | AP9: =WEEKNUM(R9)-WEEKNUM(EOMONTH(R9,-1)+1)+1 -> 5 | AQ9: =IF(AU9="S",IF(Q9="1. Aceitou o programa",R9-B9,0),0) -> 63 | AR9: =IF(AU9="S",IF(AND(S9<>"",R9<>""),S9-R9,0),0) -> 0 | AS9: =IF(AU9="S",IF(Q9="1. Aceitou o programa",IF(OR(X9="Não se Aplica",X9=""),IF(OR(W9="Não se Aplica",W9=""),0,W9-V9),AVERAGE(X9-W9,W9-V9)),0),0) -> 27 | AT9: =IF(AU9="S",IF(AND(Q9="1. Aceitou o programa",AB9="Realizada"),IFERROR(IF(AA9="",0,AA9-R9),0),0),0) -> 0 | AU9: =_xlfn.XLOOKUP(U9,'Lista Suspensa'!$AA$20:$AA$23,'Lista Suspensa'!$AB$20:$AB$23,"N/A") -> S
A10: Não | B10: 46104 | C10: Transbordo/Navegação | D10: Captado pela Amil/Call Center | E10: 753842173 | F10: LUCI BITTENCOURT DE SOUZA CHAVES | G10: 60592680720 | H10: 22151 | J10: F | K10: RJ | L10: RIO DE JANEIRO | M10: VILA VALQUEIRE | N10: NÍVEL 100 | O10: 21-988288714 | P10: Equiipe CMDP | Q10: 1. Aceitou o programa | R10: 46167 | T10: Contato Com Sucesso | U10: Ativo | V10: 46113 | W10: 46160 | X10: 46167 | Y10: contato com sucesso em 18/05 | Z10: Agendada | AA10: 09/06/2026 13:00 | AB10: agendada | AC10: pendente | AD10: pendente | AE10: pendente | AF10: pendente | AG10: CMDP | AH10: pendente | AJ10: Sim | AK10: Sim | AL10: Coluna | AM10: =MONTH(B10)&"/"&YEAR(B10) -> 3/2026 | AN10: =WEEKNUM(B10)-WEEKNUM(EOMONTH(B10,-1)+1)+1 -> 4 | AO10: =MONTH(R10)&"/"&YEAR(R10) -> 5/2026 | AP10: =WEEKNUM(R10)-WEEKNUM(EOMONTH(R10,-1)+1)+1 -> 5 | AQ10: =IF(AU10="S",IF(Q10="1. Aceitou o programa",R10-B10,0),0) -> 63 | AR10: =IF(AU10="S",IF(AND(S10<>"",R10<>""),S10-R10,0),0) -> 0 | AS10: =IF(AU10="S",IF(Q10="1. Aceitou o programa",IF(OR(X10="Não se Aplica",X10=""),IF(OR(W10="Não se Aplica",W10=""),0,W10-V10),AVERAGE(X10-W10,W10-V10)),0),0) -> 27 | AT10: =IF(AU10="S",IF(AND(Q10="1. Aceitou o programa",AB10="Realizada"),IFERROR(IF(AA10="",0,AA10-R10),0),0),0) -> 0 | AU10: =_xlfn.XLOOKUP(U10,'Lista Suspensa'!$AA$20:$AA$23,'Lista Suspensa'!$AB$20:$AB$23,"N/A") -> S
A11: Não | B11: 46104 | C11: Transbordo/Navegação | D11: Captado pela Amil/Call Center | E11: 758099894 | F11: MARCIA SILVA ALVARENGA DOS SANTOS | G11: 1156104726 | H11: 25789 | J11: F | K11: RJ | L11: RIO DE JANEIRO | M11: CASCADURA | N11: NÍVEL 100 | O11: 21-986930477 | P11: Equiipe CMDP | Q11: 1. Aceitou o programa | R11: 46167 | T11: Contato Com Sucesso | U11: Ativo | V11: 46113 | W11: 46160 | X11: 46167 | Y11: contato com sucesso em 25/05 | Z11: Agendada | AA11: 09/06/2026 13:20 | AB11: agendada | AC11: pendente | AD11: pendente | AE11: pendente | AF11: pendente | AG11: Amil Tijuca | AH11: pendente | AJ11: Sim | AK11: Sim | AL11: Coluna | AM11: =MONTH(B11)&"/"&YEAR(B11) -> 3/2026 | AN11: =WEEKNUM(B11)-WEEKNUM(EOMONTH(B11,-1)+1)+1 -> 4 | AO11: =MONTH(R11)&"/"&YEAR(R11) -> 5/2026 | AP11: =WEEKNUM(R11)-WEEKNUM(EOMONTH(R11,-1)+1)+1 -> 5 | AQ11: =IF(AU11="S",IF(Q11="1. Aceitou o programa",R11-B11,0),0) -> 63 | AR11: =IF(AU11="S",IF(AND(S11<>"",R11<>""),S11-R11,0),0) -> 0 | AS11: =IF(AU11="S",IF(Q11="1. Aceitou o programa",IF(OR(X11="Não se Aplica",X11=""),IF(OR(W11="Não se Aplica",W11=""),0,W11-V11),AVERAGE(X11-W11,W11-V11)),0),0) -> 27 | AT11: =IF(AU11="S",IF(AND(Q11="1. Aceitou o programa",AB11="Realizada"),IFERROR(IF(AA11="",0,AA11-R11),0),0),0) -> 0 | AU11: =_xlfn.XLOOKUP(U11,'Lista Suspensa'!$AA$20:$AA$23,'Lista Suspensa'!$AB$20:$AB$23,"N/A") -> S
A12: Não | B12: 46104 | C12: Transbordo/Navegação | D12: Captado pela Amil/Call Center | E12: 631115633 | F12: MARILDA AFONSO COSTA SANTOS | G12: 15251399839 | H12: 25939 | J12: F | K12: SP | L12: SAO PAULO | M12: JARDIM DO CAMPO | N12: NÍVEL 200 | O12: 11-979508070 | P12: Equiipe CMDP | Q12: 1. Aceitou o programa | R12: 46167 | T12: Contato Com Sucesso | U12: Ativo | V12: 46113 | W12: 46160 | X12: 46167 | Y12: contato com sucesso em 25/05 | Z12: Agendada | AA12: 10/06/2026 09:20 | AB12: agendada | AC12: pendente | AD12: pendente | AE12: pendente | AF12: pendente | AG12: Unidade avançada Vitória Tatuapé | AH12: pendente | AJ12: Sim | AK12: Sim | AL12: Coluna | AM12: =MONTH(B12)&"/"&YEAR(B12) -> 3/2026 | AN12: =WEEKNUM(B12)-WEEKNUM(EOMONTH(B12,-1)+1)+1 -> 4 | AO12: =MONTH(R12)&"/"&YEAR(R12) -> 5/2026 | AP12: =WEEKNUM(R12)-WEEKNUM(EOMONTH(R12,-1)+1)+1 -> 5 | AQ12: =IF(AU12="S",IF(Q12="1. Aceitou o programa",R12-B12,0),0) -> 63 | AR12: =IF(AU12="S",IF(AND(S12<>"",R12<>""),S12-R12,0),0) -> 0 | AS12: =IF(AU12="S",IF(Q12="1. Aceitou o programa",IF(OR(X12="Não se Aplica",X12=""),IF(OR(W12="Não se Aplica",W12=""),0,W12-V12),AVERAGE(X12-W12,W12-V12)),0),0) -> 27 | AT12: =IF(AU12="S",IF(AND(Q12="1. Aceitou o programa",AB12="Realizada"),IFERROR(IF(AA12="",0,AA12-R12),0),0),0) -> 0 | AU12: =_xlfn.XLOOKUP(U12,'Lista Suspensa'!$AA$20:$AA$23,'Lista Suspensa'!$AB$20:$AB$23,"N/A") -> S
A13: Não | B13: 46104 | C13: Transbordo/Navegação | D13: Captado pela Amil/Call Center | E13: 807239682 | F13: MARLUCIA VIEIRA MAGESTE SANTOS | G13: 337092621 | H13: 24634 | J13: F | K13: SP | L13: SAO PAULO | M13: JARDIM BELAURA | N13: NÍVEL 100 | O13: 11-967509643 | P13: Equiipe CMDP | Q13: 1. Aceitou o programa | R13: 46167 | T13: Contato Com Sucesso | U13: Ativo | V13: 46113 | W13: 46160 | X13: 46167 | Y13: contato com sucesso em 25/05 | Z13: Agendada | AA13: 10/06/2026 09:40 | AB13: agendada | AC13: pendente | AD13: pendente | AE13: pendente | AF13: pendente | AG13: Tijuca | AH13: pendente | AJ13: Sim | AK13: Sim | AL13: Coluna | AM13: =MONTH(B13)&"/"&YEAR(B13) -> 3/2026 | AN13: =WEEKNUM(B13)-WEEKNUM(EOMONTH(B13,-1)+1)+1 -> 4 | AO13: =MONTH(R13)&"/"&YEAR(R13) -> 5/2026 | AP13: =WEEKNUM(R13)-WEEKNUM(EOMONTH(R13,-1)+1)+1 -> 5 | AQ13: =IF(AU13="S",IF(Q13="1. Aceitou o programa",R13-B13,0),0) -> 63 | AR13: =IF(AU13="S",IF(AND(S13<>"",R13<>""),S13-R13,0),0) -> 0 | AS13: =IF(AU13="S",IF(Q13="1. Aceitou o programa",IF(OR(X13="Não se Aplica",X13=""),IF(OR(W13="Não se Aplica",W13=""),0,W13-V13),AVERAGE(X13-W13,W13-V13)),0),0) -> 27 | AT13: =IF(AU13="S",IF(AND(Q13="1. Aceitou o programa",AB13="Realizada"),IFERROR(IF(AA13="",0,AA13-R13),0),0),0) -> 0 | AU13: =_xlfn.XLOOKUP(U13,'Lista Suspensa'!$AA$20:$AA$23,'Lista Suspensa'!$AB$20:$AB$23,"N/A") -> S
... A18: Não | B18: 46104 | C18: Transbordo/Navegação | D18: Captado pela Amil/Call Center | E18: 94993405 | F18: KETTY BASAGLIA CARVALHO | G18: 31142297861 | H18: 29364 | J18: F | K18: SP | L18: SAO PAULO | M18: TATUAPE | N18: NÍVEL 60 | O18: 11-961613550 | P18: Equiipe CMDP | Q18: 1. Aceitou o programa | R18: 46167 | T18: Contato Com Sucesso | U18: Ativo | V18: 46114 | W18: 46160 | X18: 46167 | Y18: contato com sucesso em 25/05 | Z18: Agendada | AA18: 10/06/2026 11:20 | AB18: agendada | AC18: pendente | AD18: pendente | AE18: pendente | AF18: pendente | AG18: AMIL - UNIDADE AVANÇADA VITÓRIA | AH18: pendente | AJ18: Sim | AK18: Sim | AL18: Coluna | AM18: =MONTH(B18)&"/"&YEAR(B18) -> 3/2026 | AN18: =WEEKNUM(B18)-WEEKNUM(EOMONTH(B18,-1)+1)+1 -> 4 | AO18: =MONTH(R18)&"/"&YEAR(R18) -> 5/2026 | AP18: =WEEKNUM(R18)-WEEKNUM(EOMONTH(R18,-1)+1)+1 -> 5 | AQ18: =IF(AU18="S",IF(Q18="1. Aceitou o programa",R18-B18,0),0) -> 63 | AR18: =IF(AU18="S",IF(AND(S18<>"",R18<>""),S18-R18,0),0) -> 0 | AS18: =IF(AU18="S",IF(Q18="1. Aceitou o programa",IF(OR(X18="Não se Aplica",X18=""),IF(OR(W18="Não se Aplica",W18=""),0,W18-V18),AVERAGE(X18-W18,W18-V18)),0),0) -> 26.5 | AT18: =IF(AU18="S",IF(AND(Q18="1. Aceitou o programa",AB18="Realizada"),IFERROR(IF(AA18="",0,AA18-R18),0),0),0) -> 0 | AU18: =_xlfn.XLOOKUP(U18,'Lista Suspensa'!$AA$20:$AA$23,'Lista Suspensa'!$AB$20:$AB$23,"N/A") -> S
A19: Não | B19: 46104 | C19: Transbordo/Navegação | D19: Captado pela Amil/Call Center | E19: 87162980 | F19: ELAINE CRISTINA DA SILVA IWANCZUK | G19: 28459162800 | H19: 29323 | J19: F | K19: SP | L19: SAO PAULO | M19: PARQUE SEVILHA | N19: NÍVEL 200 | O19: 11-999345716 | P19: Equiipe CMDP | Q19: 1. Aceitou o programa | R19: 46167 | T19: Contato Com Sucesso | U19: Ativo | V19: 46114 | W19: 46160 | X19: 46167 | Z19: Agendada | AA19: 10/06/2026 11:40 | AB19: agendada | AC19: pendente | AD19: pendente | AE19: pendente | AF19: pendente | AG19: ASM - HOSPITAL SAMARITANO PAULISTA - AMBULATORIO | AH19: pendente | AJ19: Sim | AK19: Sim | AL19: Coluna | AM19: =MONTH(B19)&"/"&YEAR(B19) -> 3/2026 | AN19: =WEEKNUM(B19)-WEEKNUM(EOMONTH(B19,-1)+1)+1 -> 4 | AO19: =MONTH(R19)&"/"&YEAR(R19) -> 5/2026 | AP19: =WEEKNUM(R19)-WEEKNUM(EOMONTH(R19,-1)+1)+1 -> 5 | AQ19: =IF(AU19="S",IF(Q19="1. Aceitou o programa",R19-B19,0),0) -> 63 | AR19: =IF(AU19="S",IF(AND(S19<>"",R19<>""),S19-R19,0),0) -> 0 | AS19: =IF(AU19="S",IF(Q19="1. Aceitou o programa",IF(OR(X19="Não se Aplica",X19=""),IF(OR(W19="Não se Aplica",W19=""),0,W19-V19),AVERAGE(X19-W19,W19-V19)),0),0) -> 26.5 | AT19: =IF(AU19="S",IF(AND(Q19="1. Aceitou o programa",AB19="Realizada"),IFERROR(IF(AA19="",0,AA19-R19),0),0),0) -> 0 | AU19: =_xlfn.XLOOKUP(U19,'Lista Suspensa'!$AA$20:$AA$23,'Lista Suspensa'!$AB$20:$AB$23,"N/A") -> S
A20: Não | B20: 46104 | C20: Transbordo/Navegação | D20: Captado pela Amil/Call Center | E20: 92905616 | F20: VILMA LUCIA SOUZA ARES | G20: 7782174856 | H20: 23770 | J20: F | K20: SP | L20: SAO PAULO | M20: VILA CRUZEIRO | N20: NÍVEL 110 | O20: 11-952111281 | P20: Equiipe CMDP | Q20: 1. Aceitou o programa | R20: 46167 | T20: Contato Com Sucesso | U20: Ativo | V20: 46114 | W20: 46160 | X20: 46167 | Y20: contato com sucesso em 25/05 | Z20: Agendada | AA20: 10/06/2026 13:00 | AB20: agendada | AC20: pendente | AD20: pendente | AE20: pendente | AF20: pendente | AG20: Hospital da luz | AH20: pendente | AJ20: Sim | AK20: Sim | AL20: Coluna | AM20: =MONTH(B20)&"/"&YEAR(B20) -> 3/2026 | AN20: =WEEKNUM(B20)-WEEKNUM(EOMONTH(B20,-1)+1)+1 -> 4 | AO20: =MONTH(R20)&"/"&YEAR(R20) -> 5/2026 | AP20: =WEEKNUM(R20)-WEEKNUM(EOMONTH(R20,-1)+1)+1 -> 5 | AQ20: =IF(AU20="S",IF(Q20="1. Aceitou o programa",R20-B20,0),0) -> 63 | AR20: =IF(AU20="S",IF(AND(S20<>"",R20<>""),S20-R20,0),0) -> 0 | AS20: =IF(AU20="S",IF(Q20="1. Aceitou o programa",IF(OR(X20="Não se Aplica",X20=""),IF(OR(W20="Não se Aplica",W20=""),0,W20-V20),AVERAGE(X20-W20,W20-V20)),0),0) -> 26.5 | AT20: =IF(AU20="S",IF(AND(Q20="1. Aceitou o programa",AB20="Realizada"),IFERROR(IF(AA20="",0,AA20-R20),0),0),0) -> 0 | AU20: =_xlfn.XLOOKUP(U20,'Lista Suspensa'!$AA$20:$AA$23,'Lista Suspensa'!$AB$20:$AB$23,"N/A") -> S
A21: Não | B21: 46104 | C21: Transbordo/Navegação | D21: Captado pela Amil/Call Center | E21: 87878616 | F21: HENRIQUE SOUSA NERY | G21: 48010543829 | H21: 36252 | J21: M | K21: SP | L21: SAO PAULO | M21: RECANTO CAMPO BELO | N21: NÍVEL 60 | O21: 11-932733202 | P21: Equiipe CMDP | Q21: 1. Aceitou o programa | R21: 46167 | T21: Contato Com Sucesso | U21: Ativo | V21: 46114 | W21: 46160 | X21: 46167 | Y21: contato com sucesso em 25/05 | Z21: Agendada | AA21: 10/06/2026 13:20 | AB21: agendada | AC21: pendente | AD21: pendente | AE21: pendente | AF21: pendente | AG21: cubatão | AH21: pendente | AJ21: Sim | AK21: Sim | AL21: Coluna | AM21: =MONTH(B21)&"/"&YEAR(B21) -> 3/2026 | AN21: =WEEKNUM(B21)-WEEKNUM(EOMONTH(B21,-1)+1)+1 -> 4 | AO21: =MONTH(R21)&"/"&YEAR(R21) -> 5/2026 | AP21: =WEEKNUM(R21)-WEEKNUM(EOMONTH(R21,-1)+1)+1 -> 5 | AQ21: =IF(AU21="S",IF(Q21="1. Aceitou o programa",R21-B21,0),0) -> 63 | AR21: =IF(AU21="S",IF(AND(S21<>"",R21<>""),S21-R21,0),0) -> 0 | AS21: =IF(AU21="S",IF(Q21="1. Aceitou o programa",IF(OR(X21="Não se Aplica",X21=""),IF(OR(W21="Não se Aplica",W21=""),0,W21-V21),AVERAGE(X21-W21,W21-V21)),0),0) -> 26.5 | AT21: =IF(AU21="S",IF(AND(Q21="1. Aceitou o programa",AB21="Realizada"),IFERROR(IF(AA21="",0,AA21-R21),0),0),0) -> 0 | AU21: =_xlfn.XLOOKUP(U21,'Lista Suspensa'!$AA$20:$AA$23,'Lista Suspensa'!$AB$20:$AB$23,"N/A") -> S
A22: Não | B22: 46104 | C22: Transbordo/Navegação | D22: Captado pela Amil/Call Center | E22: 73769304 | F22: MARIVANI MENEGATT | G22: 84862220959 | H22: 27423 | J22: F | K22: SP | L22: SAO PAULO | M22: BELENZINHO | N22: NÍVEL 50 | O22: 11-995907274 | P22: Equiipe CMDP | Q22: 1. Aceitou o programa | R22: 46167 | T22: Contato Com Sucesso | U22: Ativo | V22: 46114 | W22: 46160 | X22: 46167 | Y22: contato com sucesso em 18/05 | Z22: Agendada | AA22: 11/06/2026 09:20 | AB22: agendada | AC22: pendente | AD22: pendente | AE22: pendente | AF22: pendente | AG22: unidade avançada vitoria | AH22: pendente | AJ22: Sim | AK22: Sim | AL22: Coluna | AM22: =MONTH(B22)&"/"&YEAR(B22) -> 3/2026 | AN22: =WEEKNUM(B22)-WEEKNUM(EOMONTH(B22,-1)+1)+1 -> 4 | AO22: =MONTH(R22)&"/"&YEAR(R22) -> 5/2026 | AP22: =WEEKNUM(R22)-WEEKNUM(EOMONTH(R22,-1)+1)+1 -> 5 | AQ22: =IF(AU22="S",IF(Q22="1. Aceitou o programa",R22-B22,0),0) -> 63 | AR22: =IF(AU22="S",IF(AND(S22<>"",R22<>""),S22-R22,0),0) -> 0 | AS22: =IF(AU22="S",IF(Q22="1. Aceitou o programa",IF(OR(X22="Não se Aplica",X22=""),IF(OR(W22="Não se Aplica",W22=""),0,W22-V22),AVERAGE(X22-W22,W22-V22)),0),0) -> 26.5 | AT22: =IF(AU22="S",IF(AND(Q22="1. Aceitou o programa",AB22="Realizada"),IFERROR(IF(AA22="",0,AA22-R22),0),0),0) -> 0 | AU22: =_xlfn.XLOOKUP(U22,'Lista Suspensa'!$AA$20:$AA$23,'Lista Suspensa'!$AB$20:$AB$23,"N/A") -> S
A23: Não | B23: 46104 | C23: Transbordo/Navegação | D23: Captado pela Amil/Call Center | E23: 73828294 | F23: ANDERSON ANDRE GARCIA ALVES | G23: 6957100790 | H23: 27395 | J23: M | K23: RJ | L23: RIO DE JANEIRO | M23: SANTA CRUZ | N23: NÍVEL 50 | O23: 21-985638916 | P23: Equiipe CMDP | Q23: 1. Aceitou o programa | R23: 46167 | T23: Contato Com Sucesso | U23: Ativo | V23: 46114 | W23: 46160 | X23: 46167 | Y23: contato com sucesso em 25/05 | Z23: Agendada | AA23: 11/06/2026 09:40 | AB23: agendada | AC23: pendente | AD23: pendente | AE23: pendente | AF23: pendente | AG23: AMIL ESPAÇO SAÚDE - CAMPO GRANDE | AH23: pendente | AJ23: Sim | AK23: Sim | AL23: Coluna | AM23: =MONTH(B23)&"/"&YEAR(B23) -> 3/2026 | AN23: =WEEKNUM(B23)-WEEKNUM(EOMONTH(B23,-1)+1)+1 -> 4 | AO23: =MONTH(R23)&"/"&YEAR(R23) -> 5/2026 | AP23: =WEEKNUM(R23)-WEEKNUM(EOMONTH(R23,-1)+1)+1 -> 5 | AQ23: =IF(AU23="S",IF(Q23="1. Aceitou o programa",R23-B23,0),0) -> 63 | AR23: =IF(AU23="S",IF(AND(S23<>"",R23<>""),S23-R23,0),0) -> 0 | AS23: =IF(AU23="S",IF(Q23="1. Aceitou o programa",IF(OR(X23="Não se Aplica",X23=""),IF(OR(W23="Não se Aplica",W23=""),0,W23-V23),AVERAGE(X23-W23,W23-V23)),0),0) -> 26.5 | AT23: =IF(AU23="S",IF(AND(Q23="1. Aceitou o programa",AB23="Realizada"),IFERROR(IF(AA23="",0,AA23-R23),0),0),0) -> 0 | AU23: =_xlfn.XLOOKUP(U23,'Lista Suspensa'!$AA$20:$AA$23,'Lista Suspensa'!$AB$20:$AB$23,"N/A") -> S
A24: Não | B24: 46104 | C24: Transbordo/Navegação | D24: Captado pela Amil/Call Center | E24: 84450691 | F24: AGNEZ PEREIRA DA CUNHA | G24: 15377219848 | H24: 26277 | J24: F | K24: SP | L24: GUARULHOS | M24: PARQUE CONTINENTAL I | N24: NÍVEL 60 | O24: 11-997589557 | P24: Equiipe CMDP | Q24: 1. Aceitou o programa | R24: 46167 | T24: Contato Com Sucesso | U24: Ativo | V24: 46114 | W24: 46160 | X24: 46167 | Y24: contato com sucesso em 25/05 | Z24: Agendada | AA24: 11/06/2026 10:00 | AB24: agendada | AC24: pendente | AD24: pendente | AE24: pendente | AF24: pendente | AG24: AMIL ESPAÇO SAÚDE - GUARULHOS | AH24: pendente | AJ24: Sim | AK24: Sim | AL24: Coluna | AM24: =MONTH(B24)&"/"&YEAR(B24) -> 3/2026 | AN24: =WEEKNUM(B24)-WEEKNUM(EOMONTH(B24,-1)+1)+1 -> 4 | AO24: =MONTH(R24)&"/"&YEAR(R24) -> 5/2026 | AP24: =WEEKNUM(R24)-WEEKNUM(EOMONTH(R24,-1)+1)+1 -> 5 | AQ24: =IF(AU24="S",IF(Q24="1. Aceitou o programa",R24-B24,0),0) -> 63 | AR24: =IF(AU24="S",IF(AND(S24<>"",R24<>""),S24-R24,0),0) -> 0 | AS24: =IF(AU24="S",IF(Q24="1. Aceitou o programa",IF(OR(X24="Não se Aplica",X24=""),IF(OR(W24="Não se Aplica",W24=""),0,W24-V24),AVERAGE(X24-W24,W24-V24)),0),0) -> 26.5 | AT24: =IF(AU24="S",IF(AND(Q24="1. Aceitou o programa",AB24="Realizada"),IFERROR(IF(AA24="",0,AA24-R24),0),0),0) -> 0 | AU24: =_xlfn.XLOOKUP(U24,'Lista Suspensa'!$AA$20:$AA$23,'Lista Suspensa'!$AB$20:$AB$23,"N/A") -> S
A25: Não | B25: 46104 | C25: Transbordo/Navegação | D25: Captado pela Amil/Call Center | E25: 76590612 | F25: ELSONEY SILVA SANTOS | G25: 70715483587 | H25: 27122 | J25: M | K25: SP | L25: SAO PAULO | M25: PARQUE BOA ESPERANÇA | N25: NÍVEL 50 | O25: 11-982863032 | P25: Equiipe CMDP | Q25: 1. Aceitou o programa | R25: 46167 | T25: Contato Com Sucesso | U25: Ativo | V25: 46114 | W25: 46160 | X25: 46167 | Y25: contato com sucesso em 25/05 | Z25: Agendada | AA25: 11/06/2026 10:20 | AB25: agendada | AC25: pendente | AD25: pendente | AE25: pendente | AF25: pendente | AG25: AMIL - UD CUBATAO SP - HOSPITAL DA LUZ | AH25: pendente | AJ25: Sim | AK25: Sim | AL25: Coluna | AM25: =MONTH(B25)&"/"&YEAR(B25) -> 3/2026 | AN25: =WEEKNUM(B25)-WEEKNUM(EOMONTH(B25,-1)+1)+1 -> 4 | AO25: =MONTH(R25)&"/"&YEAR(R25) -> 5/2026 | AP25: =WEEKNUM(R25)-WEEKNUM(EOMONTH(R25,-1)+1)+1 -> 5 | AQ25: =IF(AU25="S",IF(Q25="1. Aceitou o programa",R25-B25,0),0) -> 63 | AR25: =IF(AU25="S",IF(AND(S25<>"",R25<>""),S25-R25,0),0) -> 0 | AS25: =IF(AU25="S",IF(Q25="1. Aceitou o programa",IF(OR(X25="Não se Aplica",X25=""),IF(OR(W25="Não se Aplica",W25=""),0,W25-V25),AVERAGE(X25-W25,W25-V25)),0),0) -> 26.5 | AT25: =IF(AU25="S",IF(AND(Q25="1. Aceitou o programa",AB25="Realizada"),IFERROR(IF(AA25="",0,AA25-R25),0),0),0) -> 0 | AU25: =_xlfn.XLOOKUP(U25,'Lista Suspensa'!$AA$20:$AA$23,'Lista Suspensa'!$AB$20:$AB$23,"N/A") -> S
A26: Não | B26: 46104 | C26: Transbordo/Navegação | D26: Captado pela Amil/Call Center | E26: 83813404 | F26: IBERE RODRIGUES DE OLIVEIRA | G26: 483184187 | H26: 16373 | J26: M | K26: SP | L26: SAO PAULO | M26: CAMPO BELO | N26: NÍVEL 750 | O26: 11-999411770 | P26: Equiipe CMDP | Q26: 1. Aceitou o programa | R26: 46167 | T26: Contato Com Sucesso | U26: Ativo | V26: 46114 | W26: 46160 | X26: 46167 | Y26: contato com sucesso em 18/05 | Z26: Agendada | AA26: 11/06/2026 10:40 | AB26: agendada | AC26: pendente | AD26: pendente | AE26: pendente | AF26: pendente | AG26: Unidade Samaritano Paulista-SP | AH26: pendente | AJ26: Sim | AK26: Sim | AL26: Coluna | AM26: =MONTH(B26)&"/"&YEAR(B26) -> 3/2026 | AN26: =WEEKNUM(B26)-WEEKNUM(EOMONTH(B26,-1)+1)+1 -> 4 | AO26: =MONTH(R26)&"/"&YEAR(R26) -> 5/2026 | AP26: =WEEKNUM(R26)-WEEKNUM(EOMONTH(R26,-1)+1)+1 -> 5 | AQ26: =IF(AU26="S",IF(Q26="1. Aceitou o programa",R26-B26,0),0) -> 63 | AR26: =IF(AU26="S",IF(AND(S26<>"",R26<>""),S26-R26,0),0) -> 0 | AS26: =IF(AU26="S",IF(Q26="1. Aceitou o programa",IF(OR(X26="Não se Aplica",X26=""),IF(OR(W26="Não se Aplica",W26=""),0,W26-V26),AVERAGE(X26-W26,W26-V26)),0),0) -> 26.5 | AT26: =IF(AU26="S",IF(AND(Q26="1. Aceitou o programa",AB26="Realizada"),IFERROR(IF(AA26="",0,AA26-R26),0),0),0) -> 0 | AU26: =_xlfn.XLOOKUP(U26,'Lista Suspensa'!$AA$20:$AA$23,'Lista Suspensa'!$AB$20:$AB$23,"N/A") -> S
A27: Não | B27: 46104 | C27: Transbordo/Navegação | D27: Captado pela Amil/Call Center | E27: 76921125 | F27: VANIA DA COSTA CORREIA | G27: 1816367788 | H27: 26183 | J27: F | K27: RJ | L27: RIO DE JANEIRO | M27: SAO CRISTOVAO | N27: NÍVEL 50 | O27: 21-964168200 | P27: Equiipe CMDP | Q27: 1. Aceitou o programa | R27: 46167 | T27: Contato Com Sucesso | U27: Ativo | V27: 46118 | W27: 46160 | X27: 46167 | Y27: contato com sucesso em 25/05 | Z27: Agendada | AA27: 11/06/2026 11:00 | AB27: agendada | AC27: pendente | AD27: pendente | AE27: pendente | AF27: pendente | AG27: amil tijuca | AH27: pendente | AJ27: Sim | AK27: Sim | AL27: Coluna | AM27: =MONTH(B27)&"/"&YEAR(B27) -> 3/2026 | AN27: =WEEKNUM(B27)-WEEKNUM(EOMONTH(B27,-1)+1)+1 -> 4 | AO27: =MONTH(R27)&"/"&YEAR(R27) -> 5/2026 | AP27: =WEEKNUM(R27)-WEEKNUM(EOMONTH(R27,-1)+1)+1 -> 5 | AQ27: =IF(AU27="S",IF(Q27="1. Aceitou o programa",R27-B27,0),0) -> 63 | AR27: =IF(AU27="S",IF(AND(S27<>"",R27<>""),S27-R27,0),0) -> 0 | AS27: =IF(AU27="S",IF(Q27="1. Aceitou o programa",IF(OR(X27="Não se Aplica",X27=""),IF(OR(W27="Não se Aplica",W27=""),0,W27-V27),AVERAGE(X27-W27,W27-V27)),0),0) -> 24.5 | AT27: =IF(AU27="S",IF(AND(Q27="1. Aceitou o programa",AB27="Realizada"),IFERROR(IF(AA27="",0,AA27-R27),0),0),0) -> 0 | AU27: =_xlfn.XLOOKUP(U27,'Lista Suspensa'!$AA$20:$AA$23,'Lista Suspensa'!$AB$20:$AB$23,"N/A") -> S
A28: Não | B28: 46104 | C28: Transbordo/Navegação | D28: Captado pela Amil/Call Center | E28: 77219792 | F28: MARIA MARTA DA SILVA | G28: 1687066361 | H28: 29818 | J28: F | K28: SP | L28: SAO PAULO | M28: PARQUE ARTUR ALVIM | N28: NÍVEL 50 | O28: 11-986424794 | P28: Equiipe CMDP | Q28: 1. Aceitou o programa | R28: 46167 | T28: Contato Com Sucesso | U28: Ativo | V28: 46118 | W28: 46160 | X28: 46167 | Y28: contato com sucesso em 25/05 | Z28: Agendada | AA28: 11/06/2026 11:20 | AB28: agendada | AC28: pendente | AD28: pendente | AE28: pendente | AF28: pendente | AG28: unidade vitoria | AH28: pendente | AJ28: Sim | AK28: Sim | AL28: Coluna | AM28: =MONTH(B28)&"/"&YEAR(B28) -> 3/2026 | AN28: =WEEKNUM(B28)-WEEKNUM(EOMONTH(B28,-1)+1)+1 -> 4 | AO28: =MONTH(R28)&"/"&YEAR(R28) -> 5/2026 | AP28: =WEEKNUM(R28)-WEEKNUM(EOMONTH(R28,-1)+1)+1 -> 5 | AQ28: =IF(AU28="S",IF(Q28="1. Aceitou o programa",R28-B28,0),0) -> 63 | AR28: =IF(AU28="S",IF(AND(S28<>"",R28<>""),S28-R28,0),0) -> 0 | AS28: =IF(AU28="S",IF(Q28="1. Aceitou o programa",IF(OR(X28="Não se Aplica",X28=""),IF(OR(W28="Não se Aplica",W28=""),0,W28-V28),AVERAGE(X28-W28,W28-V28)),0),0) -> 24.5 | AT28: =IF(AU28="S",IF(AND(Q28="1. Aceitou o programa",AB28="Realizada"),IFERROR(IF(AA28="",0,AA28-R28),0),0),0) -> 0 | AU28: =_xlfn.XLOOKUP(U28,'Lista Suspensa'!$AA$20:$AA$23,'Lista Suspensa'!$AB$20:$AB$23,"N/A") -> S
A29: Não | B29: 46104 | C29: Transbordo/Navegação | D29: Captado pela Amil/Call Center | E29: 77408887 | F29: LETICIA DE JESUS DA SILVA | G29: 22651731854 | H29: 30683 | J29: F | K29: SP | L29: SAO PAULO | M29: JARDIM CENTENARIO | N29: NÍVEL 50 | O29: 11-982624680 | P29: Equiipe CMDP | Q29: 1. Aceitou o programa | R29: 46167 | T29: Contato Com Sucesso | U29: Ativo | V29: 46118 | W29: 46161 | X29: 46167 | Z29: Agendada | AA29: 11/06/2026 11:40 | AB29: agendada | AC29: pendente | AD29: pendente | AE29: pendente | AF29: pendente | AG29: AMIL - UD CUBATAO SP - HOSPITAL DA LUZ | AH29: pendente | AJ29: Sim | AK29: Sim | AL29: Coluna | AM29: =MONTH(B29)&"/"&YEAR(B29) -> 3/2026 | AN29: =WEEKNUM(B29)-WEEKNUM(EOMONTH(B29,-1)+1)+1 -> 4 | AO29: =MONTH(R29)&"/"&YEAR(R29) -> 5/2026 | AP29: =WEEKNUM(R29)-WEEKNUM(EOMONTH(R29,-1)+1)+1 -> 5 | AQ29: =IF(AU29="S",IF(Q29="1. Aceitou o programa",R29-B29,0),0) -> 63 | AR29: =IF(AU29="S",IF(AND(S29<>"",R29<>""),S29-R29,0),0) -> 0 | AS29: =IF(AU29="S",IF(Q29="1. Aceitou o programa",IF(OR(X29="Não se Aplica",X29=""),IF(OR(W29="Não se Aplica",W29=""),0,W29-V29),AVERAGE(X29-W29,W29-V29)),0),0) -> 24.5 | AT29: =IF(AU29="S",IF(AND(Q29="1. Aceitou o programa",AB29="Realizada"),IFERROR(IF(AA29="",0,AA29-R29),0),0),0) -> 0 | AU29: =_xlfn.XLOOKUP(U29,'Lista Suspensa'!$AA$20:$AA$23,'Lista Suspensa'!$AB$20:$AB$23,"N/A") -> S
A30: Não | B30: 46104 | C30: Transbordo/Navegação | D30: Captado pela Amil/Call Center | E30: 85721645 | F30: FRANCISCO DAS CHAGAS MEDEIROS | G30: 28695690768 | H30: 18857 | J30: M | K30: RJ | L30: DUQUE DE CAXIAS | M30: CAMPOS ELISEOS | N30: NÍVEL 60 | O30: 21-980800808 | P30: Equiipe CMDP | Q30: 1. Aceitou o programa | R30: 46167 | T30: Contato Com Sucesso | U30: Ativo | V30: 46118 | W30: 46161 | X30: 46167 | Y30: contato com sucesso em 25/05 | Z30: Agendada | AA30: 11/06/2026 13:00 | AB30: agendada | AC30: pendente | AD30: pendente | AE30: pendente | AF30: pendente | AG30: tijuca | AH30: pendente | AJ30: Sim | AK30: Sim | AL30: Coluna | AM30: =MONTH(B30)&"/"&YEAR(B30) -> 3/2026 | AN30: =WEEKNUM(B30)-WEEKNUM(EOMONTH(B30,-1)+1)+1 -> 4 | AO30: =MONTH(R30)&"/"&YEAR(R30) -> 5/2026 | AP30: =WEEKNUM(R30)-WEEKNUM(EOMONTH(R30,-1)+1)+1 -> 5 | AQ30: =IF(AU30="S",IF(Q30="1. Aceitou o programa",R30-B30,0),0) -> 63 | AR30: =IF(AU30="S",IF(AND(S30<>"",R30<>""),S30-R30,0),0) -> 0 | AS30: =IF(AU30="S",IF(Q30="1. Aceitou o programa",IF(OR(X30="Não se Aplica",X30=""),IF(OR(W30="Não se Aplica",W30=""),0,W30-V30),AVERAGE(X30-W30,W30-V30)),0),0) -> 24.5 | AT30: =IF(AU30="S",IF(AND(Q30="1. Aceitou o programa",AB30="Realizada"),IFERROR(IF(AA30="",0,AA30-R30),0),0),0) -> 0 | AU30: =_xlfn.XLOOKUP(U30,'Lista Suspensa'!$AA$20:$AA$23,'Lista Suspensa'!$AB$20:$AB$23,"N/A") -> S
A31: Não | B31: 46104 | C31: Transbordo/Navegação | D31: Captado pela Amil/Call Center | E31: 78356382 | F31: ANA CAROLINE MARQUES DE SOUSA | G31: 14206898782 | H31: 33778 | J31: F | K31: RJ | L31: RIO DE JANEIRO | M31: MANGUINHOS | N31: NÍVEL 380 | O31: 21-982541349 | P31: Equiipe CMDP | Q31: 1. Aceitou o programa | R31: 46167 | T31: Contato Com Sucesso | U31: Ativo | V31: 46118 | W31: 46161 | X31: 46167 | Y31: contato com sucesso em 25/05 | Z31: Agendada | AA31: 11/06/2026 13:20 | AB31: agendada | AC31: pendente | AD31: pendente | AE31: pendente | AF31: pendente | AG31: Tijuca | AH31: pendente | AJ31: Sim | AK31: Sim | AL31: Coluna | AM31: =MONTH(B31)&"/"&YEAR(B31) -> 3/2026 | AN31: =WEEKNUM(B31)-WEEKNUM(EOMONTH(B31,-1)+1)+1 -> 4 | AO31: =MONTH(R31)&"/"&YEAR(R31) -> 5/2026 | AP31: =WEEKNUM(R31)-WEEKNUM(EOMONTH(R31,-1)+1)+1 -> 5 | AQ31: =IF(AU31="S",IF(Q31="1. Aceitou o programa",R31-B31,0),0) -> 63 | AR31: =IF(AU31="S",IF(AND(S31<>"",R31<>""),S31-R31,0),0) -> 0 | AS31: =IF(AU31="S",IF(Q31="1. Aceitou o programa",IF(OR(X31="Não se Aplica",X31=""),IF(OR(W31="Não se Aplica",W31=""),0,W31-V31),AVERAGE(X31-W31,W31-V31)),0),0) -> 24.5 | AT31: =IF(AU31="S",IF(AND(Q31="1. Aceitou o programa",AB31="Realizada"),IFERROR(IF(AA31="",0,AA31-R31),0),0),0) -> 0 | AU31: =_xlfn.XLOOKUP(U31,'Lista Suspensa'!$AA$20:$AA$23,'Lista Suspensa'!$AB$20:$AB$23,"N/A") -> S
A32: Não | B32: 46104 | C32: Transbordo/Navegação | D32: Captado pela Amil/Call Center | E32: 78391206 | F32: GLAUCE ENILDA NASCIMENTO DE OLIVEIRA BATISTA | G32: 2201095752 | H32: 26366 | J32: F | K32: RJ | L32: RIO DE JANEIRO | M32: INHOAIBA | N32: NÍVEL 600 | O32: 21-988267999 | P32: Equiipe CMDP | Q32: 1. Aceitou o programa | R32: 46167 | T32: Contato Com Sucesso | U32: Ativo | V32: 46118 | W32: 46161 | X32: 46167 | Y32: contato com sucesso em 25/05 | Z32: Agendada | AA32: 12/06/2026 09:20 | AB32: agendada | AC32: pendente | AD32: pendente | AE32: pendente | AF32: pendente | AG32: AMIL ESPAÇO SAÚDE - CAMPO GRANDE | AH32: pendente | AJ32: Sim | AK32: Sim | AL32: Coluna | AM32: =MONTH(B32)&"/"&YEAR(B32) -> 3/2026 | AN32: =WEEKNUM(B32)-WEEKNUM(EOMONTH(B32,-1)+1)+1 -> 4 | AO32: =MONTH(R32)&"/"&YEAR(R32) -> 5/2026 | AP32: =WEEKNUM(R32)-WEEKNUM(EOMONTH(R32,-1)+1)+1 -> 5 | AQ32: =IF(AU32="S",IF(Q32="1. Aceitou o programa",R32-B32,0),0) -> 63 | AR32: =IF(AU32="S",IF(AND(S32<>"",R32<>""),S32-R32,0),0) -> 0 | AS32: =IF(AU32="S",IF(Q32="1. Aceitou o programa",IF(OR(X32="Não se Aplica",X32=""),IF(OR(W32="Não se Aplica",W32=""),0,W32-V32),AVERAGE(X32-W32,W32-V32)),0),0) -> 24.5 | AT32: =IF(AU32="S",IF(AND(Q32="1. Aceitou o programa",AB32="Realizada"),IFERROR(IF(AA32="",0,AA32-R32),0),0),0) -> 0 | AU32: =_xlfn.XLOOKUP(U32,'Lista Suspensa'!$AA$20:$AA$23,'Lista Suspensa'!$AB$20:$AB$23,"N/A") -> S
A33: Não | B33: 46104 | C33: Transbordo/Navegação | D33: Captado pela Amil/Call Center | E33: 93734652 | F33: KARINE BORGES MARGELA | G33: 14075418707 | H33: 33456 | J33: F | K33: RJ | L33: RIO DE JANEIRO | M33: FREGUESIA (JACAREPAGUA) | N33: NÍVEL 750 | O33: 21-970449012 | P33: Equiipe CMDP | Q33: 1. Aceitou o programa | R33: 46167 | T33: Contato Com Sucesso | U33: Ativo | V33: 46118 | W33: 46161 | X33: 46167 | Z33: Agendada | AA33: 12/06/2026 09:40 | AB33: agendada | AC33: pendente | AD33: pendente | AE33: pendente | AF33: pendente | AG33: Tijuca | AH33: pendente | AJ33: Sim | AK33: Sim | AL33: Coluna | AM33: =MONTH(B33)&"/"&YEAR(B33) -> 3/2026 | AN33: =WEEKNUM(B33)-WEEKNUM(EOMONTH(B33,-1)+1)+1 -> 4 | AO33: =MONTH(R33)&"/"&YEAR(R33) -> 5/2026 | AP33: =WEEKNUM(R33)-WEEKNUM(EOMONTH(R33,-1)+1)+1 -> 5 | AQ33: =IF(AU33="S",IF(Q33="1. Aceitou o programa",R33-B33,0),0) -> 63 | AR33: =IF(AU33="S",IF(AND(S33<>"",R33<>""),S33-R33,0),0) -> 0 | AS33: =IF(AU33="S",IF(Q33="1. Aceitou o programa",IF(OR(X33="Não se Aplica",X33=""),IF(OR(W33="Não se Aplica",W33=""),0,W33-V33),AVERAGE(X33-W33,W33-V33)),0),0) -> 24.5 | AT33: =IF(AU33="S",IF(AND(Q33="1. Aceitou o programa",AB33="Realizada"),IFERROR(IF(AA33="",0,AA33-R33),0),0),0) -> 0 | AU33: =_xlfn.XLOOKUP(U33,'Lista Suspensa'!$AA$20:$AA$23,'Lista Suspensa'!$AB$20:$AB$23,"N/A") -> S
A34: Não | B34: 46104 | C34: Transbordo/Navegação | D34: Captado pela Amil/Call Center | E34: 78354533 | F34: MARY HELEN DE OLIVEIRA RIBEIRO | G34: 16061386770 | H34: 34801 | J34: F | K34: RJ | L34: RIO DE JANEIRO | M34: COSTA BARROS | N34: NÍVEL 380 | O34: 21-971123551 | P34: Equiipe CMDP | Q34: 1. Aceitou o programa | R34: 46167 | T34: Contato Com Sucesso | U34: Ativo | V34: 46118 | W34: 46161 | X34: 46167 | Y34: contato com sucesso em 25/05 | Z34: Agendada | AA34: 12/06/2026 10:00 | AB34: agendada | AC34: pendente | AD34: pendente | AE34: pendente | AF34: pendente | AG34: AMIL Espaço Saúde – Tijuca/RJ | AH34: pendente | AJ34: Sim | AK34: Sim | AL34: Coluna | AM34: =MONTH(B34)&"/"&YEAR(B34) -> 3/2026 | AN34: =WEEKNUM(B34)-WEEKNUM(EOMONTH(B34,-1)+1)+1 -> 4 | AO34: =MONTH(R34)&"/"&YEAR(R34) -> 5/2026 | AP34: =WEEKNUM(R34)-WEEKNUM(EOMONTH(R34,-1)+1)+1 -> 5 | AQ34: =IF(AU34="S",IF(Q34="1. Aceitou o programa",R34-B34,0),0) -> 63 | AR34: =IF(AU34="S",IF(AND(S34<>"",R34<>""),S34-R34,0),0) -> 0 | AS34: =IF(AU34="S",IF(Q34="1. Aceitou o programa",IF(OR(X34="Não se Aplica",X34=""),IF(OR(W34="Não se Aplica",W34=""),0,W34-V34),AVERAGE(X34-W34,W34-V34)),0),0) -> 24.5 | AT34: =IF(AU34="S",IF(AND(Q34="1. Aceitou o programa",AB34="Realizada"),IFERROR(IF(AA34="",0,AA34-R34),0),0),0) -> 0 | AU34: =_xlfn.XLOOKUP(U34,'Lista Suspensa'!$AA$20:$AA$23,'Lista Suspensa'!$AB$20:$AB$23,"N/A") -> S
A35: Não | B35: 46104 | C35: Transbordo/Navegação | D35: Captado pela Amil/Call Center | E35: 84378288 | F35: THIAGO FERREIRA DA SILVA | G35: 5853628747 | H35: 31865 | J35: M | K35: RJ | L35: RIO DE JANEIRO | M35: PILARES | N35: NÍVEL 380 | O35: 21-985691153 | P35: Equiipe CMDP | Q35: 1. Aceitou o programa | R35: 46167 | T35: Contato Com Sucesso | U35: Ativo | V35: 46118 | W35: 46161 | X35: 46167 | Y35: contato com sucesso em 25/05 | Z35: Agendada | AA35: 12/06/2026 10:20 | AB35: agendada | AC35: pendente | AD35: pendente | AE35: pendente | AF35: pendente | AG35: AMIL ESPAÇO SAÚDE - TIJUCA | AH35: pendente | AJ35: Sim | AK35: Sim | AL35: Coluna | AM35: =MONTH(B35)&"/"&YEAR(B35) -> 3/2026 | AN35: =WEEKNUM(B35)-WEEKNUM(EOMONTH(B35,-1)+1)+1 -> 4 | AO35: =MONTH(R35)&"/"&YEAR(R35) -> 5/2026 | AP35: =WEEKNUM(R35)-WEEKNUM(EOMONTH(R35,-1)+1)+1 -> 5 | AQ35: =IF(AU35="S",IF(Q35="1. Aceitou o programa",R35-B35,0),0) -> 63 | AR35: =IF(AU35="S",IF(AND(S35<>"",R35<>""),S35-R35,0),0) -> 0 | AS35: =IF(AU35="S",IF(Q35="1. Aceitou o programa",IF(OR(X35="Não se Aplica",X35=""),IF(OR(W35="Não se Aplica",W35=""),0,W35-V35),AVERAGE(X35-W35,W35-V35)),0),0) -> 24.5 | AT35: =IF(AU35="S",IF(AND(Q35="1. Aceitou o programa",AB35="Realizada"),IFERROR(IF(AA35="",0,AA35-R35),0),0),0) -> 0 | AU35: =_xlfn.XLOOKUP(U35,'Lista Suspensa'!$AA$20:$AA$23,'Lista Suspensa'!$AB$20:$AB$23,"N/A") -> S
A36: Não | B36: 46104 | C36: Transbordo/Navegação | D36: Captado pela Amil/Call Center | E36: 78260828 | F36: SIMONE TAVARES VELOSO | G36: 88387100749 | H36: 24519 | J36: F | K36: RJ | L36: RIO DE JANEIRO | M36: BARRA DA TIJUCA | N36: NÍVEL 750 | O36: 21-996402928 | P36: Equiipe CMDP | Q36: 1. Aceitou o programa | R36: 46167 | T36: Contato Com Sucesso | U36: Ativo | V36: 46118 | W36: 46161 | X36: 46167 | Y36: contato com sucesso em 19/05 | Z36: Agendada | AA36: 12/06/2026 10:40 | AB36: agendada | AC36: pendente | AD36: pendente | AE36: pendente | AF36: pendente | AG36: Ja faz acompanhamento com dr. Dirceu Belize | AH36: pendente | AJ36: Sim | AK36: Sim | AL36: Coluna | AM36: =MONTH(B36)&"/"&YEAR(B36) -> 3/2026 | AN36: =WEEKNUM(B36)-WEEKNUM(EOMONTH(B36,-1)+1)+1 -> 4 | AO36: =MONTH(R36)&"/"&YEAR(R36) -> 5/2026 | AP36: =WEEKNUM(R36)-WEEKNUM(EOMONTH(R36,-1)+1)+1 -> 5 | AQ36: =IF(AU36="S",IF(Q36="1. Aceitou o programa",R36-B36,0),0) -> 63 | AR36: =IF(AU36="S",IF(AND(S36<>"",R36<>""),S36-R36,0),0) -> 0 | AS36: =IF(AU36="S",IF(Q36="1. Aceitou o programa",IF(OR(X36="Não se Aplica",X36=""),IF(OR(W36="Não se Aplica",W36=""),0,W36-V36),AVERAGE(X36-W36,W36-V36)),0),0) -> 24.5 | AT36: =IF(AU36="S",IF(AND(Q36="1. Aceitou o programa",AB36="Realizada"),IFERROR(IF(AA36="",0,AA36-R36),0),0),0) -> 0 | AU36: =_xlfn.XLOOKUP(U36,'Lista Suspensa'!$AA$20:$AA$23,'Lista Suspensa'!$AB$20:$AB$23,"N/A") -> S
A37: Não | B37: 46104 | C37: Transbordo/Navegação | D37: Captado pela Amil/Call Center | E37: 82617897 | F37: PATRICIA RUFINO LOPES | G37: 31657013855 | H37: 29934 | J37: F | K37: SP | L37: SAO PAULO | M37: VILA MARIANA | N37: NÍVEL 750 | O37: 11-983125014 | P37: Equiipe CMDP | Q37: 1. Aceitou o programa | R37: 46167 | T37: Contato Com Sucesso | U37: Ativo | V37: 46118 | W37: 46161 | X37: 46167 | Y37: contato com sucesso em 25/05 | Z37: Agendada | AA37: 12/06/2026 11:00 | AB37: agendada | AC37: pendente | AD37: pendente | AE37: pendente | AF37: pendente | AG37: Hospital da Luz – Cubatão/SP | AH37: pendente | AJ37: Sim | AK37: Sim | AL37: Coluna | AM37: =MONTH(B37)&"/"&YEAR(B37) -> 3/2026 | AN37: =WEEKNUM(B37)-WEEKNUM(EOMONTH(B37,-1)+1)+1 -> 4 | AO37: =MONTH(R37)&"/"&YEAR(R37) -> 5/2026 | AP37: =WEEKNUM(R37)-WEEKNUM(EOMONTH(R37,-1)+1)+1 -> 5 | AQ37: =IF(AU37="S",IF(Q37="1. Aceitou o programa",R37-B37,0),0) -> 63 | AR37: =IF(AU37="S",IF(AND(S37<>"",R37<>""),S37-R37,0),0) -> 0 | AS37: =IF(AU37="S",IF(Q37="1. Aceitou o programa",IF(OR(X37="Não se Aplica",X37=""),IF(OR(W37="Não se Aplica",W37=""),0,W37-V37),AVERAGE(X37-W37,W37-V37)),0),0) -> 24.5 | AT37: =IF(AU37="S",IF(AND(Q37="1. Aceitou o programa",AB37="Realizada"),IFERROR(IF(AA37="",0,AA37-R37),0),0),0) -> 0 | AU37: =_xlfn.XLOOKUP(U37,'Lista Suspensa'!$AA$20:$AA$23,'Lista Suspensa'!$AB$20:$AB$23,"N/A") -> S
A38: Não | B38: 46104 | C38: Transbordo/Navegação | D38: Captado pela Amil/Call Center | E38: 78667967 | F38: ANTONIO FERNANDO LEITE DE SOUZA | G38: 79677568787 | H38: 23175 | J38: M | K38: RJ | L38: RIO DE JANEIRO | M38: CAMPO GRANDE | N38: NÍVEL 380 | O38: 21-997592268 | P38: Equiipe CMDP | Q38: 1. Aceitou o programa | R38: 46167 | T38: Contato Com Sucesso | U38: Ativo | V38: 46118 | W38: 46161 | X38: 46167 | Y38: contato com sucesso em 25/05 | Z38: Agendada | AA38: 12/06/2026 11:20 | AB38: agendada | AC38: pendente | AD38: pendente | AE38: pendente | AF38: pendente | AG38: Amil campo grande | AH38: pendente | AJ38: Sim | AK38: Sim | AL38: Coluna | AM38: =MONTH(B38)&"/"&YEAR(B38) -> 3/2026 | AN38: =WEEKNUM(B38)-WEEKNUM(EOMONTH(B38,-1)+1)+1 -> 4 | AO38: =MONTH(R38)&"/"&YEAR(R38) -> 5/2026 | AP38: =WEEKNUM(R38)-WEEKNUM(EOMONTH(R38,-1)+1)+1 -> 5 | AQ38: =IF(AU38="S",IF(Q38="1. Aceitou o programa",R38-B38,0),0) -> 63 | AR38: =IF(AU38="S",IF(AND(S38<>"",R38<>""),S38-R38,0),0) -> 0 | AS38: =IF(AU38="S",IF(Q38="1. Aceitou o programa",IF(OR(X38="Não se Aplica",X38=""),IF(OR(W38="Não se Aplica",W38=""),0,W38-V38),AVERAGE(X38-W38,W38-V38)),0),0) -> 24.5 | AT38: =IF(AU38="S",IF(AND(Q38="1. Aceitou o programa",AB38="Realizada"),IFERROR(IF(AA38="",0,AA38-R38),0),0),0) -> 0 | AU38: =_xlfn.XLOOKUP(U38,'Lista Suspensa'!$AA$20:$AA$23,'Lista Suspensa'!$AB$20:$AB$23,"N/A") -> S
A39: Não | B39: 46104 | C39: Transbordo/Navegação | D39: Captado pela Amil/Call Center | E39: 79300226 | F39: ELIANE NETTO DO CARMO | G39: 10289192714 | H39: 32269 | J39: F | K39: RJ | L39: RIO DE JANEIRO | M39: CAMPO GRANDE | N39: NÍVEL 60 | O39: 21-987004988 | P39: Equiipe CMDP | Q39: 1. Aceitou o programa | R39: 46167 | T39: Contato Com Sucesso | U39: Ativo | V39: 46118 | W39: 46161 | X39: 46167 | Y39: contato com sucesso em 25/05 | Z39: Agendada | AA39: 12/06/2026 11:40 | AB39: agendada | AC39: pendente | AD39: pendente | AE39: pendente | AF39: pendente | AG39: AMIL Espaço Saúde – Campo Grande/RJ | AH39: pendente | AJ39: Sim | AK39: Sim | AL39: Coluna | AM39: =MONTH(B39)&"/"&YEAR(B39) -> 3/2026 | AN39: =WEEKNUM(B39)-WEEKNUM(EOMONTH(B39,-1)+1)+1 -> 4 | AO39: =MONTH(R39)&"/"&YEAR(R39) -> 5/2026 | AP39: =WEEKNUM(R39)-WEEKNUM(EOMONTH(R39,-1)+1)+1 -> 5 | AQ39: =IF(AU39="S",IF(Q39="1. Aceitou o programa",R39-B39,0),0) -> 63 | AR39: =IF(AU39="S",IF(AND(S39<>"",R39<>""),S39-R39,0),0) -> 0 | AS39: =IF(AU39="S",IF(Q39="1. Aceitou o programa",IF(OR(X39="Não se Aplica",X39=""),IF(OR(W39="Não se Aplica",W39=""),0,W39-V39),AVERAGE(X39-W39,W39-V39)),0),0) -> 24.5 | AT39: =IF(AU39="S",IF(AND(Q39="1. Aceitou o programa",AB39="Realizada"),IFERROR(IF(AA39="",0,AA39-R39),0),0),0) -> 0 | AU39: =_xlfn.XLOOKUP(U39,'Lista Suspensa'!$AA$20:$AA$23,'Lista Suspensa'!$AB$20:$AB$23,"N/A") -> S
A40: Não | B40: 46104 | C40: Transbordo/Navegação | D40: Captado pela Amil/Call Center | E40: 79584258 | F40: MATILDE SANTANA SOARES | G40: 3366481706 | H40: 27413 | J40: F | K40: RJ | L40: RIO DE JANEIRO | M40: CAMPO GRANDE | N40: NÍVEL 40 | O40: 21-964187094 | P40: Equiipe CMDP | Q40: 1. Aceitou o programa | R40: 46167 | T40: Contato Com Sucesso | U40: Ativo | V40: 46118 | W40: 46161 | X40: 46167 | Y40: contato com sucesso em 19/05 | Z40: Agendada | AA40: 12/06/2026 13:00 | AB40: agendada | AC40: pendente | AD40: pendente | AE40: pendente | AF40: pendente | AG40: Campo grande | AH40: pendente | AJ40: Sim | AK40: Sim | AL40: Coluna | AM40: =MONTH(B40)&"/"&YEAR(B40) -> 3/2026 | AN40: =WEEKNUM(B40)-WEEKNUM(EOMONTH(B40,-1)+1)+1 -> 4 | AO40: =MONTH(R40)&"/"&YEAR(R40) -> 5/2026 | AP40: =WEEKNUM(R40)-WEEKNUM(EOMONTH(R40,-1)+1)+1 -> 5 | AQ40: =IF(AU40="S",IF(Q40="1. Aceitou o programa",R40-B40,0),0) -> 63 | AR40: =IF(AU40="S",IF(AND(S40<>"",R40<>""),S40-R40,0),0) -> 0 | AS40: =IF(AU40="S",IF(Q40="1. Aceitou o programa",IF(OR(X40="Não se Aplica",X40=""),IF(OR(W40="Não se Aplica",W40=""),0,W40-V40),AVERAGE(X40-W40,W40-V40)),0),0) -> 24.5 | AT40: =IF(AU40="S",IF(AND(Q40="1. Aceitou o programa",AB40="Realizada"),IFERROR(IF(AA40="",0,AA40-R40),0),0),0) -> 0 | AU40: =_xlfn.XLOOKUP(U40,'Lista Suspensa'!$AA$20:$AA$23,'Lista Suspensa'!$AB$20:$AB$23,"N/A") -> S
A41: Não | B41: 46104 | C41: Transbordo/Navegação | D41: Captado pela Amil/Call Center | E41: 79972122 | F41: SAMARAH FARIA DA SILVA | G41: 21505725755 | H41: 39861 | J41: F | K41: RJ | L41: SAO JOAO DE MERITI | M41: NAO INFORMADO | N41: NÍVEL 60 | O41: 21-974053355 | P41: Equiipe CMDP | Q41: 1. Aceitou o programa | R41: 46167 | T41: Contato Com Sucesso | U41: Ativo | V41: 46118 | W41: 46161 | X41: 46167 | Y41: contato com sucesso em 25/05 | Z41: Agendada | AA41: 12/06/2026 13:20 | AB41: agendada | AC41: pendente | AD41: pendente | AE41: pendente | AF41: pendente | AG41: Amil – Unidade nova Iguaçu | AH41: pendente | AJ41: Sim | AK41: Sim | AL41: Coluna | AM41: =MONTH(B41)&"/"&YEAR(B41) -> 3/2026 | AN41: =WEEKNUM(B41)-WEEKNUM(EOMONTH(B41,-1)+1)+1 -> 4 | AO41: =MONTH(R41)&"/"&YEAR(R41) -> 5/2026 | AP41: =WEEKNUM(R41)-WEEKNUM(EOMONTH(R41,-1)+1)+1 -> 5 | AQ41: =IF(AU41="S",IF(Q41="1. Aceitou o programa",R41-B41,0),0) -> 63 | AR41: =IF(AU41="S",IF(AND(S41<>"",R41<>""),S41-R41,0),0) -> 0 | AS41: =IF(AU41="S",IF(Q41="1. Aceitou o programa",IF(OR(X41="Não se Aplica",X41=""),IF(OR(W41="Não se Aplica",W41=""),0,W41-V41),AVERAGE(X41-W41,W41-V41)),0),0) -> 24.5 | AT41: =IF(AU41="S",IF(AND(Q41="1. Aceitou o programa",AB41="Realizada"),IFERROR(IF(AA41="",0,AA41-R41),0),0),0) -> 0 | AU41: =_xlfn.XLOOKUP(U41,'Lista Suspensa'!$AA$20:$AA$23,'Lista Suspensa'!$AB$20:$AB$23,"N/A") -> S
A42: Não | B42: 46104 | C42: Transbordo/Navegação | D42: Captado pela Amil/Call Center | E42: 80922617 | F42: RECIMEA CELES LOPES | G42: 4469387851 | H42: 20742 | J42: F | K42: SP | L42: GUARULHOS | M42: JARDIM PRESIDENTE DUTRA | N42: NÍVEL 60 | O42: 11-985339112 | P42: Equiipe CMDP | Q42: 1. Aceitou o programa | R42: 46167 | T42: Contato Com Sucesso | U42: Ativo | V42: 46118 | W42: 46161 | X42: 46167 | Y42: contato com sucesso em 19/05 | Z42: Agendada | AA42: 15/06/2026 09:20 | AB42: agendada | AC42: pendente | AD42: pendente | AE42: pendente | AF42: pendente | AG42: amil guarulhos | AH42: pendente | AJ42: Sim | AK42: Sim | AL42: Coluna | AM42: =MONTH(B42)&"/"&YEAR(B42) -> 3/2026 | AN42: =WEEKNUM(B42)-WEEKNUM(EOMONTH(B42,-1)+1)+1 -> 4 | AO42: =MONTH(R42)&"/"&YEAR(R42) -> 5/2026 | AP42: =WEEKNUM(R42)-WEEKNUM(EOMONTH(R42,-1)+1)+1 -> 5 | AQ42: =IF(AU42="S",IF(Q42="1. Aceitou o programa",R42-B42,0),0) -> 63 | AR42: =IF(AU42="S",IF(AND(S42<>"",R42<>""),S42-R42,0),0) -> 0 | AS42: =IF(AU42="S",IF(Q42="1. Aceitou o programa",IF(OR(X42="Não se Aplica",X42=""),IF(OR(W42="Não se Aplica",W42=""),0,W42-V42),AVERAGE(X42-W42,W42-V42)),0),0) -> 24.5 | AT42: =IF(AU42="S",IF(AND(Q42="1. Aceitou o programa",AB42="Realizada"),IFERROR(IF(AA42="",0,AA42-R42),0),0),0) -> 0 | AU42: =_xlfn.XLOOKUP(U42,'Lista Suspensa'!$AA$20:$AA$23,'Lista Suspensa'!$AB$20:$AB$23,"N/A") -> S
A43: Não | B43: 46104 | C43: Transbordo/Navegação | D43: Captado pela Amil/Call Center | E43: 89156553 | F43: DAVID ROCHA JUSTINO | G43: 79028551468 | H43: 26214 | J43: M | K43: SP | L43: TABOAO DA SERRA | M43: PARQUE JACARANDA | N43: NÍVEL 60 | O43: 11-962718125 | P43: Equiipe CMDP | Q43: 1. Aceitou o programa | R43: 46167 | T43: Contato Com Sucesso | U43: Ativo | V43: 46118 | W43: 46161 | X43: 46167 | Y43: contato com sucesso em 25/05 | Z43: Agendada | AA43: 15/06/2026 09:40 | AB43: agendada | AC43: pendente | AD43: pendente | AE43: pendente | AF43: pendente | AG43: informa já ter cosnulta com o seu médico especialista dia 02/06, informa estar fazendo fisioterapia e já ter realizado cirurgia na coluna porem não da detalhes | AH43: pendente | AJ43: Sim | AK43: Sim | AL43: Coluna | AM43: =MONTH(B43)&"/"&YEAR(B43) -> 3/2026 | AN43: =WEEKNUM(B43)-WEEKNUM(EOMONTH(B43,-1)+1)+1 -> 4 | AO43: =MONTH(R43)&"/"&YEAR(R43) -> 5/2026 | AP43: =WEEKNUM(R43)-WEEKNUM(EOMONTH(R43,-1)+1)+1 -> 5 | AQ43: =IF(AU43="S",IF(Q43="1. Aceitou o programa",R43-B43,0),0) -> 63 | AR43: =IF(AU43="S",IF(AND(S43<>"",R43<>""),S43-R43,0),0) -> 0 | AS43: =IF(AU43="S",IF(Q43="1. Aceitou o programa",IF(OR(X43="Não se Aplica",X43=""),IF(OR(W43="Não se Aplica",W43=""),0,W43-V43),AVERAGE(X43-W43,W43-V43)),0),0) -> 24.5 | AT43: =IF(AU43="S",IF(AND(Q43="1. Aceitou o programa",AB43="Realizada"),IFERROR(IF(AA43="",0,AA43-R43),0),0),0) -> 0 | AU43: =_xlfn.XLOOKUP(U43,'Lista Suspensa'!$AA$20:$AA$23,'Lista Suspensa'!$AB$20:$AB$23,"N/A") -> S
A44: Não | B44: 46104 | C44: Transbordo/Navegação | D44: Captado pela Amil/Call Center | E44: 81056433 | F44: ROSELI DIAS FIRMINO SILVA | G44: 18167546845 | H44: 27451 | J44: F | K44: SP | L44: SAO PAULO | M44: ALTO DA MOOCA | N44: NÍVEL 380 | O44: 11-991724347 | P44: Equiipe CMDP | Q44: 1. Aceitou o programa | R44: 46167 | T44: Contato Com Sucesso | U44: Ativo | V44: 46118 | W44: 46161 | X44: 46167 | Y44: contato com sucesso em 19/05 | Z44: Agendada | AA44: 15/06/2026 10:00 | AB44: agendada | AC44: pendente | AD44: pendente | AE44: pendente | AF44: pendente | AG44: Hospital Vitória | AH44: pendente | AJ44: Sim | AK44: Sim | AL44: Coluna | AM44: =MONTH(B44)&"/"&YEAR(B44) -> 3/2026 | AN44: =WEEKNUM(B44)-WEEKNUM(EOMONTH(B44,-1)+1)+1 -> 4 | AO44: =MONTH(R44)&"/"&YEAR(R44) -> 5/2026 | AP44: =WEEKNUM(R44)-WEEKNUM(EOMONTH(R44,-1)+1)+1 -> 5 | AQ44: =IF(AU44="S",IF(Q44="1. Aceitou o programa",R44-B44,0),0) -> 63 | AR44: =IF(AU44="S",IF(AND(S44<>"",R44<>""),S44-R44,0),0) -> 0 | AS44: =IF(AU44="S",IF(Q44="1. Aceitou o programa",IF(OR(X44="Não se Aplica",X44=""),IF(OR(W44="Não se Aplica",W44=""),0,W44-V44),AVERAGE(X44-W44,W44-V44)),0),0) -> 24.5 | AT44: =IF(AU44="S",IF(AND(Q44="1. Aceitou o programa",AB44="Realizada"),IFERROR(IF(AA44="",0,AA44-R44),0),0),0) -> 0 | AU44: =_xlfn.XLOOKUP(U44,'Lista Suspensa'!$AA$20:$AA$23,'Lista Suspensa'!$AB$20:$AB$23,"N/A") -> S
...

Sheet Lista Suspensa
D1: Motivo Envio | F1: Lista Suspensa - Origem | H1: Linha | I1: Origem (Colocar na ordem desejada) | K1: Lista Suspensa - Local de Acomapanhamento | M1: Linha | N1: Local de Acomapanhamento (Colocar na ordem desejada) | P1: Local de Acomapanhamento atual | R1: Linhas | T1: CA Confirmado? | V1: Status BNF Linha | X1: Status Do Contato | Z1: Situação Atual Do Paciente | AB1: Status Pré Consulta Enfermagem | AD1: Status da 1ª Consulta Enfermagem | AF1: Complexidade | AH1: Direcionado ao Paulistano? | AJ1: Flag | AL1: Encaminhado p/ Consolidado? | AN1: Prioridade no Contato?
B2: CÉLULA COM FÓRMULA - NÃO ALTERAR | D2: Captação + Navegação | F2: {=IF(COUNTIF(Consolidado!$AL:$AL,"Emagrecimento")<>0,_xlfn._xlws.FILTER($I$2:$I$54,$H$2:$H$54<>""),_xlfn._xlws.FILTER($I$2:$I$54,$H$2:$H$54="Outras"))} -> Captado pela Amil/Call Center | H2: Outras | I2: Captado pela Amil/Call Center | K2: {=IF(COUNTIF(Consolidado!$AL:$AL,"Emagrecimento")<>0,_xlfn._xlws.FILTER($N$2:$N$100,$M$2:$M$100<>""),_xlfn._xlws.FILTER($N$2:$N$100,$M$2:$M$100="Outras"))} -> Amil Paulistano | M2: Outras | N2: Amil Paulistano | P2: Amil Paulistano | R2: Colorretal | T2: Em Investigação | V2: 1. Aceitou o programa | X2: Contato Com Sucesso | Z2: Ativo | AB2: Agendada | AD2: Realizada | AF2: Baixa | AH2: Sim | AJ2: Sim | AL2: Sim | AN2: Sim
D3: Navegação | F3: Casos Prioritário - E-mail | H3: Outras | I3: Casos Prioritário - E-mail | K3: Samaritano Higi | M3: Outras | N3: Samaritano Higi | P3: Samaritano Higi | R3: Mama | T3: Confirmado | V3: 2. Em avaliação para participar do programa | X3: Contato Sem Sucesso | Z3: Inativo | AB3: Aguardando Agendamento | AD3: Não realizada - Reagendada | AF3: Média | AH3: Não | AJ3: Desflagado | AL3: Não | AN3: Não
D4: Transbordo/Navegação | F4: Forms Total Care | H4: Outras | I4: Forms Total Care | K4: COI -RJ | M4: Outras | N4: COI -RJ | P4: COI RJ | R4: Pós-TMO | T4: Negativo | V4: 3. Recusa por conta da assinatura do termo | X4: Aguardando Contato | Z4: Fora da Linha | AD4: Não realizada - Desistência | AF4: Alta | AJ4: Pendente | AL4: NA
D5: Migrou do Fluxo de Negativa | F5: GSC | H5: Outras | I5: GSC | K5: Interno - Amil Geral | M5: Outras | N5: Interno - Amil Geral | P5: Externo - Outros | R5: Próstata | T5: NA | V5: 3. Recusa por desconfiança do programa | AD5: Não realizada - Falta | AJ5: Não
F6: Triggers | H6: Outras | I6: Triggers | K6: Externo - Geral | M6: Outras | N6: Externo - Geral | R6: Pulmão | V6: 3. Recusa por falta de interesse | AD6: Recusa
F7: Viva Bem | H7: Outras | I7: Viva Bem | K7: Não Informou | M7: Outras | N7: Não Informou | R7: Autoimunidade | V7: 3. Recusa pela coparticipação
F8: Saúde Ocupacional | H8: Outras | I8: Saúde Ocupacional | K8: CMDP - Centro Médico Dom Pedro | M8: Outras | N8: CMDP - Centro Médico Dom Pedro | R8: Anticoagulante | V8: 3. Recusa por estar fora da região
F9: Optin | H9: Emagrecimento | I9: Ambulatório - Américas | K9: Outros | M9: Outras | N9: Outros | R9: Arritmias | V9: 3. Recusa por outros motivos | Z9: Ativo/Inativo | AA9: Ativo
H10: Emagrecimento | I10: Ambulatório - Samaritano Barra | K10: Amil - Hospital Ipiranga Arujá - Ambulatório | M10: Outras | N10: Amil - Hospital Ipiranga Arujá - Ambulatório | R10: ICC | V10: 4. Inelegível fora do escopo | Z10: Ativo/Inativo | AA10: Inativo
H11: Emagrecimento | I11: Captado pela Amil | K11: Amil - Hospital Ipiranga Mogi - Ambulatório | M11: Outras | N11: Amil - Hospital Ipiranga Mogi - Ambulatório | R11: Pós-IAM | V11: 4. Exclusão do plano | Z11: Ativo | AA11: Ativo
H12: Emagrecimento | I12: Captado pela Amil - Endocrino CMDP | K12: Amil - Hospital Metropolitano - Centro Médico | M12: Outras | N12: Amil - Hospital Metropolitano - Centro Médico | R12: Valvopatias | V12: 4. Óbito | Z12: Inativo | AA12: Inativo
H13: Emagrecimento | I13: CMDP - Busca Ativa do Paciente | K13: Amil - Hospital Paulistano - Ambulatório | M13: Outras | N13: Amil - Hospital Paulistano - Ambulatório | R13: Diabetes | V13: 4. Não Captar a pedido da Operadora | Z13: Fora da Linha | AA13: Fora da Linha
H14: Emagrecimento | I14: CMDP - Eduardo | K14: Amil - Ud Cubatão Sp - Hospital Da Luz | M14: Outras | N14: Amil - Ud Cubatão Sp - Hospital Da Luz | R14: Emagrecimento | V14: 5. Alta por óbito | Z14: Total | AA14: Ativo
H15: Emagrecimento | I15: CMDP Nutri - Andreza Oliveira Barbosa | K15: Amil - Unidade Avançada Carlos Chagas | M15: Outras | N15: Amil - Unidade Avançada Carlos Chagas | R15: Gestantes | V15: 5. Alta por inelegibilidade | Z15: Total | AA15: Inativo
H16: Emagrecimento | I16: CMDP Nutri - Helena Guazzelli | K16: Amil - Unidade Avançada Luz Butantã | M16: Outras | N16: Amil - Unidade Avançada Luz Butantã | R16: Coluna | V16: 5. Alta por múltiplas tentativas | Z16: Total | AA16: Fora da Linha
H17: Emagrecimento | I17: CMDP Nutri - Juliana Cardoso Gaia | K17: Amil - Unidade Avançada Luz Joao Dias | M17: Outras | N17: Amil - Unidade Avançada Luz Joao Dias | R17: Pós-AVC | V17: 5. Alta a pedido - recusa em assinar o termo
H18: Emagrecimento | I18: CMDP Nutri - Maria Carolina Vieira Marrano | K18: Amil - Unidade Avançada Vitoria | M18: Outras | N18: Amil - Unidade Avançada Vitoria | R18: Cefaleia | V18: 5. Alta a pedido - perda de interesse
H19: Emagrecimento | I19: CMDP Nutri - Mariana Freire Lima | K19: Amil Espaço Saúde - Ana Rosa | M19: Outras | N19: Amil Espaço Saúde - Ana Rosa | R19: Endometriose | V19: 5. Alta a pedido - mudança de região
